Workbook
Name Reporting_Month: Dashboard!$C$4
Name Truck_Filter: Dashboard!$F$4
Name Gross_Fee_Month: Dashboard!$B$8
Name Cash_Profit_Month: Dashboard!$L$8
Name Margin_Month: Dashboard!$B$12
Name Crew_To_Pay: Dashboard!$H$12
Name Loan_Balance: Dashboard!$J$12
Name Unpaid_Invoices: Dashboard!$L$12

Sheet Dashboard
A1: 🚚 J&Z TRUCKING · COMMAND CENTER
A2: Live figures from every trip, every receipt and every loan. Change the two filters below — the whole page follows.
B3: GO TO ▸ | C3: P&L | D3: Trucks | E3: Loans | F3: Destinations | G3: Crew pay | H3: Trips log | I3: Expenses | J3: Payroll | K3: Setup | L3: Read me
B4: MONTH | C4: 46296 | D4: ◀ change | E4: TRUCK | F4: All | G4: all units | H4: ="vs previous month ▸ fee "&IF(N(Calc!$B$40)=0,"n/a",IF(Calc!$B$7>=Calc!$B$40,"+","")&ROUND((Calc!$B$7/Calc!$B$40-1)*100,1)&"%")&" trips "&IF(N(Calc!$B$41)=0,"n/a",IF(Calc!$B$10>=Calc!$B$41,"+","")&(Calc!$B$10-Calc!$B$41))&" tons "&IF(N(Calc!$B$42)=0,"n/a",IF(Calc!$B$11>=Calc!$B$42,"+","")&ROUND((Calc!$B$11/Calc!$B$42-1)*100,1)&"%")&" (pick a truck to see that unit alone)"
B7: GROSS HAULING FEE | D7: NET HAULING FEE | F7: CREW COST | H7: TRIP NET PROFIT | J7: OPERATING PROFIT | L7: CASH PROFIT AFTER LOANS
B8: =Calc!$B$7 | D8: =Calc!$Q$9 | F8: =Calc!$B$15 | H8: =Calc!$Q$19 | J8: =Calc!$Q$22 | L8: =Calc!$Q$24
B9: total fee invoiced this month | D9: after the 2% withholding tax | F9: driver + helper share + allowance | H9: after fuel, toll & crew | J9: after repairs, rent & overhead | L9: what is really left in your pocket
B11: PROFIT MARGIN | D11: TRIPS DELIVERED | F11: TONS HAULED | H11: STILL TO PAY CREW | J11: LOAN BALANCE | L11: UNPAID INVOICES
B12: =Calc!$Q$25 | D12: =Calc!$B$10 | F12: =Calc!$B$11 | H12: =Calc!$B$30 | J12: =Calc!$B$99 | L12: =Calc!$B$31
B13: cash profit ÷ gross fee | D13: this month | F13: total weight moved | H13: unsettled balance this month | J13: principal still owed, all lenders | L13: customer fees not yet collected
B47: PROFIT & LOSS · selected month
B48: LINE ITEM | D48: AMOUNT | E48: % OF FEE | F48: HOW IT IS BUILT
B49: Gross hauling fee | D49: =Calc!$Q$7 | E49: =IF(Calc!$Q$7=0,"",D49/Calc!$Q$7) | F49: tons × rate × (1 + fuel surcharge)
B50: Withholding tax (2%) | D50: =Calc!$Q$8 | E50: =IF(Calc!$Q$7=0,"",D50/Calc!$Q$7) | F50: 2% withheld by the client
B51: Net hauling fee | D51: =Calc!$Q$9 | E51: =IF(Calc!$Q$7=0,"",D51/Calc!$Q$7) | F51: the base for the crew shares
B52: Driver share | D52: =Calc!$Q$10 | E52: =IF(Calc!$Q$7=0,"",D52/Calc!$Q$7) | F52: driver share of net fee
B53: Helper share | D53: =Calc!$Q$11 | E53: =IF(Calc!$Q$7=0,"",D53/Calc!$Q$7) | F53: helper share of net fee
B54: Driver allowance | D54: =Calc!$Q$12 | E54: =IF(Calc!$Q$7=0,"",D54/Calc!$Q$7) | F54: cash given per trip
B55: Reimbursable expenses | D55: =Calc!$Q$13 | E55: =IF(Calc!$Q$7=0,"",D55/Calc!$Q$7) | F55: driver receipts to pay back
B56: Gross profit | D56: =Calc!$Q$14 | E56: =IF(Calc!$Q$7=0,"",D56/Calc!$Q$7) | F56: after crew and reimbursables
B57: Fuel | D57: =Calc!$Q$15 | E57: =IF(Calc!$Q$7=0,"",D57/Calc!$Q$7) | F57: diesel logged per trip
B58: Toll & parking | D58: =Calc!$Q$16 | E58: =IF(Calc!$Q$7=0,"",D58/Calc!$Q$7) | F58: expressway + parking
B59: Other trip costs | D59: =Calc!$Q$17 | E59: =IF(Calc!$Q$7=0,"",D59/Calc!$Q$7) | F59: weighing, grease, tips
B60: Total trip cost | D60: =Calc!$Q$18 | E60: =IF(Calc!$Q$7=0,"",D60/Calc!$Q$7)
B61: Trip net profit | D61: =Calc!$Q$19 | E61: =IF(Calc!$Q$7=0,"",D61/Calc!$Q$7) | F61: before truck running costs
B62: Vehicle running costs (repairs, tires…) | D62: =Calc!$Q$20 | E62: =IF(Calc!$Q$7=0,"",D62/Calc!$Q$7) | F62: repairs, tires, insurance, LTO, wash
B63: Overhead (rent, office, salaries…) | D63: =Calc!$Q$21 | E63: =IF(Calc!$Q$7=0,"",D63/Calc!$Q$7) | F63: rent, office salary, utilities, fees
B64: Operating profit | D64: =Calc!$Q$22 | E64: =IF(Calc!$Q$7=0,"",D64/Calc!$Q$7) | F64: the operating result
B65: Loan amortisation paid | D65: =Calc!$Q$23 | E65: =IF(Calc!$Q$7=0,"",D65/Calc!$Q$7) | F65: principal + interest to all lenders
B66: Cash profit after loans | D66: =Calc!$Q$24 | E66: =IF(Calc!$Q$7=0,"",D66/Calc!$Q$7) | F66: money actually left with you
B67: Margin on hauling fee | D67: =Calc!$Q$25 | F67: cash profit ÷ gross fee
B68: Memo: advances & payouts (not a cost) | D68: =Calc!$Q$26 | E68: =IF(Calc!$Q$7=0,"",D68/Calc!$Q$7) | F68: advances are a transfer, not a cost
B70: TRUCK PERFORMANCE · selected month | H70: LOAN BOOK · all lenders, self-updating
B71: TRUCK | C71: TRIPS | D71: TONS | E71: GROSS FEE | F71: TRIP PROFIT | G71: MARGIN | H71: LENDER · TRUCK | J71: AMORT. | K71: BALANCE | L71: MONTHS LEFT | M71: PAID %
B72: =Calc!$Q$32 | C72: =Calc!$R$32 | D72: =Calc!$S$32 | E72: =Calc!$T$32 | F72: =Calc!$U$32 | G72: =Calc!$V$32 | H72: =IF(Setup!$A133="","",Setup!$A133&" · "&Setup!$B133) | J72: =Setup!$E133 | K72: =Setup!$K133 | L72: =Setup!$J133 | M72: =Setup!$M133
B73: =Calc!$Q$33 | C73: =Calc!$R$33 | D73: =Calc!$S$33 | E73: =Calc!$T$33 | F73: =Calc!$U$33 | G73: =Calc!$V$33 | H73: =IF(Setup!$A134="","",Setup!$A134&" · "&Setup!$B134) | J73: =Setup!$E134 | K73: =Setup!$K134 | L73: =Setup!$J134 | M73: =Setup!$M134
B74: =Calc!$Q$34 | C74: =Calc!$R$34 | D74: =Calc!$S$34 | E74: =Calc!$T$34 | F74: =Calc!$U$34 | G74: =Calc!$V$34 | H74: =IF(Setup!$A135="","",Setup!$A135&" · "&Setup!$B135) | J74: =Setup!$E135 | K74: =Setup!$K135 | L74: =Setup!$J135 | M74: =Setup!$M135
B75: =Calc!$Q$35 | C75: =Calc!$R$35 | D75: =Calc!$S$35 | E75: =Calc!$T$35 | F75: =Calc!$U$35 | G75: =Calc!$V$35 | H75: =IF(Setup!$A136="","",Setup!$A136&" · "&Setup!$B136) | J75: =Setup!$E136 | K75: =Setup!$K136 | L75: =Setup!$J136 | M75: =Setup!$M136
B76: =Calc!$Q$36 | C76: =Calc!$R$36 | D76: =Calc!$S$36 | E76: =Calc!$T$36 | F76: =Calc!$U$36 | G76: =Calc!$V$36 | H76: =IF(Setup!$A137="","",Setup!$A137&" · "&Setup!$B137) | J76: =Setup!$E137 | K76: =Setup!$K137 | L76: =Setup!$J137 | M76: =Setup!$M137
B77: =Calc!$Q$37 | C77: =Calc!$R$37 | D77: =Calc!$S$37 | E77: =Calc!$T$37 | F77: =Calc!$U$37 | G77: =Calc!$V$37 | H77: =IF(Setup!$A138="","",Setup!$A138&" · "&Setup!$B138) | J77: =Setup!$E138 | K77: =Setup!$K138 | L77: =Setup!$J138 | M77: =Setup!$M138
...

Sheet Trips
A1: 🚚 TRIPS — one row per delivery (this is the only sheet you fill in daily)
A2: Type only in the WHITE columns. Grey columns calculate themselves. Leave the fuel surcharge blank to use the 18% default — leave allowance blank to use the default.
A3: ALL-TIME TOTALS → | B3: =COUNT(5:1004)&" trips logged" | H3: =SUM(H5:H1004) | K3: =SUM(K5:K1004) | L3: =SUM(L5:L1004) | M3: =SUM(M5:M1004) | N3: =SUM(N5:N1004) | O3: =SUM(O5:O1004) | P3: =SUM(P5:P1004) | Q3: =SUM(Q5:Q1004) | R3: =SUM(R5:R1004) | ... V3: =SUM(V5:V1004)
A4: DATE | B4: INVOICE / DR NO. | C4: TRUCK | D4: DRIVER | E4: HELPER | F4: SOURCE | G4: DESTINATION | H4: TONS | I4: RATE / TON | J4: FUEL SURCH. % | K4: GROSS FEE | L4: 2% TAX | M4: NET FEE | N4: DRIVER PAY | O4: HELPER PAY | P4: ALLOWANCE | Q4: REIMBURSABLE | R4: FUEL COST | S4: TOLL + PARKING | T4: OTHER TRIP COST | U4: DIRECT COST | V4: TRIP NET PROFIT | W4: BILLING | X4: REMARKS
A5: 46235 | B5: DR-1001 | C5: TRUCK 1 | D5: R. Dela Cruz | E5: J. Santos | F5: BATAAN | G5: TARLAC | H5: 17 | I5: =IF($G5="","",IF($F5="",IFERROR(INDEX(Setup!$C$21:$C$60,MATCH("|"&UPPER(TRIM($G5)),Setup!$Q$21:$Q$60,0)),"NO RATE"),IFERROR(INDEX(Setup!$C$21:$C$60,MATCH(UPPER(TRIM($F5))&"|"&UPPER(TRIM($G5)),Setup!$P$21:$P$60,0)),IFERROR(INDEX(Setup!$C$21:$C$60,MATCH(UPPER(TRIM($G5))&"|"&UPPER(TRIM($F5)),Setup!$P$21:$P$60,0)),"NO RATE")))) | K5: =IF(OR($G5="",$H5="",NOT(ISNUMBER($I5))),"",ROUND($H5*$I5*(1+IF($J5="",Setup!$B$16,$J5)),2)) | L5: =IF($K5="","",ROUND($K5*Setup!$B$13,2)) | M5: =IF($K5="","",$K5-$L5) | N5: =IF(OR($M5="",$D5=""),"",ROUND($M5*IFERROR(IF(VLOOKUP($D5,Setup!$A$76:$C$87,3,FALSE)="",Setup!$B$14,VLOOKUP($D5,Setup!$A$76:$C$87,3,FALSE)),Setup!$B$14),2)) | O5: =IF(OR($M5="",$E5=""),"",ROUND($M5*IFERROR(IF(VLOOKUP($E5,Setup!$A$76:$C$87,3,FALSE)="",Setup!$B$15,VLOOKUP($E5,Setup!$A$76:$C$87,3,FALSE)),Setup!$B$15),2)) | P5: 500 | Q5: 450 | R5: 5600 | S5: 620 | T5: 0 | U5: =IF($K5="","",SUM($R5:$T5)) | V5: =IF($K5="","",$M5-(N($N5)+N($O5)+IF($P5="",Setup!$B$17,$P5)+N($Q5))-N($U5)) | W5: Paid | Z5: =IF($A5="","",DATE(YEAR($A5),MONTH($A5),1))
A6: 46237 | B6: DR-1002 | C6: TRUCK 1 | D6: M. Reyes | E6: A. Bautista | F6: BATAAN | G6: BMPP | H6: 20 | I6: =IF($G6="","",IF($F6="",IFERROR(INDEX(Setup!$C$21:$C$60,MATCH("|"&UPPER(TRIM($G6)),Setup!$Q$21:$Q$60,0)),"NO RATE"),IFERROR(INDEX(Setup!$C$21:$C$60,MATCH(UPPER(TRIM($F6))&"|"&UPPER(TRIM($G6)),Setup!$P$21:$P$60,0)),IFERROR(INDEX(Setup!$C$21:$C$60,MATCH(UPPER(TRIM($G6))&"|"&UPPER(TRIM($F6)),Setup!$P$21:$P$60,0)),"NO RATE")))) | K6: =IF(OR($G6="",$H6="",NOT(ISNUMBER($I6))),"",ROUND($H6*$I6*(1+IF($J6="",Setup!$B$16,$J6)),2)) | L6: =IF($K6="","",ROUND($K6*Setup!$B$13,2)) | M6: =IF($K6="","",$K6-$L6) | N6: =IF(OR($M6="",$D6=""),"",ROUND($M6*IFERROR(IF(VLOOKUP($D6,Setup!$A$76:$C$87,3,FALSE)="",Setup!$B$14,VLOOKUP($D6,Setup!$A$76:$C$87,3,FALSE)),Setup!$B$14),2)) | O6: =IF(OR($M6="",$E6=""),"",ROUND($M6*IFERROR(IF(VLOOKUP($E6,Setup!$A$76:$C$87,3,FALSE)="",Setup!$B$15,VLOOKUP($E6,Setup!$A$76:$C$87,3,FALSE)),Setup!$B$15),2)) | P6: 500 | Q6: 0 | R6: 8300 | S6: 560 | T6: 0 | U6: =IF($K6="","",SUM($R6:$T6)) | V6: =IF($K6="","",$M6-(N($N6)+N($O6)+IF($P6="",Setup!$B$17,$P6)+N($Q6))-N($U6)) | W6: Paid | Z6: =IF($A6="","",DATE(YEAR($A6),MONTH($A6),1))
A7: 46239 | B7: DR-1003 | C7: TRUCK 1 | D7: R. Dela Cruz | E7: J. Santos | F7: ORION | G7: BMPP | H7: 23 | I7: =IF($G7="","",IF($F7="",IFERROR(INDEX(Setup!$C$21:$C$60,MATCH("|"&UPPER(TRIM($G7)),Setup!$Q$21:$Q$60,0)),"NO RATE"),IFERROR(INDEX(Setup!$C$21:$C$60,MATCH(UPPER(TRIM($F7))&"|"&UPPER(TRIM($G7)),Setup!$P$21:$P$60,0)),IFERROR(INDEX(Setup!$C$21:$C$60,MATCH(UPPER(TRIM($G7))&"|"&UPPER(TRIM($F7)),Setup!$P$21:$P$60,0)),"NO RATE")))) | K7: =IF(OR($G7="",$H7="",NOT(ISNUMBER($I7))),"",ROUND($H7*$I7*(1+IF($J7="",Setup!$B$16,$J7)),2)) | L7: =IF($K7="","",ROUND($K7*Setup!$B$13,2)) | M7: =IF($K7="","",$K7-$L7) | N7: =IF(OR($M7="",$D7=""),"",ROUND($M7*IFERROR(IF(VLOOKUP($D7,Setup!$A$76:$C$87,3,FALSE)="",Setup!$B$14,VLOOKUP($D7,Setup!$A$76:$C$87,3,FALSE)),Setup!$B$14),2)) | O7: =IF(OR($M7="",$E7=""),"",ROUND($M7*IFERROR(IF(VLOOKUP($E7,Setup!$A$76:$C$87,3,FALSE)="",Setup!$B$15,VLOOKUP($E7,Setup!$A$76:$C$87,3,FALSE)),Setup!$B$15),2)) | P7: 500 | Q7: 0 | R7: 9800 | S7: 540 | T7: 0 | U7: =IF($K7="","",SUM($R7:$T7)) | V7: =IF($K7="","",$M7-(N($N7)+N($O7)+IF($P7="",Setup!$B$17,$P7)+N($Q7))-N($U7)) | W7: Paid | Z7: =IF($A7="","",DATE(YEAR($A7),MONTH($A7),1))
A8: 46241 | B8: DR-1004 | C8: TRUCK 1 | D8: M. Reyes | E8: A. Bautista | F8: MABINI, BATANGAS | G8: BMPP | H8: 19 | I8: =IF($G8="","",IF($F8="",IFERROR(INDEX(Setup!$C$21:$C$60,MATCH("|"&UPPER(TRIM($G8)),Setup!$Q$21:$Q$60,0)),"NO RATE"),IFERROR(INDEX(Setup!$C$21:$C$60,MATCH(UPPER(TRIM($F8))&"|"&UPPER(TRIM($G8)),Setup!$P$21:$P$60,0)),IFERROR(INDEX(Setup!$C$21:$C$60,MATCH(UPPER(TRIM($G8))&"|"&UPPER(TRIM($F8)),Setup!$P$21:$P$60,0)),"NO RATE")))) | K8: =IF(OR($G8="",$H8="",NOT(ISNUMBER($I8))),"",ROUND($H8*$I8*(1+IF($J8="",Setup!$B$16,$J8)),2)) | L8: =IF($K8="","",ROUND($K8*Setup!$B$13,2)) | M8: =IF($K8="","",$K8-$L8) | N8: =IF(OR($M8="",$D8=""),"",ROUND($M8*IFERROR(IF(VLOOKUP($D8,Setup!$A$76:$C$87,3,FALSE)="",Setup!$B$14,VLOOKUP($D8,Setup!$A$76:$C$87,3,FALSE)),Setup!$B$14),2)) | O8: =IF(OR($M8="",$E8=""),"",ROUND($M8*IFERROR(IF(VLOOKUP($E8,Setup!$A$76:$C$87,3,FALSE)="",Setup!$B$15,VLOOKUP($E8,Setup!$A$76:$C$87,3,FALSE)),Setup!$B$15),2)) | P8: 500 | Q8: 0 | R8: 11100 | S8: 980 | T8: 0 | U8: =IF($K8="","",SUM($R8:$T8)) | V8: =IF($K8="","",$M8-(N($N8)+N($O8)+IF($P8="",Setup!$B$17,$P8)+N($Q8))-N($U8)) | W8: Paid | Z8: =IF($A8="","",DATE(YEAR($A8),MONTH($A8),1))
A9: 46243 | B9: DR-1005 | C9: TRUCK 1 | D9: R. Dela Cruz | E9: J. Santos | F9: BATAAN | G9: ISABELA | H9: 18 | I9: =IF($G9="","",IF($F9="",IFERROR(INDEX(Setup!$C$21:$C$60,MATCH("|"&UPPER(TRIM($G9)),Setup!$Q$21:$Q$60,0)),"NO RATE"),IFERROR(INDEX(Setup!$C$21:$C$60,MATCH(UPPER(TRIM($F9))&"|"&UPPER(TRIM($G9)),Setup!$P$21:$P$60,0)),IFERROR(INDEX(Setup!$C$21:$C$60,MATCH(UPPER(TRIM($G9))&"|"&UPPER(TRIM($F9)),Setup!$P$21:$P$60,0)),"NO RATE")))) | K9: =IF(OR($G9="",$H9="",NOT(ISNUMBER($I9))),"",ROUND($H9*$I9*(1+IF($J9="",Setup!$B$16,$J9)),2)) | L9: =IF($K9="","",ROUND($K9*Setup!$B$13,2)) | M9: =IF($K9="","",$K9-$L9) | N9: =IF(OR($M9="",$D9=""),"",ROUND($M9*IFERROR(IF(VLOOKUP($D9,Setup!$A$76:$C$87,3,FALSE)="",Setup!$B$14,VLOOKUP($D9,Setup!$A$76:$C$87,3,FALSE)),Setup!$B$14),2)) | O9: =IF(OR($M9="",$E9=""),"",ROUND($M9*IFERROR(IF(VLOOKUP($E9,Setup!$A$76:$C$87,3,FALSE)="",Setup!$B$15,VLOOKUP($E9,Setup!$A$76:$C$87,3,FALSE)),Setup!$B$15),2)) | P9: 500 | Q9: 0 | R9: 16500 | S9: 1250 | T9: 0 | U9: =IF($K9="","",SUM($R9:$T9)) | V9: =IF($K9="","",$M9-(N($N9)+N($O9)+IF($P9="",Setup!$B$17,$P9)+N($Q9))-N($U9)) | W9: Paid | X9: long haul — diesel receipt attached | Z9: =IF($A9="","",DATE(YEAR($A9),MONTH($A9),1))
A10: 46245 | B10: DR-1006 | C10: TRUCK 1 | D10: M. Reyes | E10: A. Bautista | F10: ORION | G10: TARLAC | H10: 21 | I10: =IF($G10="","",IF($F10="",IFERROR(INDEX(Setup!$C$21:$C$60,MATCH("|"&UPPER(TRIM($G10)),Setup!$Q$21:$Q$60,0)),"NO RATE"),IFERROR(INDEX(Setup!$C$21:$C$60,MATCH(UPPER(TRIM($F10))&"|"&UPPER(TRIM($G10)),Setup!$P$21:$P$60,0)),IFERROR(INDEX(Setup!$C$21:$C$60,MATCH(UPPER(TRIM($G10))&"|"&UPPER(TRIM($F10)),Setup!$P$21:$P$60,0)),"NO RATE")))) | K10: =IF(OR($G10="",$H10="",NOT(ISNUMBER($I10))),"",ROUND($H10*$I10*(1+IF($J10="",Setup!$B$16,$J10)),2)) | L10: =IF($K10="","",ROUND($K10*Setup!$B$13,2)) | M10: =IF($K10="","",$K10-$L10) | N10: =IF(OR($M10="",$D10=""),"",ROUND($M10*IFERROR(IF(VLOOKUP($D10,Setup!$A$76:$C$87,3,FALSE)="",Setup!$B$14,VLOOKUP($D10,Setup!$A$76:$C$87,3,FALSE)),Setup!$B$14),2)) | O10: =IF(OR($M10="",$E10=""),"",ROUND($M10*IFERROR(IF(VLOOKUP($E10,Setup!$A$76:$C$87,3,FALSE)="",Setup!$B$15,VLOOKUP($E10,Setup!$A$76:$C$87,3,FALSE)),Setup!$B$15),2)) | P10: 500 | Q10: 450 | R10: 7200 | S10: 610 | T10: 0 | U10: =IF($K10="","",SUM($R10:$T10)) | V10: =IF($K10="","",$M10-(N($N10)+N($O10)+IF($P10="",Setup!$B$17,$P10)+N($Q10))-N($U10)) | W10: Paid | Z10: =IF($A10="","",DATE(YEAR($A10),MONTH($A10),1))
A11: 46247 | B11: DR-1007 | C11: TRUCK 1 | D11: R. Dela Cruz | E11: J. Santos | F11: MABINI, BATANGAS | G11: TARLAC | H11: 17 | I11: =IF($G11="","",IF($F11="",IFERROR(INDEX(Setup!$C$21:$C$60,MATCH("|"&UPPER(TRIM($G11)),Setup!$Q$21:$Q$60,0)),"NO RATE"),IFERROR(INDEX(Setup!$C$21:$C$60,MATCH(UPPER(TRIM($F11))&"|"&UPPER(TRIM($G11)),Setup!$P$21:$P$60,0)),IFERROR(INDEX(Setup!$C$21:$C$60,MATCH(UPPER(TRIM($G11))&"|"&UPPER(TRIM($F11)),Setup!$P$21:$P$60,0)),"NO RATE")))) | K11: =IF(OR($G11="",$H11="",NOT(ISNUMBER($I11))),"",ROUND($H11*$I11*(1+IF($J11="",Setup!$B$16,$J11)),2)) | L11: =IF($K11="","",ROUND($K11*Setup!$B$13,2)) | M11: =IF($K11="","",$K11-$L11) | N11: =IF(OR($M11="",$D11=""),"",ROUND($M11*IFERROR(IF(VLOOKUP($D11,Setup!$A$76:$C$87,3,FALSE)="",Setup!$B$14,VLOOKUP($D11,Setup!$A$76:$C$87,3,FALSE)),Setup!$B$14),2)) | O11: =IF(OR($M11="",$E11=""),"",ROUND($M11*IFERROR(IF(VLOOKUP($E11,Setup!$A$76:$C$87,3,FALSE)="",Setup!$B$15,VLOOKUP($E11,Setup!$A$76:$C$87,3,FALSE)),Setup!$B$15),2)) | P11: 500 | Q11: 0 | R11: 8900 | S11: 900 | T11: 0 | U11: =IF($K11="","",SUM($R11:$T11)) | V11: =IF($K11="","",$M11-(N($N11)+N($O11)+IF($P11="",Setup!$B$17,$P11)+N($Q11))-N($U11)) | W11: Paid | Z11: =IF($A11="","",DATE(YEAR($A11),MONTH($A11),1))
A12: 46249 | B12: DR-1008 | C12: TRUCK 1 | D12: M. Reyes | E12: A. Bautista | F12: BATAAN | G12: ARMOR | H12: 20 | I12: =IF($G12="","",IF($F12="",IFERROR(INDEX(Setup!$C$21:$C$60,MATCH("|"&UPPER(TRIM($G12)),Setup!$Q$21:$Q$60,0)),"NO RATE"),IFERROR(INDEX(Setup!$C$21:$C$60,MATCH(UPPER(TRIM($F12))&"|"&UPPER(TRIM($G12)),Setup!$P$21:$P$60,0)),IFERROR(INDEX(Setup!$C$21:$C$60,MATCH(UPPER(TRIM($G12))&"|"&UPPER(TRIM($F12)),Setup!$P$21:$P$60,0)),"NO RATE")))) | K12: =IF(OR($G12="",$H12="",NOT(ISNUMBER($I12))),"",ROUND($H12*$I12*(1+IF($J12="",Setup!$B$16,$J12)),2)) | L12: =IF($K12="","",ROUND($K12*Setup!$B$13,2)) | M12: =IF($K12="","",$K12-$L12) | N12: =IF(OR($M12="",$D12=""),"",ROUND($M12*IFERROR(IF(VLOOKUP($D12,Setup!$A$76:$C$87,3,FALSE)="",Setup!$B$14,VLOOKUP($D12,Setup!$A$76:$C$87,3,FALSE)),Setup!$B$14),2)) | O12: =IF(OR($M12="",$E12=""),"",ROUND($M12*IFERROR(IF(VLOOKUP($E12,Setup!$A$76:$C$87,3,FALSE)="",Setup!$B$15,VLOOKUP($E12,Setup!$A$76:$C$87,3,FALSE)),Setup!$B$15),2)) | P12: 500 | Q12: 0 | R12: 7900 | S12: 520 | T12: 0 | U12: =IF($K12="","",SUM($R12:$T12)) | V12: =IF($K12="","",$M12-(N($N12)+N($O12)+IF($P12="",Setup!$B$17,$P12)+N($Q12))-N($U12)) | W12: Paid | Z12: =IF($A12="","",DATE(YEAR($A12),MONTH($A12),1))
A13: 46251 | B13: DR-1009 | C13: TRUCK 1 | D13: R. Dela Cruz | E13: J. Santos | F13: ORION | G13: BULACAN | H13: 23 | I13: =IF($G13="","",IF($F13="",IFERROR(INDEX(Setup!$C$21:$C$60,MATCH("|"&UPPER(TRIM($G13)),Setup!$Q$21:$Q$60,0)),"NO RATE"),IFERROR(INDEX(Setup!$C$21:$C$60,MATCH(UPPER(TRIM($F13))&"|"&UPPER(TRIM($G13)),Setup!$P$21:$P$60,0)),IFERROR(INDEX(Setup!$C$21:$C$60,MATCH(UPPER(TRIM($G13))&"|"&UPPER(TRIM($F13)),Setup!$P$21:$P$60,0)),"NO RATE")))) | K13: =IF(OR($G13="",$H13="",NOT(ISNUMBER($I13))),"",ROUND($H13*$I13*(1+IF($J13="",Setup!$B$16,$J13)),2)) | L13: =IF($K13="","",ROUND($K13*Setup!$B$13,2)) | M13: =IF($K13="","",$K13-$L13) | N13: =IF(OR($M13="",$D13=""),"",ROUND($M13*IFERROR(IF(VLOOKUP($D13,Setup!$A$76:$C$87,3,FALSE)="",Setup!$B$14,VLOOKUP($D13,Setup!$A$76:$C$87,3,FALSE)),Setup!$B$14),2)) | O13: =IF(OR($M13="",$E13=""),"",ROUND($M13*IFERROR(IF(VLOOKUP($E13,Setup!$A$76:$C$87,3,FALSE)="",Setup!$B$15,VLOOKUP($E13,Setup!$A$76:$C$87,3,FALSE)),Setup!$B$15),2)) | P13: 500 | Q13: 0 | R13: 7700 | S13: 590 | T13: 0 | U13: =IF($K13="","",SUM($R13:$T13)) | V13: =IF($K13="","",$M13-(N($N13)+N($O13)+IF($P13="",Setup!$B$17,$P13)+N($Q13))-N($U13)) | W13: Paid | Z13: =IF($A13="","",DATE(YEAR($A13),MONTH($A13),1))
A14: 46253 | B14: DR-1010 | C14: TRUCK 1 | D14: M. Reyes | E14: A. Bautista | F14: MABINI, BATANGAS | G14: MONCADA | H14: 17 | I14: =IF($G14="","",IF($F14="",IFERROR(INDEX(Setup!$C$21:$C$60,MATCH("|"&UPPER(TRIM($G14)),Setup!$Q$21:$Q$60,0)),"NO RATE"),IFERROR(INDEX(Setup!$C$21:$C$60,MATCH(UPPER(TRIM($F14))&"|"&UPPER(TRIM($G14)),Setup!$P$21:$P$60,0)),IFERROR(INDEX(Setup!$C$21:$C$60,MATCH(UPPER(TRIM($G14))&"|"&UPPER(TRIM($F14)),Setup!$P$21:$P$60,0)),"NO RATE")))) | K14: =IF(OR($G14="",$H14="",NOT(ISNUMBER($I14))),"",ROUND($H14*$I14*(1+IF($J14="",Setup!$B$16,$J14)),2)) | L14: =IF($K14="","",ROUND($K14*Setup!$B$13,2)) | M14: =IF($K14="","",$K14-$L14) | N14: =IF(OR($M14="",$D14=""),"",ROUND($M14*IFERROR(IF(VLOOKUP($D14,Setup!$A$76:$C$87,3,FALSE)="",Setup!$B$14,VLOOKUP($D14,Setup!$A$76:$C$87,3,FALSE)),Setup!$B$14),2)) | O14: =IF(OR($M14="",$E14=""),"",ROUND($M14*IFERROR(IF(VLOOKUP($E14,Setup!$A$76:$C$87,3,FALSE)="",Setup!$B$15,VLOOKUP($E14,Setup!$A$76:$C$87,3,FALSE)),Setup!$B$15),2)) | P14: 500 | Q14: 0 | R14: 6600 | S14: 430 | T14: 0 | U14: =IF($K14="","",SUM($R14:$T14)) | V14: =IF($K14="","",$M14-(N($N14)+N($O14)+IF($P14="",Setup!$B$17,$P14)+N($Q14))-N($U14)) | W14: Paid | X14: helper not available, driver solo | Z14: =IF($A14="","",DATE(YEAR($A14),MONTH($A14),1))
A15: 46255 | B15: DR-1011 | C15: TRUCK 1 | D15: R. Dela Cruz | E15: J. Santos | F15: BATAAN | G15: BULACAN | H15: 20 | I15: =IF($G15="","",IF($F15="",IFERROR(INDEX(Setup!$C$21:$C$60,MATCH("|"&UPPER(TRIM($G15)),Setup!$Q$21:$Q$60,0)),"NO RATE"),IFERROR(INDEX(Setup!$C$21:$C$60,MATCH(UPPER(TRIM($F15))&"|"&UPPER(TRIM($G15)),Setup!$P$21:$P$60,0)),IFERROR(INDEX(Setup!$C$21:$C$60,MATCH(UPPER(TRIM($G15))&"|"&UPPER(TRIM($F15)),Setup!$P$21:$P$60,0)),"NO RATE")))) | K15: =IF(OR($G15="",$H15="",NOT(ISNUMBER($I15))),"",ROUND($H15*$I15*(1+IF($J15="",Setup!$B$16,$J15)),2)) | L15: =IF($K15="","",ROUND($K15*Setup!$B$13,2)) | M15: =IF($K15="","",$K15-$L15) | N15: =IF(OR($M15="",$D15=""),"",ROUND($M15*IFERROR(IF(VLOOKUP($D15,Setup!$A$76:$C$87,3,FALSE)="",Setup!$B$14,VLOOKUP($D15,Setup!$A$76:$C$87,3,FALSE)),Setup!$B$14),2)) | O15: =IF(OR($M15="",$E15=""),"",ROUND($M15*IFERROR(IF(VLOOKUP($E15,Setup!$A$76:$C$87,3,FALSE)="",Setup!$B$15,VLOOKUP($E15,Setup!$A$76:$C$87,3,FALSE)),Setup!$B$15),2)) | P15: 500 | Q15: 450 | R15: 7600 | S15: 480 | T15: 0 | U15: =IF($K15="","",SUM($R15:$T15)) | V15: =IF($K15="","",$M15-(N($N15)+N($O15)+IF($P15="",Setup!$B$17,$P15)+N($Q15))-N($U15)) | W15: Paid | Z15: =IF($A15="","",DATE(YEAR($A15),MONTH($A15),1))
A16: 46257 | B16: DR-1012 | C16: TRUCK 1 | D16: M. Reyes | E16: A. Bautista | F16: ORION | G16: ROSALES | H16: 21 | I16: =IF($G16="","",IF($F16="",IFERROR(INDEX(Setup!$C$21:$C$60,MATCH("|"&UPPER(TRIM($G16)),Setup!$Q$21:$Q$60,0)),"NO RATE"),IFERROR(INDEX(Setup!$C$21:$C$60,MATCH(UPPER(TRIM($F16))&"|"&UPPER(TRIM($G16)),Setup!$P$21:$P$60,0)),IFERROR(INDEX(Setup!$C$21:$C$60,MATCH(UPPER(TRIM($G16))&"|"&UPPER(TRIM($F16)),Setup!$P$21:$P$60,0)),"NO RATE")))) | K16: =IF(OR($G16="",$H16="",NOT(ISNUMBER($I16))),"",ROUND($H16*$I16*(1+IF($J16="",Setup!$B$16,$J16)),2)) | L16: =IF($K16="","",ROUND($K16*Setup!$B$13,2)) | M16: =IF($K16="","",$K16-$L16) | N16: =IF(OR($M16="",$D16=""),"",ROUND($M16*IFERROR(IF(VLOOKUP($D16,Setup!$A$76:$C$87,3,FALSE)="",Setup!$B$14,VLOOKUP($D16,Setup!$A$76:$C$87,3,FALSE)),Setup!$B$14),2)) | O16: =IF(OR($M16="",$E16=""),"",ROUND($M16*IFERROR(IF(VLOOKUP($E16,Setup!$A$76:$C$87,3,FALSE)="",Setup!$B$15,VLOOKUP($E16,Setup!$A$76:$C$87,3,FALSE)),Setup!$B$15),2)) | P16: 500 | Q16: 0 | R16: 7800 | S16: 700 | T16: 0 | U16: =IF($K16="","",SUM($R16:$T16)) | V16: =IF($K16="","",$M16-(N($N16)+N($O16)+IF($P16="",Setup!$B$17,$P16)+N($Q16))-N($U16)) | W16: Paid | Z16: =IF($A16="","",DATE(YEAR($A16),MONTH($A16),1))
A17: 46259 | B17: DR-1013 | C17: TRUCK 1 | D17: R. Dela Cruz | E17: J. Santos | F17: MABINI, BATANGAS | G17: BATAAN | H17: 17 | I17: =IF($G17="","",IF($F17="",IFERROR(INDEX(Setup!$C$21:$C$60,MATCH("|"&UPPER(TRIM($G17)),Setup!$Q$21:$Q$60,0)),"NO RATE"),IFERROR(INDEX(Setup!$C$21:$C$60,MATCH(UPPER(TRIM($F17))&"|"&UPPER(TRIM($G17)),Setup!$P$21:$P$60,0)),IFERROR(INDEX(Setup!$C$21:$C$60,MATCH(UPPER(TRIM($G17))&"|"&UPPER(TRIM($F17)),Setup!$P$21:$P$60,0)),"NO RATE")))) | K17: =IF(OR($G17="",$H17="",NOT(ISNUMBER($I17))),"",ROUND($H17*$I17*(1+IF($J17="",Setup!$B$16,$J17)),2)) | L17: =IF($K17="","",ROUND($K17*Setup!$B$13,2)) | M17: =IF($K17="","",$K17-$L17) | N17: =IF(OR($M17="",$D17=""),"",ROUND($M17*IFERROR(IF(VLOOKUP($D17,Setup!$A$76:$C$87,3,FALSE)="",Setup!$B$14,VLOOKUP($D17,Setup!$A$76:$C$87,3,FALSE)),Setup!$B$14),2)) | O17: =IF(OR($M17="",$E17=""),"",ROUND($M17*IFERROR(IF(VLOOKUP($E17,Setup!$A$76:$C$87,3,FALSE)="",Setup!$B$15,VLOOKUP($E17,Setup!$A$76:$C$87,3,FALSE)),Setup!$B$15),2)) | P17: 500 | Q17: 0 | R17: 10000 | S17: 880 | T17: 0 | U17: =IF($K17="","",SUM($R17:$T17)) | V17: =IF($K17="","",$M17-(N($N17)+N($O17)+IF($P17="",Setup!$B$17,$P17)+N($Q17))-N($U17)) | W17: Paid | Z17: =IF($A17="","",DATE(YEAR($A17),MONTH($A17),1))
A18: 46261 | B18: DR-1014 | C18: TRUCK 1 | D18: M. Reyes | E18: A. Bautista | F18: BATAAN | G18: BMEG BATAAN | H18: 20 | I18: =IF($G18="","",IF($F18="",IFERROR(INDEX(Setup!$C$21:$C$60,MATCH("|"&UPPER(TRIM($G18)),Setup!$Q$21:$Q$60,0)),"NO RATE"),IFERROR(INDEX(Setup!$C$21:$C$60,MATCH(UPPER(TRIM($F18))&"|"&UPPER(TRIM($G18)),Setup!$P$21:$P$60,0)),IFERROR(INDEX(Setup!$C$21:$C$60,MATCH(UPPER(TRIM($G18))&"|"&UPPER(TRIM($F18)),Setup!$P$21:$P$60,0)),"NO RATE")))) | K18: =IF(OR($G18="",$H18="",NOT(ISNUMBER($I18))),"",ROUND($H18*$I18*(1+IF($J18="",Setup!$B$16,$J18)),2)) | L18: =IF($K18="","",ROUND($K18*Setup!$B$13,2)) | M18: =IF($K18="","",$K18-$L18) | N18: =IF(OR($M18="",$D18=""),"",ROUND($M18*IFERROR(IF(VLOOKUP($D18,Setup!$A$76:$C$87,3,FALSE)="",Setup!$B$14,VLOOKUP($D18,Setup!$A$76:$C$87,3,FALSE)),Setup!$B$14),2)) | O18: =IF(OR($M18="",$E18=""),"",ROUND($M18*IFERROR(IF(VLOOKUP($E18,Setup!$A$76:$C$87,3,FALSE)="",Setup!$B$15,VLOOKUP($E18,Setup!$A$76:$C$87,3,FALSE)),Setup!$B$15),2)) | P18: 400 | Q18: 0 | R18: 900 | S18: 120 | T18: 0 | U18: =IF($K18="","",SUM($R18:$T18)) | V18: =IF($K18="","",$M18-(N($N18)+N($O18)+IF($P18="",Setup!$B$17,$P18)+N($Q18))-N($U18)) | W18: Paid | Z18: =IF($A18="","",DATE(YEAR($A18),MONTH($A18),1))
A19: 46266 | B19: DR-1015 | C19: TRUCK 1 | D19: M. Reyes | E19: A. Bautista | F19: BATAAN | G19: TARLAC | H19: 18 | I19: =IF($G19="","",IF($F19="",IFERROR(INDEX(Setup!$C$21:$C$60,MATCH("|"&UPPER(TRIM($G19)),Setup!$Q$21:$Q$60,0)),"NO RATE"),IFERROR(INDEX(Setup!$C$21:$C$60,MATCH(UPPER(TRIM($F19))&"|"&UPPER(TRIM($G19)),Setup!$P$21:$P$60,0)),IFERROR(INDEX(Setup!$C$21:$C$60,MATCH(UPPER(TRIM($G19))&"|"&UPPER(TRIM($F19)),Setup!$P$21:$P$60,0)),"NO RATE")))) | K19: =IF(OR($G19="",$H19="",NOT(ISNUMBER($I19))),"",ROUND($H19*$I19*(1+IF($J19="",Setup!$B$16,$J19)),2)) | L19: =IF($K19="","",ROUND($K19*Setup!$B$13,2)) | M19: =IF($K19="","",$K19-$L19) | N19: =IF(OR($M19="",$D19=""),"",ROUND($M19*IFERROR(IF(VLOOKUP($D19,Setup!$A$76:$C$87,3,FALSE)="",Setup!$B$14,VLOOKUP($D19,Setup!$A$76:$C$87,3,FALSE)),Setup!$B$14),2)) | O19: =IF(OR($M19="",$E19=""),"",ROUND($M19*IFERROR(IF(VLOOKUP($E19,Setup!$A$76:$C$87,3,FALSE)="",Setup!$B$15,VLOOKUP($E19,Setup!$A$76:$C$87,3,FALSE)),Setup!$B$15),2)) | P19: 500 | Q19: 0 | R19: 6400 | S19: 620 | T19: 0 | U19: =IF($K19="","",SUM($R19:$T19)) | V19: =IF($K19="","",$M19-(N($N19)+N($O19)+IF($P19="",Setup!$B$17,$P19)+N($Q19))-N($U19)) | W19: Paid | Z19: =IF($A19="","",DATE(YEAR($A19),MONTH($A19),1))
A20: 46267 | B20: DR-1016 | C20: TRUCK 1 | D20: R. Dela Cruz | E20: J. Santos | F20: BATAAN | G20: BMPP | H20: 21 | I20: =IF($G20="","",IF($F20="",IFERROR(INDEX(Setup!$C$21:$C$60,MATCH("|"&UPPER(TRIM($G20)),Setup!$Q$21:$Q$60,0)),"NO RATE"),IFERROR(INDEX(Setup!$C$21:$C$60,MATCH(UPPER(TRIM($F20))&"|"&UPPER(TRIM($G20)),Setup!$P$21:$P$60,0)),IFERROR(INDEX(Setup!$C$21:$C$60,MATCH(UPPER(TRIM($G20))&"|"&UPPER(TRIM($F20)),Setup!$P$21:$P$60,0)),"NO RATE")))) | K20: =IF(OR($G20="",$H20="",NOT(ISNUMBER($I20))),"",ROUND($H20*$I20*(1+IF($J20="",Setup!$B$16,$J20)),2)) | L20: =IF($K20="","",ROUND($K20*Setup!$B$13,2)) | M20: =IF($K20="","",$K20-$L20) | N20: =IF(OR($M20="",$D20=""),"",ROUND($M20*IFERROR(IF(VLOOKUP($D20,Setup!$A$76:$C$87,3,FALSE)="",Setup!$B$14,VLOOKUP($D20,Setup!$A$76:$C$87,3,FALSE)),Setup!$B$14),2)) | O20: =IF(OR($M20="",$E20=""),"",ROUND($M20*IFERROR(IF(VLOOKUP($E20,Setup!$A$76:$C$87,3,FALSE)="",Setup!$B$15,VLOOKUP($E20,Setup!$A$76:$C$87,3,FALSE)),Setup!$B$15),2)) | P20: 500 | Q20: 0 | R20: 9400 | S20: 560 | T20: 0 | U20: =IF($K20="","",SUM($R20:$T20)) | V20: =IF($K20="","",$M20-(N($N20)+N($O20)+IF($P20="",Setup!$B$17,$P20)+N($Q20))-N($U20)) | W20: Paid | Z20: =IF($A20="","",DATE(YEAR($A20),MONTH($A20),1))
A21: 46269 | B21: DR-1017 | C21: TRUCK 1 | D21: M. Reyes | E21: A. Bautista | F21: ORION | G21: BMPP | H21: 21 | I21: =IF($G21="","",IF($F21="",IFERROR(INDEX(Setup!$C$21:$C$60,MATCH("|"&UPPER(TRIM($G21)),Setup!$Q$21:$Q$60,0)),"NO RATE"),IFERROR(INDEX(Setup!$C$21:$C$60,MATCH(UPPER(TRIM($F21))&"|"&UPPER(TRIM($G21)),Setup!$P$21:$P$60,0)),IFERROR(INDEX(Setup!$C$21:$C$60,MATCH(UPPER(TRIM($G21))&"|"&UPPER(TRIM($F21)),Setup!$P$21:$P$60,0)),"NO RATE")))) | K21: =IF(OR($G21="",$H21="",NOT(ISNUMBER($I21))),"",ROUND($H21*$I21*(1+IF($J21="",Setup!$B$16,$J21)),2)) | L21: =IF($K21="","",ROUND($K21*Setup!$B$13,2)) | M21: =IF($K21="","",$K21-$L21) | N21: =IF(OR($M21="",$D21=""),"",ROUND($M21*IFERROR(IF(VLOOKUP($D21,Setup!$A$76:$C$87,3,FALSE)="",Setup!$B$14,VLOOKUP($D21,Setup!$A$76:$C$87,3,FALSE)),Setup!$B$14),2)) | O21: =IF(OR($M21="",$E21=""),"",ROUND($M21*IFERROR(IF(VLOOKUP($E21,Setup!$A$76:$C$87,3,FALSE)="",Setup!$B$15,VLOOKUP($E21,Setup!$A$76:$C$87,3,FALSE)),Setup!$B$15),2)) | P21: 500 | Q21: 0 | R21: 7600 | S21: 540 | T21: 0 | U21: =IF($K21="","",SUM($R21:$T21)) | V21: =IF($K21="","",$M21-(N($N21)+N($O21)+IF($P21="",Setup!$B$17,$P21)+N($Q21))-N($U21)) | W21: Paid | Z21: =IF($A21="","",DATE(YEAR($A21),MONTH($A21),1))
A22: 46271 | B22: DR-1018 | C22: TRUCK 1 | D22: R. Dela Cruz | E22: J. Santos | F22: MABINI, BATANGAS | G22: BMPP | H22: 20 | I22: =IF($G22="","",IF($F22="",IFERROR(INDEX(Setup!$C$21:$C$60,MATCH("|"&UPPER(TRIM($G22)),Setup!$Q$21:$Q$60,0)),"NO RATE"),IFERROR(INDEX(Setup!$C$21:$C$60,MATCH(UPPER(TRIM($F22))&"|"&UPPER(TRIM($G22)),Setup!$P$21:$P$60,0)),IFERROR(INDEX(Setup!$C$21:$C$60,MATCH(UPPER(TRIM($G22))&"|"&UPPER(TRIM($F22)),Setup!$P$21:$P$60,0)),"NO RATE")))) | K22: =IF(OR($G22="",$H22="",NOT(ISNUMBER($I22))),"",ROUND($H22*$I22*(1+IF($J22="",Setup!$B$16,$J22)),2)) | L22: =IF($K22="","",ROUND($K22*Setup!$B$13,2)) | M22: =IF($K22="","",$K22-$L22) | N22: =IF(OR($M22="",$D22=""),"",ROUND($M22*IFERROR(IF(VLOOKUP($D22,Setup!$A$76:$C$87,3,FALSE)="",Setup!$B$14,VLOOKUP($D22,Setup!$A$76:$C$87,3,FALSE)),Setup!$B$14),2)) | O22: =IF(OR($M22="",$E22=""),"",ROUND($M22*IFERROR(IF(VLOOKUP($E22,Setup!$A$76:$C$87,3,FALSE)="",Setup!$B$15,VLOOKUP($E22,Setup!$A$76:$C$87,3,FALSE)),Setup!$B$15),2)) | P22: 500 | Q22: 0 | R22: 12700 | S22: 980 | T22: 0 | U22: =IF($K22="","",SUM($R22:$T22)) | V22: =IF($K22="","",$M22-(N($N22)+N($O22)+IF($P22="",Setup!$B$17,$P22)+N($Q22))-N($U22)) | W22: Paid | Z22: =IF($A22="","",DATE(YEAR($A22),MONTH($A22),1))
A23: 46273 | B23: DR-1019 | C23: TRUCK 1 | D23: M. Reyes | E23: A. Bautista | F23: BATAAN | G23: ISABELA | H23: 19 | I23: =IF($G23="","",IF($F23="",IFERROR(INDEX(Setup!$C$21:$C$60,MATCH("|"&UPPER(TRIM($G23)),Setup!$Q$21:$Q$60,0)),"NO RATE"),IFERROR(INDEX(Setup!$C$21:$C$60,MATCH(UPPER(TRIM($F23))&"|"&UPPER(TRIM($G23)),Setup!$P$21:$P$60,0)),IFERROR(INDEX(Setup!$C$21:$C$60,MATCH(UPPER(TRIM($G23))&"|"&UPPER(TRIM($F23)),Setup!$P$21:$P$60,0)),"NO RATE")))) | K23: =IF(OR($G23="",$H23="",NOT(ISNUMBER($I23))),"",ROUND($H23*$I23*(1+IF($J23="",Setup!$B$16,$J23)),2)) | L23: =IF($K23="","",ROUND($K23*Setup!$B$13,2)) | M23: =IF($K23="","",$K23-$L23) | N23: =IF(OR($M23="",$D23=""),"",ROUND($M23*IFERROR(IF(VLOOKUP($D23,Setup!$A$76:$C$87,3,FALSE)="",Setup!$B$14,VLOOKUP($D23,Setup!$A$76:$C$87,3,FALSE)),Setup!$B$14),2)) | O23: =IF(OR($M23="",$E23=""),"",ROUND($M23*IFERROR(IF(VLOOKUP($E23,Setup!$A$76:$C$87,3,FALSE)="",Setup!$B$15,VLOOKUP($E23,Setup!$A$76:$C$87,3,FALSE)),Setup!$B$15),2)) | P23: 500 | Q23: 450 | R23: 18800 | S23: 1250 | T23: 0 | U23: =IF($K23="","",SUM($R23:$T23)) | V23: =IF($K23="","",$M23-(N($N23)+N($O23)+IF($P23="",Setup!$B$17,$P23)+N($Q23))-N($U23)) | W23: Paid | X23: long haul — diesel receipt attached | Z23: =IF($A23="","",DATE(YEAR($A23),MONTH($A23),1))
A24: 46274 | B24: DR-1020 | C24: TRUCK 1 | D24: R. Dela Cruz | E24: J. Santos | F24: ORION | G24: TARLAC | H24: 19 | I24: =IF($G24="","",IF($F24="",IFERROR(INDEX(Setup!$C$21:$C$60,MATCH("|"&UPPER(TRIM($G24)),Setup!$Q$21:$Q$60,0)),"NO RATE"),IFERROR(INDEX(Setup!$C$21:$C$60,MATCH(UPPER(TRIM($F24))&"|"&UPPER(TRIM($G24)),Setup!$P$21:$P$60,0)),IFERROR(INDEX(Setup!$C$21:$C$60,MATCH(UPPER(TRIM($G24))&"|"&UPPER(TRIM($F24)),Setup!$P$21:$P$60,0)),"NO RATE")))) | K24: =IF(OR($G24="",$H24="",NOT(ISNUMBER($I24))),"",ROUND($H24*$I24*(1+IF($J24="",Setup!$B$16,$J24)),2)) | L24: =IF($K24="","",ROUND($K24*Setup!$B$13,2)) | M24: =IF($K24="","",$K24-$L24) | N24: =IF(OR($M24="",$D24=""),"",ROUND($M24*IFERROR(IF(VLOOKUP($D24,Setup!$A$76:$C$87,3,FALSE)="",Setup!$B$14,VLOOKUP($D24,Setup!$A$76:$C$87,3,FALSE)),Setup!$B$14),2)) | O24: =IF(OR($M24="",$E24=""),"",ROUND($M24*IFERROR(IF(VLOOKUP($E24,Setup!$A$76:$C$87,3,FALSE)="",Setup!$B$15,VLOOKUP($E24,Setup!$A$76:$C$87,3,FALSE)),Setup!$B$15),2)) | P24: 500 | Q24: 0 | R24: 5600 | S24: 610 | T24: 0 | U24: =IF($K24="","",SUM($R24:$T24)) | V24: =IF($K24="","",$M24-(N($N24)+N($O24)+IF($P24="",Setup!$B$17,$P24)+N($Q24))-N($U24)) | W24: Paid | Z24: =IF($A24="","",DATE(YEAR($A24),MONTH($A24),1))
A25: 46276 | B25: DR-1021 | C25: TRUCK 1 | D25: M. Reyes | E25: A. Bautista | F25: MABINI, BATANGAS | G25: TARLAC | H25: 18 | I25: =IF($G25="","",IF($F25="",IFERROR(INDEX(Setup!$C$21:$C$60,MATCH("|"&UPPER(TRIM($G25)),Setup!$Q$21:$Q$60,0)),"NO RATE"),IFERROR(INDEX(Setup!$C$21:$C$60,MATCH(UPPER(TRIM($F25))&"|"&UPPER(TRIM($G25)),Setup!$P$21:$P$60,0)),IFERROR(INDEX(Setup!$C$21:$C$60,MATCH(UPPER(TRIM($G25))&"|"&UPPER(TRIM($F25)),Setup!$P$21:$P$60,0)),"NO RATE")))) | K25: =IF(OR($G25="",$H25="",NOT(ISNUMBER($I25))),"",ROUND($H25*$I25*(1+IF($J25="",Setup!$B$16,$J25)),2)) | L25: =IF($K25="","",ROUND($K25*Setup!$B$13,2)) | M25: =IF($K25="","",$K25-$L25) | N25: =IF(OR($M25="",$D25=""),"",ROUND($M25*IFERROR(IF(VLOOKUP($D25,Setup!$A$76:$C$87,3,FALSE)="",Setup!$B$14,VLOOKUP($D25,Setup!$A$76:$C$87,3,FALSE)),Setup!$B$14),2)) | O25: =IF(OR($M25="",$E25=""),"",ROUND($M25*IFERROR(IF(VLOOKUP($E25,Setup!$A$76:$C$87,3,FALSE)="",Setup!$B$15,VLOOKUP($E25,Setup!$A$76:$C$87,3,FALSE)),Setup!$B$15),2)) | P25: 500 | Q25: 0 | R25: 10200 | S25: 900 | T25: 0 | U25: =IF($K25="","",SUM($R25:$T25)) | V25: =IF($K25="","",$M25-(N($N25)+N($O25)+IF($P25="",Setup!$B$17,$P25)+N($Q25))-N($U25)) | W25: Paid | Z25: =IF($A25="","",DATE(YEAR($A25),MONTH($A25),1))
A26: 46278 | B26: DR-1022 | C26: TRUCK 1 | D26: R. Dela Cruz | E26: J. Santos | F26: BATAAN | G26: ARMOR | H26: 21 | I26: =IF($G26="","",IF($F26="",IFERROR(INDEX(Setup!$C$21:$C$60,MATCH("|"&UPPER(TRIM($G26)),Setup!$Q$21:$Q$60,0)),"NO RATE"),IFERROR(INDEX(Setup!$C$21:$C$60,MATCH(UPPER(TRIM($F26))&"|"&UPPER(TRIM($G26)),Setup!$P$21:$P$60,0)),IFERROR(INDEX(Setup!$C$21:$C$60,MATCH(UPPER(TRIM($G26))&"|"&UPPER(TRIM($F26)),Setup!$P$21:$P$60,0)),"NO RATE")))) | K26: =IF(OR($G26="",$H26="",NOT(ISNUMBER($I26))),"",ROUND($H26*$I26*(1+IF($J26="",Setup!$B$16,$J26)),2)) | L26: =IF($K26="","",ROUND($K26*Setup!$B$13,2)) | M26: =IF($K26="","",$K26-$L26) | N26: =IF(OR($M26="",$D26=""),"",ROUND($M26*IFERROR(IF(VLOOKUP($D26,Setup!$A$76:$C$87,3,FALSE)="",Setup!$B$14,VLOOKUP($D26,Setup!$A$76:$C$87,3,FALSE)),Setup!$B$14),2)) | O26: =IF(OR($M26="",$E26=""),"",ROUND($M26*IFERROR(IF(VLOOKUP($E26,Setup!$A$76:$C$87,3,FALSE)="",Setup!$B$15,VLOOKUP($E26,Setup!$A$76:$C$87,3,FALSE)),Setup!$B$15),2)) | P26: 500 | Q26: 0 | R26: 8900 | S26: 520 | T26: 0 | U26: =IF($K26="","",SUM($R26:$T26)) | V26: =IF($K26="","",$M26-(N($N26)+N($O26)+IF($P26="",Setup!$B$17,$P26)+N($Q26))-N($U26)) | W26: Paid | Z26: =IF($A26="","",DATE(YEAR($A26),MONTH($A26),1))
A27: 46280 | B27: DR-1023 | C27: TRUCK 1 | D27: M. Reyes | E27: A. Bautista | F27: ORION | G27: BULACAN | H27: 21 | I27: =IF($G27="","",IF($F27="",IFERROR(INDEX(Setup!$C$21:$C$60,MATCH("|"&UPPER(TRIM($G27)),Setup!$Q$21:$Q$60,0)),"NO RATE"),IFERROR(INDEX(Setup!$C$21:$C$60,MATCH(UPPER(TRIM($F27))&"|"&UPPER(TRIM($G27)),Setup!$P$21:$P$60,0)),IFERROR(INDEX(Setup!$C$21:$C$60,MATCH(UPPER(TRIM($G27))&"|"&UPPER(TRIM($F27)),Setup!$P$21:$P$60,0)),"NO RATE")))) | K27: =IF(OR($G27="",$H27="",NOT(ISNUMBER($I27))),"",ROUND($H27*$I27*(1+IF($J27="",Setup!$B$16,$J27)),2)) | L27: =IF($K27="","",ROUND($K27*Setup!$B$13,2)) | M27: =IF($K27="","",$K27-$L27) | N27: =IF(OR($M27="",$D27=""),"",ROUND($M27*IFERROR(IF(VLOOKUP($D27,Setup!$A$76:$C$87,3,FALSE)="",Setup!$B$14,VLOOKUP($D27,Setup!$A$76:$C$87,3,FALSE)),Setup!$B$14),2)) | O27: =IF(OR($M27="",$E27=""),"",ROUND($M27*IFERROR(IF(VLOOKUP($E27,Setup!$A$76:$C$87,3,FALSE)="",Setup!$B$15,VLOOKUP($E27,Setup!$A$76:$C$87,3,FALSE)),Setup!$B$15),2)) | P27: 500 | Q27: 0 | R27: 6000 | S27: 590 | T27: 0 | U27: =IF($K27="","",SUM($R27:$T27)) | V27: =IF($K27="","",$M27-(N($N27)+N($O27)+IF($P27="",Setup!$B$17,$P27)+N($Q27))-N($U27)) | W27: Paid | Z27: =IF($A27="","",DATE(YEAR($A27),MONTH($A27),1))
A28: 46281 | B28: DR-1024 | C28: TRUCK 1 | D28: R. Dela Cruz | E28: J. Santos | F28: MABINI, BATANGAS | G28: MONCADA | H28: 18 | I28: =IF($G28="","",IF($F28="",IFERROR(INDEX(Setup!$C$21:$C$60,MATCH("|"&UPPER(TRIM($G28)),Setup!$Q$21:$Q$60,0)),"NO RATE"),IFERROR(INDEX(Setup!$C$21:$C$60,MATCH(UPPER(TRIM($F28))&"|"&UPPER(TRIM($G28)),Setup!$P$21:$P$60,0)),IFERROR(INDEX(Setup!$C$21:$C$60,MATCH(UPPER(TRIM($G28))&"|"&UPPER(TRIM($F28)),Setup!$P$21:$P$60,0)),"NO RATE")))) | K28: =IF(OR($G28="",$H28="",NOT(ISNUMBER($I28))),"",ROUND($H28*$I28*(1+IF($J28="",Setup!$B$16,$J28)),2)) | L28: =IF($K28="","",ROUND($K28*Setup!$B$13,2)) | M28: =IF($K28="","",$K28-$L28) | N28: =IF(OR($M28="",$D28=""),"",ROUND($M28*IFERROR(IF(VLOOKUP($D28,Setup!$A$76:$C$87,3,FALSE)="",Setup!$B$14,VLOOKUP($D28,Setup!$A$76:$C$87,3,FALSE)),Setup!$B$14),2)) | O28: =IF(OR($M28="",$E28=""),"",ROUND($M28*IFERROR(IF(VLOOKUP($E28,Setup!$A$76:$C$87,3,FALSE)="",Setup!$B$15,VLOOKUP($E28,Setup!$A$76:$C$87,3,FALSE)),Setup!$B$15),2)) | P28: 500 | Q28: 450 | R28: 7700 | S28: 430 | T28: 0 | U28: =IF($K28="","",SUM($R28:$T28)) | V28: =IF($K28="","",$M28-(N($N28)+N($O28)+IF($P28="",Setup!$B$17,$P28)+N($Q28))-N($U28)) | W28: Paid | X28: helper not available, driver solo | Z28: =IF($A28="","",DATE(YEAR($A28),MONTH($A28),1))
A29: 46283 | B29: DR-1025 | C29: TRUCK 1 | D29: M. Reyes | E29: A. Bautista | F29: BATAAN | G29: BULACAN | H29: 21 | I29: =IF($G29="","",IF($F29="",IFERROR(INDEX(Setup!$C$21:$C$60,MATCH("|"&UPPER(TRIM($G29)),Setup!$Q$21:$Q$60,0)),"NO RATE"),IFERROR(INDEX(Setup!$C$21:$C$60,MATCH(UPPER(TRIM($F29))&"|"&UPPER(TRIM($G29)),Setup!$P$21:$P$60,0)),IFERROR(INDEX(Setup!$C$21:$C$60,MATCH(UPPER(TRIM($G29))&"|"&UPPER(TRIM($F29)),Setup!$P$21:$P$60,0)),"NO RATE")))) | K29: =IF(OR($G29="",$H29="",NOT(ISNUMBER($I29))),"",ROUND($H29*$I29*(1+IF($J29="",Setup!$B$16,$J29)),2)) | L29: =IF($K29="","",ROUND($K29*Setup!$B$13,2)) | M29: =IF($K29="","",$K29-$L29) | N29: =IF(OR($M29="",$D29=""),"",ROUND($M29*IFERROR(IF(VLOOKUP($D29,Setup!$A$76:$C$87,3,FALSE)="",Setup!$B$14,VLOOKUP($D29,Setup!$A$76:$C$87,3,FALSE)),Setup!$B$14),2)) | O29: =IF(OR($M29="",$E29=""),"",ROUND($M29*IFERROR(IF(VLOOKUP($E29,Setup!$A$76:$C$87,3,FALSE)="",Setup!$B$15,VLOOKUP($E29,Setup!$A$76:$C$87,3,FALSE)),Setup!$B$15),2)) | P29: 500 | Q29: 0 | R29: 8600 | S29: 480 | T29: 0 | U29: =IF($K29="","",SUM($R29:$T29)) | V29: =IF($K29="","",$M29-(N($N29)+N($O29)+IF($P29="",Setup!$B$17,$P29)+N($Q29))-N($U29)) | W29: Paid | Z29: =IF($A29="","",DATE(YEAR($A29),MONTH($A29),1))
A30: 46285 | B30: DR-1026 | C30: TRUCK 1 | D30: R. Dela Cruz | E30: J. Santos | F30: ORION | G30: ROSALES | H30: 19 | I30: =IF($G30="","",IF($F30="",IFERROR(INDEX(Setup!$C$21:$C$60,MATCH("|"&UPPER(TRIM($G30)),Setup!$Q$21:$Q$60,0)),"NO RATE"),IFERROR(INDEX(Setup!$C$21:$C$60,MATCH(UPPER(TRIM($F30))&"|"&UPPER(TRIM($G30)),Setup!$P$21:$P$60,0)),IFERROR(INDEX(Setup!$C$21:$C$60,MATCH(UPPER(TRIM($G30))&"|"&UPPER(TRIM($F30)),Setup!$P$21:$P$60,0)),"NO RATE")))) | K30: =IF(OR($G30="",$H30="",NOT(ISNUMBER($I30))),"",ROUND($H30*$I30*(1+IF($J30="",Setup!$B$16,$J30)),2)) | L30: =IF($K30="","",ROUND($K30*Setup!$B$13,2)) | M30: =IF($K30="","",$K30-$L30) | N30: =IF(OR($M30="",$D30=""),"",ROUND($M30*IFERROR(IF(VLOOKUP($D30,Setup!$A$76:$C$87,3,FALSE)="",Setup!$B$14,VLOOKUP($D30,Setup!$A$76:$C$87,3,FALSE)),Setup!$B$14),2)) | O30: =IF(OR($M30="",$E30=""),"",ROUND($M30*IFERROR(IF(VLOOKUP($E30,Setup!$A$76:$C$87,3,FALSE)="",Setup!$B$15,VLOOKUP($E30,Setup!$A$76:$C$87,3,FALSE)),Setup!$B$15),2)) | P30: 500 | Q30: 0 | R30: 6000 | S30: 700 | T30: 0 | U30: =IF($K30="","",SUM($R30:$T30)) | V30: =IF($K30="","",$M30-(N($N30)+N($O30)+IF($P30="",Setup!$B$17,$P30)+N($Q30))-N($U30)) | W30: Paid | Z30: =IF($A30="","",DATE(YEAR($A30),MONTH($A30),1))
A31: 46287 | B31: DR-1027 | C31: TRUCK 1 | D31: M. Reyes | E31: A. Bautista | F31: MABINI, BATANGAS | G31: BATAAN | H31: 18 | I31: =IF($G31="","",IF($F31="",IFERROR(INDEX(Setup!$C$21:$C$60,MATCH("|"&UPPER(TRIM($G31)),Setup!$Q$21:$Q$60,0)),"NO RATE"),IFERROR(INDEX(Setup!$C$21:$C$60,MATCH(UPPER(TRIM($F31))&"|"&UPPER(TRIM($G31)),Setup!$P$21:$P$60,0)),IFERROR(INDEX(Setup!$C$21:$C$60,MATCH(UPPER(TRIM($G31))&"|"&UPPER(TRIM($F31)),Setup!$P$21:$P$60,0)),"NO RATE")))) | K31: =IF(OR($G31="",$H31="",NOT(ISNUMBER($I31))),"",ROUND($H31*$I31*(1+IF($J31="",Setup!$B$16,$J31)),2)) | L31: =IF($K31="","",ROUND($K31*Setup!$B$13,2)) | M31: =IF($K31="","",$K31-$L31) | N31: =IF(OR($M31="",$D31=""),"",ROUND($M31*IFERROR(IF(VLOOKUP($D31,Setup!$A$76:$C$87,3,FALSE)="",Setup!$B$14,VLOOKUP($D31,Setup!$A$76:$C$87,3,FALSE)),Setup!$B$14),2)) | O31: =IF(OR($M31="",$E31=""),"",ROUND($M31*IFERROR(IF(VLOOKUP($E31,Setup!$A$76:$C$87,3,FALSE)="",Setup!$B$15,VLOOKUP($E31,Setup!$A$76:$C$87,3,FALSE)),Setup!$B$15),2)) | P31: 500 | Q31: 0 | R31: 11500 | S31: 880 | T31: 0 | U31: =IF($K31="","",SUM($R31:$T31)) | V31: =IF($K31="","",$M31-(N($N31)+N($O31)+IF($P31="",Setup!$B$17,$P31)+N($Q31))-N($U31)) | W31: Paid | Z31: =IF($A31="","",DATE(YEAR($A31),MONTH($A31),1))
A32: 46288 | B32: DR-1028 | C32: TRUCK 1 | D32: R. Dela Cruz | E32: J. Santos | F32: BATAAN | G32: BMEG BATAAN | H32: 21 | I32: =IF($G32="","",IF($F32="",IFERROR(INDEX(Setup!$C$21:$C$60,MATCH("|"&UPPER(TRIM($G32)),Setup!$Q$21:$Q$60,0)),"NO RATE"),IFERROR(INDEX(Setup!$C$21:$C$60,MATCH(UPPER(TRIM($F32))&"|"&UPPER(TRIM($G32)),Setup!$P$21:$P$60,0)),IFERROR(INDEX(Setup!$C$21:$C$60,MATCH(UPPER(TRIM($G32))&"|"&UPPER(TRIM($F32)),Setup!$P$21:$P$60,0)),"NO RATE")))) | K32: =IF(OR($G32="",$H32="",NOT(ISNUMBER($I32))),"",ROUND($H32*$I32*(1+IF($J32="",Setup!$B$16,$J32)),2)) | L32: =IF($K32="","",ROUND($K32*Setup!$B$13,2)) | M32: =IF($K32="","",$K32-$L32) | N32: =IF(OR($M32="",$D32=""),"",ROUND($M32*IFERROR(IF(VLOOKUP($D32,Setup!$A$76:$C$87,3,FALSE)="",Setup!$B$14,VLOOKUP($D32,Setup!$A$76:$C$87,3,FALSE)),Setup!$B$14),2)) | O32: =IF(OR($M32="",$E32=""),"",ROUND($M32*IFERROR(IF(VLOOKUP($E32,Setup!$A$76:$C$87,3,FALSE)="",Setup!$B$15,VLOOKUP($E32,Setup!$A$76:$C$87,3,FALSE)),Setup!$B$15),2)) | P32: 400 | Q32: 0 | R32: 1000 | S32: 120 | T32: 0 | U32: =IF($K32="","",SUM($R32:$T32)) | V32: =IF($K32="","",$M32-(N($N32)+N($O32)+IF($P32="",Setup!$B$17,$P32)+N($Q32))-N($U32)) | W32: Paid | Z32: =IF($A32="","",DATE(YEAR($A32),MONTH($A32),1))
A33: 46290 | B33: DR-1029 | C33: TRUCK 1 | D33: M. Reyes | E33: A. Bautista | F33: BATAAN | G33: TARLAC | H33: 17 | I33: =IF($G33="","",IF($F33="",IFERROR(INDEX(Setup!$C$21:$C$60,MATCH("|"&UPPER(TRIM($G33)),Setup!$Q$21:$Q$60,0)),"NO RATE"),IFERROR(INDEX(Setup!$C$21:$C$60,MATCH(UPPER(TRIM($F33))&"|"&UPPER(TRIM($G33)),Setup!$P$21:$P$60,0)),IFERROR(INDEX(Setup!$C$21:$C$60,MATCH(UPPER(TRIM($G33))&"|"&UPPER(TRIM($F33)),Setup!$P$21:$P$60,0)),"NO RATE")))) | K33: =IF(OR($G33="",$H33="",NOT(ISNUMBER($I33))),"",ROUND($H33*$I33*(1+IF($J33="",Setup!$B$16,$J33)),2)) | L33: =IF($K33="","",ROUND($K33*Setup!$B$13,2)) | M33: =IF($K33="","",$K33-$L33) | N33: =IF(OR($M33="",$D33=""),"",ROUND($M33*IFERROR(IF(VLOOKUP($D33,Setup!$A$76:$C$87,3,FALSE)="",Setup!$B$14,VLOOKUP($D33,Setup!$A$76:$C$87,3,FALSE)),Setup!$B$14),2)) | O33: =IF(OR($M33="",$E33=""),"",ROUND($M33*IFERROR(IF(VLOOKUP($E33,Setup!$A$76:$C$87,3,FALSE)="",Setup!$B$15,VLOOKUP($E33,Setup!$A$76:$C$87,3,FALSE)),Setup!$B$15),2)) | P33: 500 | Q33: 450 | R33: 5600 | S33: 620 | T33: 0 | U33: =IF($K33="","",SUM($R33:$T33)) | V33: =IF($K33="","",$M33-(N($N33)+N($O33)+IF($P33="",Setup!$B$17,$P33)+N($Q33))-N($U33)) | W33: Partial | Z33: =IF($A33="","",DATE(YEAR($A33),MONTH($A33),1))
A34: 46292 | B34: DR-1030 | C34: TRUCK 1 | D34: R. Dela Cruz | E34: J. Santos | F34: BATAAN | G34: BMPP | H34: 20 | I34: =IF($G34="","",IF($F34="",IFERROR(INDEX(Setup!$C$21:$C$60,MATCH("|"&UPPER(TRIM($G34)),Setup!$Q$21:$Q$60,0)),"NO RATE"),IFERROR(INDEX(Setup!$C$21:$C$60,MATCH(UPPER(TRIM($F34))&"|"&UPPER(TRIM($G34)),Setup!$P$21:$P$60,0)),IFERROR(INDEX(Setup!$C$21:$C$60,MATCH(UPPER(TRIM($G34))&"|"&UPPER(TRIM($F34)),Setup!$P$21:$P$60,0)),"NO RATE")))) | K34: =IF(OR($G34="",$H34="",NOT(ISNUMBER($I34))),"",ROUND($H34*$I34*(1+IF($J34="",Setup!$B$16,$J34)),2)) | L34: =IF($K34="","",ROUND($K34*Setup!$B$13,2)) | M34: =IF($K34="","",$K34-$L34) | N34: =IF(OR($M34="",$D34=""),"",ROUND($M34*IFERROR(IF(VLOOKUP($D34,Setup!$A$76:$C$87,3,FALSE)="",Setup!$B$14,VLOOKUP($D34,Setup!$A$76:$C$87,3,FALSE)),Setup!$B$14),2)) | O34: =IF(OR($M34="",$E34=""),"",ROUND($M34*IFERROR(IF(VLOOKUP($E34,Setup!$A$76:$C$87,3,FALSE)="",Setup!$B$15,VLOOKUP($E34,Setup!$A$76:$C$87,3,FALSE)),Setup!$B$15),2)) | P34: 500 | Q34: 0 | R34: 8300 | S34: 560 | T34: 0 | U34: =IF($K34="","",SUM($R34:$T34)) | V34: =IF($K34="","",$M34-(N($N34)+N($O34)+IF($P34="",Setup!$B$17,$P34)+N($Q34))-N($U34)) | W34: Partial | Z34: =IF($A34="","",DATE(YEAR($A34),MONTH($A34),1))
A35: 46296 | B35: DR-1031 | C35: TRUCK 1 | D35: R. Dela Cruz | E35: J. Santos | F35: BATAAN | G35: TARLAC | H35: 19 | I35: =IF($G35="","",IF($F35="",IFERROR(INDEX(Setup!$C$21:$C$60,MATCH("|"&UPPER(TRIM($G35)),Setup!$Q$21:$Q$60,0)),"NO RATE"),IFERROR(INDEX(Setup!$C$21:$C$60,MATCH(UPPER(TRIM($F35))&"|"&UPPER(TRIM($G35)),Setup!$P$21:$P$60,0)),IFERROR(INDEX(Setup!$C$21:$C$60,MATCH(UPPER(TRIM($G35))&"|"&UPPER(TRIM($F35)),Setup!$P$21:$P$60,0)),"NO RATE")))) | K35: =IF(OR($G35="",$H35="",NOT(ISNUMBER($I35))),"",ROUND($H35*$I35*(1+IF($J35="",Setup!$B$16,$J35)),2)) | L35: =IF($K35="","",ROUND($K35*Setup!$B$13,2)) | M35: =IF($K35="","",$K35-$L35) | N35: =IF(OR($M35="",$D35=""),"",ROUND($M35*IFERROR(IF(VLOOKUP($D35,Setup!$A$76:$C$87,3,FALSE)="",Setup!$B$14,VLOOKUP($D35,Setup!$A$76:$C$87,3,FALSE)),Setup!$B$14),2)) | O35: =IF(OR($M35="",$E35=""),"",ROUND($M35*IFERROR(IF(VLOOKUP($E35,Setup!$A$76:$C$87,3,FALSE)="",Setup!$B$15,VLOOKUP($E35,Setup!$A$76:$C$87,3,FALSE)),Setup!$B$15),2)) | P35: 500 | Q35: 0 | R35: 7400 | S35: 620 | T35: 0 | U35: =IF($K35="","",SUM($R35:$T35)) | V35: =IF($K35="","",$M35-(N($N35)+N($O35)+IF($P35="",Setup!$B$17,$P35)+N($Q35))-N($U35)) | W35: Paid | Z35: =IF($A35="","",DATE(YEAR($A35),MONTH($A35),1))
A36: 46297 | B36: DR-1032 | C36: TRUCK 1 | D36: M. Reyes | E36: A. Bautista | F36: BATAAN | G36: BMPP | H36: 19 | I36: =IF($G36="","",IF($F36="",IFERROR(INDEX(Setup!$C$21:$C$60,MATCH("|"&UPPER(TRIM($G36)),Setup!$Q$21:$Q$60,0)),"NO RATE"),IFERROR(INDEX(Setup!$C$21:$C$60,MATCH(UPPER(TRIM($F36))&"|"&UPPER(TRIM($G36)),Setup!$P$21:$P$60,0)),IFERROR(INDEX(Setup!$C$21:$C$60,MATCH(UPPER(TRIM($G36))&"|"&UPPER(TRIM($F36)),Setup!$P$21:$P$60,0)),"NO RATE")))) | K36: =IF(OR($G36="",$H36="",NOT(ISNUMBER($I36))),"",ROUND($H36*$I36*(1+IF($J36="",Setup!$B$16,$J36)),2)) | L36: =IF($K36="","",ROUND($K36*Setup!$B$13,2)) | M36: =IF($K36="","",$K36-$L36) | N36: =IF(OR($M36="",$D36=""),"",ROUND($M36*IFERROR(IF(VLOOKUP($D36,Setup!$A$76:$C$87,3,FALSE)="",Setup!$B$14,VLOOKUP($D36,Setup!$A$76:$C$87,3,FALSE)),Setup!$B$14),2)) | O36: =IF(OR($M36="",$E36=""),"",ROUND($M36*IFERROR(IF(VLOOKUP($E36,Setup!$A$76:$C$87,3,FALSE)="",Setup!$B$15,VLOOKUP($E36,Setup!$A$76:$C$87,3,FALSE)),Setup!$B$15),2)) | P36: 500 | Q36: 0 | R36: 7200 | S36: 560 | T36: 0 | U36: =IF($K36="","",SUM($R36:$T36)) | V36: =IF($K36="","",$M36-(N($N36)+N($O36)+IF($P36="",Setup!$B$17,$P36)+N($Q36))-N($U36)) | W36: Paid | Z36: =IF($A36="","",DATE(YEAR($A36),MONTH($A36),1))
A37: 46299 | B37: DR-1033 | C37: TRUCK 1 | D37: R. Dela Cruz | E37: J. Santos | F37: ORION | G37: BMPP | H37: 22 | I37: =IF($G37="","",IF($F37="",IFERROR(INDEX(Setup!$C$21:$C$60,MATCH("|"&UPPER(TRIM($G37)),Setup!$Q$21:$Q$60,0)),"NO RATE"),IFERROR(INDEX(Setup!$C$21:$C$60,MATCH(UPPER(TRIM($F37))&"|"&UPPER(TRIM($G37)),Setup!$P$21:$P$60,0)),IFERROR(INDEX(Setup!$C$21:$C$60,MATCH(UPPER(TRIM($G37))&"|"&UPPER(TRIM($F37)),Setup!$P$21:$P$60,0)),"NO RATE")))) | K37: =IF(OR($G37="",$H37="",NOT(ISNUMBER($I37))),"",ROUND($H37*$I37*(1+IF($J37="",Setup!$B$16,$J37)),2)) | L37: =IF($K37="","",ROUND($K37*Setup!$B$13,2)) | M37: =IF($K37="","",$K37-$L37) | N37: =IF(OR($M37="",$D37=""),"",ROUND($M37*IFERROR(IF(VLOOKUP($D37,Setup!$A$76:$C$87,3,FALSE)="",Setup!$B$14,VLOOKUP($D37,Setup!$A$76:$C$87,3,FALSE)),Setup!$B$14),2)) | O37: =IF(OR($M37="",$E37=""),"",ROUND($M37*IFERROR(IF(VLOOKUP($E37,Setup!$A$76:$C$87,3,FALSE)="",Setup!$B$15,VLOOKUP($E37,Setup!$A$76:$C$87,3,FALSE)),Setup!$B$15),2)) | P37: 500 | Q37: 0 | R37: 8600 | S37: 540 | T37: 0 | U37: =IF($K37="","",SUM($R37:$T37)) | V37: =IF($K37="","",$M37-(N($N37)+N($O37)+IF($P37="",Setup!$B$17,$P37)+N($Q37))-N($U37)) | W37: Paid | Z37: =IF($A37="","",DATE(YEAR($A37),MONTH($A37),1))
A38: 46301 | B38: DR-1034 | C38: TRUCK 1 | D38: M. Reyes | E38: A. Bautista | F38: MABINI, BATANGAS | G38: BMPP | H38: 21 | I38: =IF($G38="","",IF($F38="",IFERROR(INDEX(Setup!$C$21:$C$60,MATCH("|"&UPPER(TRIM($G38)),Setup!$Q$21:$Q$60,0)),"NO RATE"),IFERROR(INDEX(Setup!$C$21:$C$60,MATCH(UPPER(TRIM($F38))&"|"&UPPER(TRIM($G38)),Setup!$P$21:$P$60,0)),IFERROR(INDEX(Setup!$C$21:$C$60,MATCH(UPPER(TRIM($G38))&"|"&UPPER(TRIM($F38)),Setup!$P$21:$P$60,0)),"NO RATE")))) | K38: =IF(OR($G38="",$H38="",NOT(ISNUMBER($I38))),"",ROUND($H38*$I38*(1+IF($J38="",Setup!$B$16,$J38)),2)) | L38: =IF($K38="","",ROUND($K38*Setup!$B$13,2)) | M38: =IF($K38="","",$K38-$L38) | N38: =IF(OR($M38="",$D38=""),"",ROUND($M38*IFERROR(IF(VLOOKUP($D38,Setup!$A$76:$C$87,3,FALSE)="",Setup!$B$14,VLOOKUP($D38,Setup!$A$76:$C$87,3,FALSE)),Setup!$B$14),2)) | O38: =IF(OR($M38="",$E38=""),"",ROUND($M38*IFERROR(IF(VLOOKUP($E38,Setup!$A$76:$C$87,3,FALSE)="",Setup!$B$15,VLOOKUP($E38,Setup!$A$76:$C$87,3,FALSE)),Setup!$B$15),2)) | P38: 500 | Q38: 450 | R38: 14400 | S38: 980 | T38: 0 | U38: =IF($K38="","",SUM($R38:$T38)) | V38: =IF($K38="","",$M38-(N($N38)+N($O38)+IF($P38="",Setup!$B$17,$P38)+N($Q38))-N($U38)) | W38: Paid | Z38: =IF($A38="","",DATE(YEAR($A38),MONTH($A38),1))
A39: 46303 | B39: DR-1035 | C39: TRUCK 1 | D39: R. Dela Cruz | E39: J. Santos | F39: BATAAN | G39: ISABELA | H39: 17 | I39: =IF($G39="","",IF($F39="",IFERROR(INDEX(Setup!$C$21:$C$60,MATCH("|"&UPPER(TRIM($G39)),Setup!$Q$21:$Q$60,0)),"NO RATE"),IFERROR(INDEX(Setup!$C$21:$C$60,MATCH(UPPER(TRIM($F39))&"|"&UPPER(TRIM($G39)),Setup!$P$21:$P$60,0)),IFERROR(INDEX(Setup!$C$21:$C$60,MATCH(UPPER(TRIM($G39))&"|"&UPPER(TRIM($F39)),Setup!$P$21:$P$60,0)),"NO RATE")))) | K39: =IF(OR($G39="",$H39="",NOT(ISNUMBER($I39))),"",ROUND($H39*$I39*(1+IF($J39="",Setup!$B$16,$J39)),2)) | L39: =IF($K39="","",ROUND($K39*Setup!$B$13,2)) | M39: =IF($K39="","",$K39-$L39) | N39: =IF(OR($M39="",$D39=""),"",ROUND($M39*IFERROR(IF(VLOOKUP($D39,Setup!$A$76:$C$87,3,FALSE)="",Setup!$B$14,VLOOKUP($D39,Setup!$A$76:$C$87,3,FALSE)),Setup!$B$14),2)) | O39: =IF(OR($M39="",$E39=""),"",ROUND($M39*IFERROR(IF(VLOOKUP($E39,Setup!$A$76:$C$87,3,FALSE)="",Setup!$B$15,VLOOKUP($E39,Setup!$A$76:$C$87,3,FALSE)),Setup!$B$15),2)) | P39: 500 | Q39: 0 | R39: 14300 | S39: 1250 | T39: 0 | U39: =IF($K39="","",SUM($R39:$T39)) | V39: =IF($K39="","",$M39-(N($N39)+N($O39)+IF($P39="",Setup!$B$17,$P39)+N($Q39))-N($U39)) | W39: Paid | X39: long haul — diesel receipt attached | Z39: =IF($A39="","",DATE(YEAR($A39),MONTH($A39),1))
A40: 46305 | B40: DR-1036 | C40: TRUCK 1 | D40: M. Reyes | E40: A. Bautista | F40: ORION | G40: TARLAC | H40: 20 | I40: =IF($G40="","",IF($F40="",IFERROR(INDEX(Setup!$C$21:$C$60,MATCH("|"&UPPER(TRIM($G40)),Setup!$Q$21:$Q$60,0)),"NO RATE"),IFERROR(INDEX(Setup!$C$21:$C$60,MATCH(UPPER(TRIM($F40))&"|"&UPPER(TRIM($G40)),Setup!$P$21:$P$60,0)),IFERROR(INDEX(Setup!$C$21:$C$60,MATCH(UPPER(TRIM($G40))&"|"&UPPER(TRIM($F40)),Setup!$P$21:$P$60,0)),"NO RATE")))) | K40: =IF(OR($G40="",$H40="",NOT(ISNUMBER($I40))),"",ROUND($H40*$I40*(1+IF($J40="",Setup!$B$16,$J40)),2)) | L40: =IF($K40="","",ROUND($K40*Setup!$B$13,2)) | M40: =IF($K40="","",$K40-$L40) | N40: =IF(OR($M40="",$D40=""),"",ROUND($M40*IFERROR(IF(VLOOKUP($D40,Setup!$A$76:$C$87,3,FALSE)="",Setup!$B$14,VLOOKUP($D40,Setup!$A$76:$C$87,3,FALSE)),Setup!$B$14),2)) | O40: =IF(OR($M40="",$E40=""),"",ROUND($M40*IFERROR(IF(VLOOKUP($E40,Setup!$A$76:$C$87,3,FALSE)="",Setup!$B$15,VLOOKUP($E40,Setup!$A$76:$C$87,3,FALSE)),Setup!$B$15),2)) | P40: 500 | Q40: 0 | R40: 6400 | S40: 610 | T40: 0 | U40: =IF($K40="","",SUM($R40:$T40)) | V40: =IF($K40="","",$M40-(N($N40)+N($O40)+IF($P40="",Setup!$B$17,$P40)+N($Q40))-N($U40)) | W40: Paid | Z40: =IF($A40="","",DATE(YEAR($A40),MONTH($A40),1))
...

Sheet Expenses
A1: 🚚 EXPENSES — one row per receipt (fuel, repairs, toll, loans, rent, cash advances)
A2: Do NOT log crew pay here — the Payroll sheet computes it from Trips. Cash advances and payroll releases are logged here so the Payroll sheet can clear them.
A3: ALL-TIME TOTALS → | B3: =COUNT(5:1004)&" entries logged" | F3: =SUM(F5:F1004)
A4: DATE | B4: EXPENSE TYPE | C4: DESCRIPTION | D4: TRUCK | E4: PAID TO / LENDER | F4: AMOUNT | G4: PAYMENT METHOD | H4: RECEIPT? | I4: COST GROUP
A5: 46239 | B5: Repairs & Maintenance | C5: PMS + brake adjustment | D5: TRUCK 1 | E5: Casa Mechanic | F5: 8500 | G5: Cash | H5: Y | I5: =IF($B5="","",IFERROR(INDEX(Setup!$B$99:$B$128,MATCH($B5,Setup!$A$99:$A$128,0)),"CHECK TYPE")) | J5: =IF($A5="","",DATE(YEAR($A5),MONTH($A5),1))
A6: 46246 | B6: Insurance | C6: Comprehensive premium (quarterly) | D6: TRUCK 1 | E6: Fortune Insurance | F6: 18500 | G6: Bank Transfer | H6: Y | I6: =IF($B6="","",IFERROR(INDEX(Setup!$B$99:$B$128,MATCH($B6,Setup!$A$99:$A$128,0)),"CHECK TYPE")) | J6: =IF($A6="","",DATE(YEAR($A6),MONTH($A6),1))
A7: 46265 | B7: Loan Payment | C7: August amortisation | D7: TRUCK 1 | E7: BDO Leasing | F7: 32000 | G7: Bank Transfer | H7: Y | I7: =IF($B7="","",IFERROR(INDEX(Setup!$B$99:$B$128,MATCH($B7,Setup!$A$99:$A$128,0)),"CHECK TYPE")) | J7: =IF($A7="","",DATE(YEAR($A7),MONTH($A7),1))
A8: 46265 | B8: Loan Payment | C8: August amortisation | D8: TRUCK 1 | E8: Security Bank | F8: 18500 | G8: Bank Transfer | H8: Y | I8: =IF($B8="","",IFERROR(INDEX(Setup!$B$99:$B$128,MATCH($B8,Setup!$A$99:$A$128,0)),"CHECK TYPE")) | J8: =IF($A8="","",DATE(YEAR($A8),MONTH($A8),1))
A9: 46265 | B9: Loan Payment | C9: August amortisation | D9: TRUCK 1 | E9: Private Lender | F9: 12500 | G9: GCash | H9: N | I9: =IF($B9="","",IFERROR(INDEX(Setup!$B$99:$B$128,MATCH($B9,Setup!$A$99:$A$128,0)),"CHECK TYPE")) | J9: =IF($A9="","",DATE(YEAR($A9),MONTH($A9),1))
A10: 46265 | B10: Rent | C10: Yard rent | E10: Mrs. Lim | F10: 5000 | G10: Cash | H10: N | I10: =IF($B10="","",IFERROR(INDEX(Setup!$B$99:$B$128,MATCH($B10,Setup!$A$99:$A$128,0)),"CHECK TYPE")) | J10: =IF($A10="","",DATE(YEAR($A10),MONTH($A10),1))
A11: 46265 | B11: Payroll Payout | C11: August release | E11: R. Dela Cruz | F11: 13000 | G11: Cash | H11: N | I11: =IF($B11="","",IFERROR(INDEX(Setup!$B$99:$B$128,MATCH($B11,Setup!$A$99:$A$128,0)),"CHECK TYPE")) | J11: =IF($A11="","",DATE(YEAR($A11),MONTH($A11),1))
A12: 46265 | B12: Payroll Payout | C12: August release | E12: M. Reyes | F12: 13000 | G12: Cash | H12: N | I12: =IF($B12="","",IFERROR(INDEX(Setup!$B$99:$B$128,MATCH($B12,Setup!$A$99:$A$128,0)),"CHECK TYPE")) | J12: =IF($A12="","",DATE(YEAR($A12),MONTH($A12),1))
A13: 46269 | B13: Tires & Batteries | C13: 2 pcs rear tires | D13: TRUCK 1 | E13: Goodyear Dealer | F13: 21000 | G13: Bank Transfer | H13: Y | I13: =IF($B13="","",IFERROR(INDEX(Setup!$B$99:$B$128,MATCH($B13,Setup!$A$99:$A$128,0)),"CHECK TYPE")) | J13: =IF($A13="","",DATE(YEAR($A13),MONTH($A13),1))
A14: 46274 | B14: Repairs & Maintenance | C14: Clutch lining + labour | D14: TRUCK 1 | E14: Diesel Works | F14: 6200 | G14: Cash | H14: Y | I14: =IF($B14="","",IFERROR(INDEX(Setup!$B$99:$B$128,MATCH($B14,Setup!$A$99:$A$128,0)),"CHECK TYPE")) | J14: =IF($A14="","",DATE(YEAR($A14),MONTH($A14),1))
A15: 46275 | B15: LTO Registration | C15: Registration + emission test | D15: TRUCK 1 | E15: LTO | F15: 4200 | G15: Cash | H15: Y | I15: =IF($B15="","",IFERROR(INDEX(Setup!$B$99:$B$128,MATCH($B15,Setup!$A$99:$A$128,0)),"CHECK TYPE")) | J15: =IF($A15="","",DATE(YEAR($A15),MONTH($A15),1))
A16: 46280 | B16: Cash Advance | C16: Advance — family emergency | E16: R. Dela Cruz | F16: 5000 | G16: Cash | H16: N | I16: =IF($B16="","",IFERROR(INDEX(Setup!$B$99:$B$128,MATCH($B16,Setup!$A$99:$A$128,0)),"CHECK TYPE")) | J16: =IF($A16="","",DATE(YEAR($A16),MONTH($A16),1))
A17: 46285 | B17: Office / Staff Salary | C17: Dispatcher salary | E17: L. Garcia | F17: 12000 | G17: Cash | H17: N | I17: =IF($B17="","",IFERROR(INDEX(Setup!$B$99:$B$128,MATCH($B17,Setup!$A$99:$A$128,0)),"CHECK TYPE")) | J17: =IF($A17="","",DATE(YEAR($A17),MONTH($A17),1))
A18: 46295 | B18: Loan Payment | C18: September amortisation | D18: TRUCK 1 | E18: BDO Leasing | F18: 32000 | G18: Bank Transfer | H18: Y | I18: =IF($B18="","",IFERROR(INDEX(Setup!$B$99:$B$128,MATCH($B18,Setup!$A$99:$A$128,0)),"CHECK TYPE")) | J18: =IF($A18="","",DATE(YEAR($A18),MONTH($A18),1))
A19: 46295 | B19: Loan Payment | C19: September amortisation | D19: TRUCK 1 | E19: Security Bank | F19: 18500 | G19: Bank Transfer | H19: Y | I19: =IF($B19="","",IFERROR(INDEX(Setup!$B$99:$B$128,MATCH($B19,Setup!$A$99:$A$128,0)),"CHECK TYPE")) | J19: =IF($A19="","",DATE(YEAR($A19),MONTH($A19),1))
A20: 46295 | B20: Loan Payment | C20: September amortisation | D20: TRUCK 1 | E20: Private Lender | F20: 12500 | G20: GCash | H20: N | I20: =IF($B20="","",IFERROR(INDEX(Setup!$B$99:$B$128,MATCH($B20,Setup!$A$99:$A$128,0)),"CHECK TYPE")) | J20: =IF($A20="","",DATE(YEAR($A20),MONTH($A20),1))
A21: 46295 | B21: Rent | C21: Yard rent | E21: Mrs. Lim | F21: 5000 | G21: Cash | H21: N | I21: =IF($B21="","",IFERROR(INDEX(Setup!$B$99:$B$128,MATCH($B21,Setup!$A$99:$A$128,0)),"CHECK TYPE")) | J21: =IF($A21="","",DATE(YEAR($A21),MONTH($A21),1))
A22: 46295 | B22: Utilities | C22: Water + internet | E22: Meralco / PLDT | F22: 2800 | G22: GCash | H22: Y | I22: =IF($B22="","",IFERROR(INDEX(Setup!$B$99:$B$128,MATCH($B22,Setup!$A$99:$A$128,0)),"CHECK TYPE")) | J22: =IF($A22="","",DATE(YEAR($A22),MONTH($A22),1))
A23: 46295 | B23: Truck Washing | C23: Wash + greasing | D23: TRUCK 1 | E23: Jomar Carwash | F23: 700 | G23: Cash | H23: N | I23: =IF($B23="","",IFERROR(INDEX(Setup!$B$99:$B$128,MATCH($B23,Setup!$A$99:$A$128,0)),"CHECK TYPE")) | J23: =IF($A23="","",DATE(YEAR($A23),MONTH($A23),1))
A24: 46298 | B24: Cash Advance | C24: Trip pocket money | E24: J. Santos | F24: 3000 | G24: Cash | H24: N | I24: =IF($B24="","",IFERROR(INDEX(Setup!$B$99:$B$128,MATCH($B24,Setup!$A$99:$A$128,0)),"CHECK TYPE")) | J24: =IF($A24="","",DATE(YEAR($A24),MONTH($A24),1))
A25: 46303 | B25: Spare Parts & Lubricants | C25: Oil filters + coolant | D25: TRUCK 1 | E25: Truck Parts Center | F25: 3900 | G25: Cash | H25: Y | I25: =IF($B25="","",IFERROR(INDEX(Setup!$B$99:$B$128,MATCH($B25,Setup!$A$99:$A$128,0)),"CHECK TYPE")) | J25: =IF($A25="","",DATE(YEAR($A25),MONTH($A25),1))
A26: 46305 | B26: Truck Washing | C26: Wash + greasing | D26: TRUCK 1 | E26: Jomar Carwash | F26: 700 | G26: Cash | H26: N | I26: =IF($B26="","",IFERROR(INDEX(Setup!$B$99:$B$128,MATCH($B26,Setup!$A$99:$A$128,0)),"CHECK TYPE")) | J26: =IF($A26="","",DATE(YEAR($A26),MONTH($A26),1))
A27: 46307 | B27: Owner's Draw | C27: Owner's personal withdrawal | E27: Owner | F27: 15000 | G27: Cash | H27: N | I27: =IF($B27="","",IFERROR(INDEX(Setup!$B$99:$B$128,MATCH($B27,Setup!$A$99:$A$128,0)),"CHECK TYPE")) | J27: =IF($A27="","",DATE(YEAR($A27),MONTH($A27),1))
A28: 46310 | B28: Loan Payment | C28: October amortisation | D28: TRUCK 1 | E28: BDO Leasing | F28: 32000 | G28: Bank Transfer | H28: Y | I28: =IF($B28="","",IFERROR(INDEX(Setup!$B$99:$B$128,MATCH($B28,Setup!$A$99:$A$128,0)),"CHECK TYPE")) | J28: =IF($A28="","",DATE(YEAR($A28),MONTH($A28),1))
A29: 46310 | B29: Loan Payment | C29: October amortisation | D29: TRUCK 1 | E29: Security Bank | F29: 18500 | G29: Bank Transfer | H29: Y | I29: =IF($B29="","",IFERROR(INDEX(Setup!$B$99:$B$128,MATCH($B29,Setup!$A$99:$A$128,0)),"CHECK TYPE")) | J29: =IF($A29="","",DATE(YEAR($A29),MONTH($A29),1))
A30: 46311 | B30: Rent | C30: Yard rent | E30: Mrs. Lim | F30: 5000 | G30: Cash | H30: N | I30: =IF($B30="","",IFERROR(INDEX(Setup!$B$99:$B$128,MATCH($B30,Setup!$A$99:$A$128,0)),"CHECK TYPE")) | J30: =IF($A30="","",DATE(YEAR($A30),MONTH($A30),1))
A31: 46312 | B31: Utilities | C31: Water + internet | E31: Meralco / PLDT | F31: 2800 | G31: GCash | H31: Y | I31: =IF($B31="","",IFERROR(INDEX(Setup!$B$99:$B$128,MATCH($B31,Setup!$A$99:$A$128,0)),"CHECK TYPE")) | J31: =IF($A31="","",DATE(YEAR($A31),MONTH($A31),1))
A32: 46314 | B32: Payroll Payout | C32: Mid-month release | E32: R. Dela Cruz | F32: 10000 | G32: GCash | H32: N | I32: =IF($B32="","",IFERROR(INDEX(Setup!$B$99:$B$128,MATCH($B32,Setup!$A$99:$A$128,0)),"CHECK TYPE")) | J32: =IF($A32="","",DATE(YEAR($A32),MONTH($A32),1))
A33: 46315 | B33: Bank Charges | C33: InstaPay transfers | E33: BDO | F33: 350 | G33: Bank Transfer | H33: Y | I33: =IF($B33="","",IFERROR(INDEX(Setup!$B$99:$B$128,MATCH($B33,Setup!$A$99:$A$128,0)),"CHECK TYPE")) | J33: =IF($A33="","",DATE(YEAR($A33),MONTH($A33),1))
