Workbook
Name OffList: Lists!$A$6:$A$104
Name OffCat: Lists!$B$6:$B$104
Name StgList: Lists!$H$6:$H$15
Name StgPct: Lists!$I$6:$I$15
Name PriList: Lists!$J$6:$J$8
Name StatusList: Lists!$K$6:$K$11
Name OutcomeList: Lists!$L$6:$L$12
Name CourtList: Lists!$M$6:$M$14
Name CustodyList: Lists!$N$6:$N$11
Name PersonnelList: Lists!$O$6:$O$13
Name BrgyList: Lists!$P$6:$P$17
Name HearTypeList: Lists!$Q$6:$Q$13
Name HearResultList: Lists!$R$6:$R$12
Name CatList: Lists!$F$6:$F$15
Name LGUName: Lists!$C$120
Name Province: Lists!$C$121
Name OfficeName: Lists!$C$122
Name PreparedBy: Lists!$C$123
Name PeriodLabel: Lists!$C$125
Name AgeMonitor: Lists!$C$126
Name AgeFu: Lists!$C$127
Name AgeCrit: Lists!$C$128
Name AgeWindow: Lists!$C$129
Name RegCaseNo: 'Case Register'!$A$3:$A$602
Name RegTitle: 'Case Register'!$C$3:$C$602
Name RegOffense: 'Case Register'!$F$3:$F$602
Name RegCat: 'Case Register'!$G$3:$G$602
Name RegStage: 'Case Register'!$H$3:$H$602
Name RegPriority: 'Case Register'!$J$3:$J$602
Name RegStatus: 'Case Register'!$K$3:$K$602
Name RegOutcome: 'Case Register'!$L$3:$L$602
Name RegCourt: 'Case Register'!$M$3:$M$602
Name RegPersonnel: 'Case Register'!$O$3:$O$602
Name RegBrgy: 'Case Register'!$P$3:$P$602
Name RegNextHearing: 'Case Register'!$T$3:$T$602
Name RegAge: 'Case Register'!$AI$3:$AI$602
Name RegProgress: 'Case Register'!$AJ$3:$AJ$602
Name RegDaysStage: 'Case Register'!$AH$3:$AH$602
Name RegDaysPending: 'Case Register'!$AG$3:$AG$602
Name RegDocsPct: 'Case Register'!$AK$3:$AK$602
Name RegCustody: 'Case Register'!$W$3:$W$602
Name RegRankKey: 'Case Register'!$AP$3:$AP$602
Name RegFiled: 'Case Register'!$R$3:$R$602
Name RegDoc1: 'Case Register'!$Y$3:$Y$602
Name RegDoc2: 'Case Register'!$Z$3:$Z$602
Name RegDoc3: 'Case Register'!$AA$3:$AA$602
Name RegDoc4: 'Case Register'!$AB$3:$AB$602
Name RegDoc5: 'Case Register'!$AC$3:$AC$602
Name RegDoc6: 'Case Register'!$AD$3:$AD$602
Name RegDoc7: 'Case Register'!$AE$3:$AE$602
Name RegDoc8: 'Case Register'!$AF$3:$AF$602

Sheet Case Dashboard
B1: =UPPER(LGUName)&" • "&UPPER(Province)
B2: CRIMINAL CASE MONITORING DASHBOARD
B3: =PeriodLabel&" • As of "&TEXT(TODAY(),"dd mmmm yyyy")&" • Prepared by: "&PreparedBy&" • "&OfficeName
B6: CASE INVENTORY AT A GLANCE
B7: TOTAL CASES MONITORED | D7: ACTIVE CASES | F7: FOR ACTION | H7: RESOLVED / CLOSED | J7: HIGH PRIORITY | L7: AVERAGE CASE PROGRESS
B8: =COUNTA(RegCaseNo) | D8: =COUNTIF(RegStatus,"Active") | F8: =COUNTIF(RegStatus,"For Action") | H8: =COUNTIF(RegStatus,"Closed") | J8: =COUNTIF(RegPriority,"High") | L8: =IFERROR(AVERAGE(RegProgress),0)
B9: All records in the register | D9: Currently being acted upon | F9: Awaiting filing / assignment | H9: Closed, dismissed or decided | J9: Flagged for urgent attention | L9: Based on current stage
B11: AGEING AND RISK EXPOSURE (thresholds are set on the Lists sheet)
B12: CRITICAL | D12: FOR FOLLOW-UP | F12: UNDER MONITORING | H12: WITHIN STANDARD | J12: OVERDUE HEARINGS | L12: AVERAGE DAYS IN STAGE
B13: =COUNTIF(RegAge,"Critical") | D13: =COUNTIF(RegAge,"For Follow-up") | F13: =COUNTIF(RegAge,"Monitor") | H13: =COUNTIF(RegAge,"Within Standard") | J13: =COUNTIFS(RegNextHearing,"<"&TODAY(),RegStatus,"<>Closed") | L13: =IFERROR(ROUND(AVERAGE(RegDaysStage),0),0)
B14: =CONCATENATE("In stage over ",AgeCrit," days") | D14: =CONCATENATE("In stage over ",AgeFu," days") | F14: =CONCATENATE("In stage over ",AgeMonitor," days") | H14: Within the set threshold | J14: Next hearing date already passed | L14: Mean days in the current stage
B51: Legend: Critical / For follow-up / Monitor ageing is calculated from DAYS IN CURRENT STAGE against the thresholds on the Lists sheet. Red hearing dates are already overdue; gold dates fall inside the hearing window. All figures refresh from the Case Register, Hearing Calendar and Document Compliance sheets.

Sheet Case Register
A1: CASE IDENTIFICATION | H1: CASE PROGRESS, COURT AND ASSIGNMENT | Q1: KEY DATES | W1: CUSTODY AND BAIL | Y1: DOCUMENT COMPLETENESS (Y = on file, N = missing, N/A = not applicable) | AG1: AUTO-CALCULATED (do not type here)
A2: CASE NO. | B2: DATE RECORDED | C2: CASE TITLE (People of the Philippines v. ...) | D2: COMPLAINANT / VICTIM | E2: RESPONDENT / ACCUSED | F2: OFFENSE / VIOLATION | G2: OFFENSE CATEGORY | H2: CASE STAGE | I2: STAGE SINCE | J2: PRIORITY | K2: CASE STATUS | L2: OUTCOME | M2: COURT / FORUM | N2: COURT DOCKET NO. | O2: ASSIGNED PROSECUTOR / INVESTIGATOR | P2: BARANGAY / LOCATION | Q2: DATE OF INCIDENT | R2: DATE FILED / REFERRED | S2: DATE FILED IN COURT | T2: NEXT HEARING | U2: LAST HEARING | V2: DATE CLOSED / RESOLVED | W2: CUSTODY / BAIL STATUS | X2: DATE OF DETENTION | Y2: 1. Affidavit of Complaint | Z2: 2. Sworn Statement(s) | AA2: 3. Police / Incident Report | AB2: 4. Evidence and Exhibits | AC2: 5. Resolution / Information | AD2: 6. Court Order / Docket | AE2: 7. Bail / Bond Records | AF2: 8. Judgment / Order | AG2: DAYS PENDING (TOTAL) | AH2: DAYS IN CURRENT STAGE | AI2: STAGE AGEING | AJ2: CASE PROGRESS | AK2: DOCUMENTS COMPLETE | AL2: DAYS IN CUSTODY | AM2: REMARKS / NEXT ACTION | AN2: HELPER - AGE KEY | AO2: HELPER - HEARING KEY | AP2: HELPER - RANK KEY
A3: CC-2026-0001 | B3: 46134 | C3: People of the Philippines v. Rolando Dela Cruz y Santos | D3: Elena Dela Cruz | E3: Rolando Dela Cruz y Santos | F3: Murder | G3: =IF(A3="","",IFERROR(INDEX(OffCat,MATCH(F3,OffList,0)),"Unlisted")) | H3: Trial | I3: 46271 | J3: High | K3: Active | L3: Pending | M3: Regional Trial Court | N3: RTC-2026-1123 | O3: Atty. R. Villanueva | P3: Barangay 3 | Q3: 46106 | R3: 46134 | S3: 46166 | T3: 46320 | U3: 46290 | W3: In Custody - No Bail | X3: 46134 | Y3: Y | Z3: Y | AA3: Y | AB3: Y | AC3: Y | AD3: N | AE3: Y | AF3: N | AG3: =IF(A3="","",IF(V3<>"",V3-B3,TODAY()-B3)) | AH3: =IF(OR(A3="",I3=""),"",MAX(0,IF(V3<>"",V3-I3,TODAY()-I3))) | AI3: =IF(A3="","",IF(OR(K3="Closed",V3<>""),"Closed",IF(AH3>=AgeCrit,"Critical",IF(AH3>=AgeFu,"For Follow-up",IF(AH3>=AgeMonitor,"Monitor","Within Standard"))))) | AJ3: =IF(A3="","",IFERROR(INDEX(StgPct,MATCH(H3,StgList,0)),0)) | AK3: =IF(A3="","",IFERROR(COUNTIF(Y3:AF3,"Y")/(COUNTIF(Y3:AF3,"Y")+COUNTIF(Y3:AF3,"N")),0)) | AL3: =IF(OR(A3="",X3=""),"",MAX(0,IF(V3<>"",V3,TODAY())-X3)) | AM3: Prosecution presented 3rd witness; firearm evidence admitted. | AN3: =IF(A3="","",LOWER(AI3)&"|"&AH3&"|"&AJ3&"|"&AK3) | AO3: =IF(OR(A3="",T3=""),"",T3-TODAY()) | AP3: =IF(OR(A3="",V3<>""),"",(TODAY()-B3)+ROW()/1000000)
A4: CC-2026-0002 | B4: 46176 | C4: People of the Philippines v. Jayson Mercado y Lim | D4: PDEA Regional Office | E4: Jayson Mercado y Lim | F4: Illegal Sale of Dangerous Drugs | G4: =IF(A4="","",IFERROR(INDEX(OffCat,MATCH(F4,OffList,0)),"Unlisted")) | H4: Pre-Trial | I4: 46246 | J4: High | K4: Active | L4: Pending | M4: Regional Trial Court | N4: RTC-2026-1188 | O4: Atty. M. Fernandez | P4: Barangay 7 | Q4: 46156 | R4: 46176 | S4: 46196 | T4: 46328 | U4: 46298 | W4: In Custody - No Bail | X4: 46176 | Y4: Y | Z4: Y | AA4: Y | AB4: Y | AC4: Y | AD4: Y | AE4: Y | AF4: N | AG4: =IF(A4="","",IF(V4<>"",V4-B4,TODAY()-B4)) | AH4: =IF(OR(A4="",I4=""),"",MAX(0,IF(V4<>"",V4-I4,TODAY()-I4))) | AI4: =IF(A4="","",IF(OR(K4="Closed",V4<>""),"Closed",IF(AH4>=AgeCrit,"Critical",IF(AH4>=AgeFu,"For Follow-up",IF(AH4>=AgeMonitor,"Monitor","Within Standard"))))) | AJ4: =IF(A4="","",IFERROR(INDEX(StgPct,MATCH(H4,StgList,0)),0)) | AK4: =IF(A4="","",IFERROR(COUNTIF(Y4:AF4,"Y")/(COUNTIF(Y4:AF4,"Y")+COUNTIF(Y4:AF4,"N")),0)) | AL4: =IF(OR(A4="",X4=""),"",MAX(0,IF(V4<>"",V4,TODAY())-X4)) | AM4: Compliance with Sec. 21 RA 9165 stipulation; pre-trial order to follow. | AN4: =IF(A4="","",LOWER(AI4)&"|"&AH4&"|"&AJ4&"|"&AK4) | AO4: =IF(OR(A4="",T4=""),"",T4-TODAY()) | AP4: =IF(OR(A4="",V4<>""),"",(TODAY()-B4)+ROW()/1000000)
A5: CC-2026-0003 | B5: 46236 | C5: People of the Philippines v. Arnel Bautista y Reyes | D5: Ma. Cristina Lim | E5: Arnel Bautista y Reyes | F5: Theft | G5: =IF(A5="","",IFERROR(INDEX(OffCat,MATCH(F5,OffList,0)),"Unlisted")) | H5: Arraignment | I5: 46286 | J5: Medium | K5: Active | L5: Pending | M5: Metropolitan Trial Court | N5: MeTC-2026-0455 | O5: Atty. J. Aquino | P5: Barangay 1 | Q5: 46221 | R5: 46236 | S5: 46271 | T5: 46310 | U5: 46279 | W5: Released on Bail | Y5: Y | Z5: Y | AA5: N | AB5: Y | AC5: Y | AD5: N | AE5: Y | AF5: N | AG5: =IF(A5="","",IF(V5<>"",V5-B5,TODAY()-B5)) | AH5: =IF(OR(A5="",I5=""),"",MAX(0,IF(V5<>"",V5-I5,TODAY()-I5))) | AI5: =IF(A5="","",IF(OR(K5="Closed",V5<>""),"Closed",IF(AH5>=AgeCrit,"Critical",IF(AH5>=AgeFu,"For Follow-up",IF(AH5>=AgeMonitor,"Monitor","Within Standard"))))) | AJ5: =IF(A5="","",IFERROR(INDEX(StgPct,MATCH(H5,StgList,0)),0)) | AK5: =IF(A5="","",IFERROR(COUNTIF(Y5:AF5,"Y")/(COUNTIF(Y5:AF5,"Y")+COUNTIF(Y5:AF5,"N")),0)) | AL5: =IF(OR(A5="",X5=""),"",MAX(0,IF(V5<>"",V5,TODAY())-X5)) | AM5: Arraignment reset twice; notice of hearing re-served on counsel. | AN5: =IF(A5="","",LOWER(AI5)&"|"&AH5&"|"&AJ5&"|"&AK5) | AO5: =IF(OR(A5="",T5=""),"",T5-TODAY()) | AP5: =IF(OR(A5="",V5<>""),"",(TODAY()-B5)+ROW()/1000000)
A6: CC-2026-0004 | B6: 46276 | C6: People of the Philippines v. Danilo Perez y Cruz | D6: AAA (name withheld) | E6: Danilo Perez y Cruz | F6: Violation of VAWC Act | G6: =IF(A6="","",IFERROR(INDEX(OffCat,MATCH(F6,OffList,0)),"Unlisted")) | H6: Filed in Court | I6: 46306 | J6: High | K6: Active | L6: Pending | M6: Municipal Trial Court | N6: MTC-2026-0672 | O6: Atty. C. Bautista | P6: Barangay 5 | Q6: 46246 | R6: 46276 | S6: 46306 | T6: 46336 | W6: Released on Bail | Y6: Y | Z6: Y | AA6: N | AB6: Y | AC6: Y | AD6: Y | AE6: Y | AF6: N | AG6: =IF(A6="","",IF(V6<>"",V6-B6,TODAY()-B6)) | AH6: =IF(OR(A6="",I6=""),"",MAX(0,IF(V6<>"",V6-I6,TODAY()-I6))) | AI6: =IF(A6="","",IF(OR(K6="Closed",V6<>""),"Closed",IF(AH6>=AgeCrit,"Critical",IF(AH6>=AgeFu,"For Follow-up",IF(AH6>=AgeMonitor,"Monitor","Within Standard"))))) | AJ6: =IF(A6="","",IFERROR(INDEX(StgPct,MATCH(H6,StgList,0)),0)) | AK6: =IF(A6="","",IFERROR(COUNTIF(Y6:AF6,"Y")/(COUNTIF(Y6:AF6,"Y")+COUNTIF(Y6:AF6,"N")),0)) | AL6: =IF(OR(A6="",X6=""),"",MAX(0,IF(V6<>"",V6,TODAY())-X6)) | AM6: Warrant of arrest served; court ordered psychiatric evaluation. | AN6: =IF(A6="","",LOWER(AI6)&"|"&AH6&"|"&AJ6&"|"&AK6) | AO6: =IF(OR(A6="",T6=""),"",T6-TODAY()) | AP6: =IF(OR(A6="",V6<>""),"",(TODAY()-B6)+ROW()/1000000)
A7: CC-2026-0005 | B7: 46056 | C7: People of the Philippines v. Victoriano Salazar y Ang | D7: BBB (name withheld) | E7: Victoriano Salazar y Ang | F7: Rape | G7: =IF(A7="","",IFERROR(INDEX(OffCat,MATCH(F7,OffList,0)),"Unlisted")) | H7: Trial | I7: 46196 | J7: High | K7: Active | L7: Pending | M7: Regional Trial Court | N7: RTC-2026-0901 | O7: Atty. S. Navarro | P7: Barangay 2 | Q7: 46016 | R7: 46056 | S7: 46076 | T7: 46318 | U7: 46288 | W7: In Custody - No Bail | X7: 46016 | Y7: Y | Z7: Y | AA7: Y | AB7: Y | AC7: Y | AD7: Y | AE7: Y | AF7: N | AG7: =IF(A7="","",IF(V7<>"",V7-B7,TODAY()-B7)) | AH7: =IF(OR(A7="",I7=""),"",MAX(0,IF(V7<>"",V7-I7,TODAY()-I7))) | AI7: =IF(A7="","",IF(OR(K7="Closed",V7<>""),"Closed",IF(AH7>=AgeCrit,"Critical",IF(AH7>=AgeFu,"For Follow-up",IF(AH7>=AgeMonitor,"Monitor","Within Standard"))))) | AJ7: =IF(A7="","",IFERROR(INDEX(StgPct,MATCH(H7,StgList,0)),0)) | AK7: =IF(A7="","",IFERROR(COUNTIF(Y7:AF7,"Y")/(COUNTIF(Y7:AF7,"Y")+COUNTIF(Y7:AF7,"N")),0)) | AL7: =IF(OR(A7="",X7=""),"",MAX(0,IF(V7<>"",V7,TODAY())-X7)) | AM7: Victim testimony completed; counsel to file formal offer of evidence. | AN7: =IF(A7="","",LOWER(AI7)&"|"&AH7&"|"&AJ7&"|"&AK7) | AO7: =IF(OR(A7="",T7=""),"",T7-TODAY()) | AP7: =IF(OR(A7="",V7<>""),"",(TODAY()-B7)+ROW()/1000000)
A8: CC-2026-0006 | B8: 46291 | C8: People of the Philippines v. Lilia Manalo y Diaz | D8: Fernando Uy | E8: Lilia Manalo y Diaz | F8: Estafa | G8: =IF(A8="","",IFERROR(INDEX(OffCat,MATCH(F8,OffList,0)),"Unlisted")) | H8: Preliminary Investigation | I8: 46291 | J8: Medium | K8: For Action | L8: Pending | M8: Office of the Prosecutor | O8: Investigator P. Reyes | P8: Barangay 9 | Q8: 46256 | R8: 46291 | W8: N/A (Not in Custody) | Y8: Y | Z8: Y | AA8: N | AB8: Y | AC8: Y | AD8: N | AE8: N | AF8: N | AG8: =IF(A8="","",IF(V8<>"",V8-B8,TODAY()-B8)) | AH8: =IF(OR(A8="",I8=""),"",MAX(0,IF(V8<>"",V8-I8,TODAY()-I8))) | AI8: =IF(A8="","",IF(OR(K8="Closed",V8<>""),"Closed",IF(AH8>=AgeCrit,"Critical",IF(AH8>=AgeFu,"For Follow-up",IF(AH8>=AgeMonitor,"Monitor","Within Standard"))))) | AJ8: =IF(A8="","",IFERROR(INDEX(StgPct,MATCH(H8,StgList,0)),0)) | AK8: =IF(A8="","",IFERROR(COUNTIF(Y8:AF8,"Y")/(COUNTIF(Y8:AF8,"Y")+COUNTIF(Y8:AF8,"N")),0)) | AL8: =IF(OR(A8="",X8=""),"",MAX(0,IF(V8<>"",V8,TODAY())-X8)) | AM8: Awaiting counter-affidavit from respondent; clarify 15-day reglementary period. | AN8: =IF(A8="","",LOWER(AI8)&"|"&AH8&"|"&AJ8&"|"&AK8) | AO8: =IF(OR(A8="",T8=""),"",T8-TODAY()) | AP8: =IF(OR(A8="",V8<>""),"",(TODAY()-B8)+ROW()/1000000)
A9: CC-2026-0007 | B9: 46016 | C9: People of the Philippines v. Emmanuel Garcia y Tan | D9: Rodolfo Santos | E9: Emmanuel Garcia y Tan | F9: Serious Physical Injuries | G9: =IF(A9="","",IFERROR(INDEX(OffCat,MATCH(F9,OffList,0)),"Unlisted")) | H9: Judgment Rendered | I9: 46281 | J9: Medium | K9: Closed | L9: Convicted | M9: Municipal Trial Court | N9: MTC-2025-0912 | O9: Atty. J. Aquino | P9: Barangay 4 | Q9: 45996 | R9: 46016 | S9: 46036 | U9: 46276 | V9: 46286 | W9: Released on Bail | Y9: Y | Z9: Y | AA9: Y | AB9: Y | AC9: Y | AD9: Y | AE9: Y | AF9: Y | AG9: =IF(A9="","",IF(V9<>"",V9-B9,TODAY()-B9)) | AH9: =IF(OR(A9="",I9=""),"",MAX(0,IF(V9<>"",V9-I9,TODAY()-I9))) | AI9: =IF(A9="","",IF(OR(K9="Closed",V9<>""),"Closed",IF(AH9>=AgeCrit,"Critical",IF(AH9>=AgeFu,"For Follow-up",IF(AH9>=AgeMonitor,"Monitor","Within Standard"))))) | AJ9: =IF(A9="","",IFERROR(INDEX(StgPct,MATCH(H9,StgList,0)),0)) | AK9: =IF(A9="","",IFERROR(COUNTIF(Y9:AF9,"Y")/(COUNTIF(Y9:AF9,"Y")+COUNTIF(Y9:AF9,"N")),0)) | AL9: =IF(OR(A9="",X9=""),"",MAX(0,IF(V9<>"",V9,TODAY())-X9)) | AM9: Accused found guilty; penalty imposed. Certified true copy on file. | AN9: =IF(A9="","",LOWER(AI9)&"|"&AH9&"|"&AJ9&"|"&AK9) | AO9: =IF(OR(A9="",T9=""),"",T9-TODAY()) | AP9: =IF(OR(A9="",V9<>""),"",(TODAY()-B9)+ROW()/1000000)
A10: CC-2026-0008 | B10: 46146 | C10: People of the Philippines v. Rodelito Ramos y Bautista | D10: Ramon Ramos | E10: Rodelito Ramos y Bautista | F10: Reckless Imprudence Resulting in Homicide | G10: =IF(A10="","",IFERROR(INDEX(OffCat,MATCH(F10,OffList,0)),"Unlisted")) | H10: Trial | I10: 46261 | J10: Medium | K10: Active | L10: Pending | M10: Municipal Trial Court | N10: MTC-2026-0210 | O10: Atty. R. Villanueva | P10: Barangay 6 | Q10: 46116 | R10: 46146 | S10: 46166 | T10: 46325 | U10: 46296 | W10: Released on Bail | Y10: Y | Z10: Y | AA10: N | AB10: Y | AC10: Y | AD10: N | AE10: Y | AF10: Y | AG10: =IF(A10="","",IF(V10<>"",V10-B10,TODAY()-B10)) | AH10: =IF(OR(A10="",I10=""),"",MAX(0,IF(V10<>"",V10-I10,TODAY()-I10))) | AI10: =IF(A10="","",IF(OR(K10="Closed",V10<>""),"Closed",IF(AH10>=AgeCrit,"Critical",IF(AH10>=AgeFu,"For Follow-up",IF(AH10>=AgeMonitor,"Monitor","Within Standard"))))) | AJ10: =IF(A10="","",IFERROR(INDEX(StgPct,MATCH(H10,StgList,0)),0)) | AK10: =IF(A10="","",IFERROR(COUNTIF(Y10:AF10,"Y")/(COUNTIF(Y10:AF10,"Y")+COUNTIF(Y10:AF10,"N")),0)) | AL10: =IF(OR(A10="",X10=""),"",MAX(0,IF(V10<>"",V10,TODAY())-X10)) | AM10: Private prosecutor presented LTO records; next setting for defense evidence. | AN10: =IF(A10="","",LOWER(AI10)&"|"&AH10&"|"&AJ10&"|"&AK10) | AO10: =IF(OR(A10="",T10=""),"",T10-TODAY()) | AP10: =IF(OR(A10="",V10<>""),"",(TODAY()-B10)+ROW()/1000000)
A11: CC-2026-0009 | B11: 45936 | C11: People of the Philippines v. Henry Ocampo y Villar | D11: Josefina Tan | E11: Henry Ocampo y Villar | F11: Qualified Theft | G11: =IF(A11="","",IFERROR(INDEX(OffCat,MATCH(F11,OffList,0)),"Unlisted")) | H11: Submitted for Decision | I11: 46111 | J11: High | K11: Active | L11: Pending | M11: Regional Trial Court | N11: RTC-2026-0777 | O11: Atty. M. Fernandez | P11: Barangay 8 | Q11: 45916 | R11: 45936 | S11: 45966 | U11: 46106 | W11: Released on Bail | Y11: Y | Z11: Y | AA11: Y | AB11: Y | AC11: Y | AD11: Y | AE11: Y | AF11: N | AG11: =IF(A11="","",IF(V11<>"",V11-B11,TODAY()-B11)) | AH11: =IF(OR(A11="",I11=""),"",MAX(0,IF(V11<>"",V11-I11,TODAY()-I11))) | AI11: =IF(A11="","",IF(OR(K11="Closed",V11<>""),"Closed",IF(AH11>=AgeCrit,"Critical",IF(AH11>=AgeFu,"For Follow-up",IF(AH11>=AgeMonitor,"Monitor","Within Standard"))))) | AJ11: =IF(A11="","",IFERROR(INDEX(StgPct,MATCH(H11,StgList,0)),0)) | AK11: =IF(A11="","",IFERROR(COUNTIF(Y11:AF11,"Y")/(COUNTIF(Y11:AF11,"Y")+COUNTIF(Y11:AF11,"N")),0)) | AL11: =IF(OR(A11="",X11=""),"",MAX(0,IF(V11<>"",V11,TODAY())-X11)) | AM11: Case submitted for decision. Follow up with branch clerk of court. | AN11: =IF(A11="","",LOWER(AI11)&"|"&AH11&"|"&AJ11&"|"&AK11) | AO11: =IF(OR(A11="",T11=""),"",T11-TODAY()) | AP11: =IF(OR(A11="",V11<>""),"",(TODAY()-B11)+ROW()/1000000)
A12: CC-2025-0010 | B12: 45756 | C12: People of the Philippines v. Armando Sison y Uy | D12: Security Bank Corporation | E12: Armando Sison y Uy | F12: Robbery | G12: =IF(A12="","",IFERROR(INDEX(OffCat,MATCH(F12,OffList,0)),"Unlisted")) | H12: Trial | I12: 45906 | J12: High | K12: Active | L12: Pending | M12: Regional Trial Court | N12: RTC-2025-1450 | O12: Atty. S. Navarro | P12: Barangay 3 | Q12: 45716 | R12: 45756 | S12: 45796 | T12: 46331 | U12: 46281 | W12: In Custody - No Bail | X12: 45716 | Y12: Y | Z12: Y | AA12: Y | AB12: Y | AC12: N | AD12: N | AE12: Y | AF12: N | AG12: =IF(A12="","",IF(V12<>"",V12-B12,TODAY()-B12)) | AH12: =IF(OR(A12="",I12=""),"",MAX(0,IF(V12<>"",V12-I12,TODAY()-I12))) | AI12: =IF(A12="","",IF(OR(K12="Closed",V12<>""),"Closed",IF(AH12>=AgeCrit,"Critical",IF(AH12>=AgeFu,"For Follow-up",IF(AH12>=AgeMonitor,"Monitor","Within Standard"))))) | AJ12: =IF(A12="","",IFERROR(INDEX(StgPct,MATCH(H12,StgList,0)),0)) | AK12: =IF(A12="","",IFERROR(COUNTIF(Y12:AF12,"Y")/(COUNTIF(Y12:AF12,"Y")+COUNTIF(Y12:AF12,"N")),0)) | AL12: =IF(OR(A12="",X12=""),"",MAX(0,IF(V12<>"",V12,TODAY())-X12)) | AM12: Long-pending. Missing bail records and judgment docs; request from RTC records. | AN12: =IF(A12="","",LOWER(AI12)&"|"&AH12&"|"&AJ12&"|"&AK12) | AO12: =IF(OR(A12="",T12=""),"",T12-TODAY()) | AP12: =IF(OR(A12="",V12<>""),"",(TODAY()-B12)+ROW()/1000000)
A13: CC-2025-0011 | B13: 46166 | C13: People of the Philippines v. Carlos Miguel y Fernandez | D13: BBB (name withheld) | E13: Carlos Miguel y Fernandez | F13: Violation of VAWC Act | G13: =IF(A13="","",IFERROR(INDEX(OffCat,MATCH(F13,OffList,0)),"Unlisted")) | H13: Filed in Court | I13: 46226 | J13: High | K13: Active | L13: Pending | M13: Municipal Trial Court | N13: MTC-2025-0888 | O13: Atty. C. Bautista | P13: Barangay 10 | Q13: 46116 | R13: 46166 | S13: 46226 | T13: 46331 | U13: 46286 | W13: Released on Bail | Y13: Y | Z13: Y | AA13: N | AB13: Y | AC13: Y | AD13: N | AE13: Y | AF13: N | AG13: =IF(A13="","",IF(V13<>"",V13-B13,TODAY()-B13)) | AH13: =IF(OR(A13="",I13=""),"",MAX(0,IF(V13<>"",V13-I13,TODAY()-I13))) | AI13: =IF(A13="","",IF(OR(K13="Closed",V13<>""),"Closed",IF(AH13>=AgeCrit,"Critical",IF(AH13>=AgeFu,"For Follow-up",IF(AH13>=AgeMonitor,"Monitor","Within Standard"))))) | AJ13: =IF(A13="","",IFERROR(INDEX(StgPct,MATCH(H13,StgList,0)),0)) | AK13: =IF(A13="","",IFERROR(COUNTIF(Y13:AF13,"Y")/(COUNTIF(Y13:AF13,"Y")+COUNTIF(Y13:AF13,"N")),0)) | AL13: =IF(OR(A13="",X13=""),"",MAX(0,IF(V13<>"",V13,TODAY())-X13)) | AM13: Temporary protection order issued and extended for 30 days. | AN13: =IF(A13="","",LOWER(AI13)&"|"&AH13&"|"&AJ13&"|"&AK13) | AO13: =IF(OR(A13="",T13=""),"",T13-TODAY()) | AP13: =IF(OR(A13="",V13<>""),"",(TODAY()-B13)+ROW()/1000000)
A14: CC-2025-0012 | B14: 46196 | C14: People of the Philippines v. Ismael Tupaz y Garcia | D14: PNP Station 2 | E14: Ismael Tupaz y Garcia | F14: Illegal Possession of Firearms | G14: =IF(A14="","",IFERROR(INDEX(OffCat,MATCH(F14,OffList,0)),"Unlisted")) | H14: Arraignment | I14: 46256 | J14: Medium | K14: Active | L14: Pending | M14: Regional Trial Court | N14: RTC-2025-1290 | O14: Atty. R. Villanueva | P14: Barangay 7 | Q14: 46136 | R14: 46196 | S14: 46241 | T14: 46323 | U14: 46301 | W14: In Custody - With Bail | X14: 46136 | Y14: Y | Z14: Y | AA14: Y | AB14: Y | AC14: Y | AD14: N | AE14: Y | AF14: N | AG14: =IF(A14="","",IF(V14<>"",V14-B14,TODAY()-B14)) | AH14: =IF(OR(A14="",I14=""),"",MAX(0,IF(V14<>"",V14-I14,TODAY()-I14))) | AI14: =IF(A14="","",IF(OR(K14="Closed",V14<>""),"Closed",IF(AH14>=AgeCrit,"Critical",IF(AH14>=AgeFu,"For Follow-up",IF(AH14>=AgeMonitor,"Monitor","Within Standard"))))) | AJ14: =IF(A14="","",IFERROR(INDEX(StgPct,MATCH(H14,StgList,0)),0)) | AK14: =IF(A14="","",IFERROR(COUNTIF(Y14:AF14,"Y")/(COUNTIF(Y14:AF14,"Y")+COUNTIF(Y14:AF14,"N")),0)) | AL14: =IF(OR(A14="",X14=""),"",MAX(0,IF(V14<>"",V14,TODAY())-X14)) | AM14: Bail approved at PHP 120,000. Arraignment set with counsel present. | AN14: =IF(A14="","",LOWER(AI14)&"|"&AH14&"|"&AJ14&"|"&AK14) | AO14: =IF(OR(A14="",T14=""),"",T14-TODAY()) | AP14: =IF(OR(A14="",V14<>""),"",(TODAY()-B14)+ROW()/1000000)
A15: CC-2025-0013 | B15: 46066 | C15: People of the Philippines v. Teresita Cruz y Dela Peña | D15: DSWD Field Office | E15: Teresita Cruz y Dela Peña | F15: Child Abuse | G15: =IF(A15="","",IFERROR(INDEX(OffCat,MATCH(F15,OffList,0)),"Unlisted")) | H15: Pre-Trial | I15: 46166 | J15: High | K15: Active | L15: Pending | M15: Regional Trial Court | N15: RTC-2025-1102 | O15: Atty. M. Fernandez | P15: Barangay 5 | Q15: 46016 | R15: 46066 | S15: 46116 | T15: 46341 | U15: 46291 | W15: Released on Bail | Y15: Y | Z15: Y | AA15: Y | AB15: Y | AC15: N | AD15: Y | AE15: N | AF15: Y | AG15: =IF(A15="","",IF(V15<>"",V15-B15,TODAY()-B15)) | AH15: =IF(OR(A15="",I15=""),"",MAX(0,IF(V15<>"",V15-I15,TODAY()-I15))) | AI15: =IF(A15="","",IF(OR(K15="Closed",V15<>""),"Closed",IF(AH15>=AgeCrit,"Critical",IF(AH15>=AgeFu,"For Follow-up",IF(AH15>=AgeMonitor,"Monitor","Within Standard"))))) | AJ15: =IF(A15="","",IFERROR(INDEX(StgPct,MATCH(H15,StgList,0)),0)) | AK15: =IF(A15="","",IFERROR(COUNTIF(Y15:AF15,"Y")/(COUNTIF(Y15:AF15,"Y")+COUNTIF(Y15:AF15,"N")),0)) | AL15: =IF(OR(A15="",X15=""),"",MAX(0,IF(V15<>"",V15,TODAY())-X15)) | AM15: Child witness presented via video conference; pre-trial partly terminated. | AN15: =IF(A15="","",LOWER(AI15)&"|"&AH15&"|"&AJ15&"|"&AK15) | AO15: =IF(OR(A15="",T15=""),"",T15-TODAY()) | AP15: =IF(OR(A15="",V15<>""),"",(TODAY()-B15)+ROW()/1000000)
A16: CC-2025-0014 | B16: 45966 | C16: People of the Philippines v. Nicanor Abad y Lim | D16: Metro Hardware Supply | E16: Nicanor Abad y Lim | F16: Anti-Fencing | G16: =IF(A16="","",IFERROR(INDEX(OffCat,MATCH(F16,OffList,0)),"Unlisted")) | H16: Archived | I16: 46246 | J16: Low | K16: Closed | L16: Dismissed | M16: Metropolitan Trial Court | N16: MeTC-2025-0760 | O16: Atty. J. Aquino | P16: Barangay 2 | Q16: 45916 | R16: 45966 | S16: 46016 | V16: 46256 | W16: At Large | Y16: Y | Z16: Y | AA16: N | AB16: Y | AC16: N | AD16: N | AE16: N | AF16: N | AG16: =IF(A16="","",IF(V16<>"",V16-B16,TODAY()-B16)) | AH16: =IF(OR(A16="",I16=""),"",MAX(0,IF(V16<>"",V16-I16,TODAY()-I16))) | AI16: =IF(A16="","",IF(OR(K16="Closed",V16<>""),"Closed",IF(AH16>=AgeCrit,"Critical",IF(AH16>=AgeFu,"For Follow-up",IF(AH16>=AgeMonitor,"Monitor","Within Standard"))))) | AJ16: =IF(A16="","",IFERROR(INDEX(StgPct,MATCH(H16,StgList,0)),0)) | AK16: =IF(A16="","",IFERROR(COUNTIF(Y16:AF16,"Y")/(COUNTIF(Y16:AF16,"Y")+COUNTIF(Y16:AF16,"N")),0)) | AL16: =IF(OR(A16="",X16=""),"",MAX(0,IF(V16<>"",V16,TODAY())-X16)) | AM16: Dismissed on demurrer to evidence. Prosecutor did not appeal. | AN16: =IF(A16="","",LOWER(AI16)&"|"&AH16&"|"&AJ16&"|"&AK16) | AO16: =IF(OR(A16="",T16=""),"",T16-TODAY()) | AP16: =IF(OR(A16="",V16<>""),"",(TODAY()-B16)+ROW()/1000000)
A17: CC-2025-0015 | B17: 46311 | C17: People of the Philippines v. Joel Manalo y Reyes | D17: Barangay 6 Council | E17: Joel Manalo y Reyes | F17: Illegal Gambling | G17: =IF(A17="","",IFERROR(INDEX(OffCat,MATCH(F17,OffList,0)),"Unlisted")) | H17: For Filing | I17: 46311 | J17: Low | K17: For Action | L17: Pending | M17: Office of the Prosecutor | O17: Investigator L. Gomez | P17: Barangay 6 | Q17: 46304 | R17: 46311 | W17: N/A (Not in Custody) | Y17: Y | Z17: N | AA17: N | AB17: N | AC17: N | AD17: N | AE17: N | AF17: N | AG17: =IF(A17="","",IF(V17<>"",V17-B17,TODAY()-B17)) | AH17: =IF(OR(A17="",I17=""),"",MAX(0,IF(V17<>"",V17-I17,TODAY()-I17))) | AI17: =IF(A17="","",IF(OR(K17="Closed",V17<>""),"Closed",IF(AH17>=AgeCrit,"Critical",IF(AH17>=AgeFu,"For Follow-up",IF(AH17>=AgeMonitor,"Monitor","Within Standard"))))) | AJ17: =IF(A17="","",IFERROR(INDEX(StgPct,MATCH(H17,StgList,0)),0)) | AK17: =IF(A17="","",IFERROR(COUNTIF(Y17:AF17,"Y")/(COUNTIF(Y17:AF17,"Y")+COUNTIF(Y17:AF17,"N")),0)) | AL17: =IF(OR(A17="",X17=""),"",MAX(0,IF(V17<>"",V17,TODAY())-X17)) | AM17: New referral. Complete sworn statements and police blotter before filing. | AN17: =IF(A17="","",LOWER(AI17)&"|"&AH17&"|"&AJ17&"|"&AK17) | AO17: =IF(OR(A17="",T17=""),"",T17-TODAY()) | AP17: =IF(OR(A17="",V17<>""),"",(TODAY()-B17)+ROW()/1000000)
A18: CC-2025-0016 | B18: 46246 | C18: People of the Philippines v. Kristine Joy Salcedo | D18: Marvin Chua | E18: Kristine Joy Salcedo | F18: Cyber Libel | G18: =IF(A18="","",IFERROR(INDEX(OffCat,MATCH(F18,OffList,0)),"Unlisted")) | H18: Filed in Court | I18: 46281 | J18: Medium | K18: Active | L18: Pending | M18: Regional Trial Court | N18: RTC-2025-1401 | O18: Atty. S. Navarro | P18: Barangay 1 | Q18: 46196 | R18: 46246 | S18: 46281 | T18: 46351 | W18: Released on Bail | Y18: Y | Z18: Y | AA18: N | AB18: Y | AC18: Y | AD18: N | AE18: N | AF18: N | AG18: =IF(A18="","",IF(V18<>"",V18-B18,TODAY()-B18)) | AH18: =IF(OR(A18="",I18=""),"",MAX(0,IF(V18<>"",V18-I18,TODAY()-I18))) | AI18: =IF(A18="","",IF(OR(K18="Closed",V18<>""),"Closed",IF(AH18>=AgeCrit,"Critical",IF(AH18>=AgeFu,"For Follow-up",IF(AH18>=AgeMonitor,"Monitor","Within Standard"))))) | AJ18: =IF(A18="","",IFERROR(INDEX(StgPct,MATCH(H18,StgList,0)),0)) | AK18: =IF(A18="","",IFERROR(COUNTIF(Y18:AF18,"Y")/(COUNTIF(Y18:AF18,"Y")+COUNTIF(Y18:AF18,"N")),0)) | AL18: =IF(OR(A18="",X18=""),"",MAX(0,IF(V18<>"",V18,TODAY())-X18)) | AM18: Preservation order on social media posts granted; awaiting URL certification. | AN18: =IF(A18="","",LOWER(AI18)&"|"&AH18&"|"&AJ18&"|"&AK18) | AO18: =IF(OR(A18="",T18=""),"",T18-TODAY()) | AP18: =IF(OR(A18="",V18<>""),"",(TODAY()-B18)+ROW()/1000000)
A19: CC-2025-0017 | B19: 46096 | C19: People of the Philippines v. Bonifacio Alonzo y Perez | D19: BFAR Municipal Office | E19: Bonifacio Alonzo y Perez | F19: Illegal Fishing | G19: =IF(A19="","",IFERROR(INDEX(OffCat,MATCH(F19,OffList,0)),"Unlisted")) | H19: Trial | I19: 46191 | J19: Medium | K19: Active | L19: Pending | M19: Municipal Trial Court | N19: MTC-2025-0819 | O19: Investigator P. Reyes | P19: Poblacion | Q19: 46066 | R19: 46096 | S19: 46126 | T19: 46335 | U19: 46286 | W19: Released on Recognizance | Y19: Y | Z19: Y | AA19: N | AB19: Y | AC19: Y | AD19: N | AE19: Y | AF19: N | AG19: =IF(A19="","",IF(V19<>"",V19-B19,TODAY()-B19)) | AH19: =IF(OR(A19="",I19=""),"",MAX(0,IF(V19<>"",V19-I19,TODAY()-I19))) | AI19: =IF(A19="","",IF(OR(K19="Closed",V19<>""),"Closed",IF(AH19>=AgeCrit,"Critical",IF(AH19>=AgeFu,"For Follow-up",IF(AH19>=AgeMonitor,"Monitor","Within Standard"))))) | AJ19: =IF(A19="","",IFERROR(INDEX(StgPct,MATCH(H19,StgList,0)),0)) | AK19: =IF(A19="","",IFERROR(COUNTIF(Y19:AF19,"Y")/(COUNTIF(Y19:AF19,"Y")+COUNTIF(Y19:AF19,"N")),0)) | AL19: =IF(OR(A19="",X19=""),"",MAX(0,IF(V19<>"",V19,TODAY())-X19)) | AM19: Boat and gear forfeited in favor of government; trial on the merits ongoing. | AN19: =IF(A19="","",LOWER(AI19)&"|"&AH19&"|"&AJ19&"|"&AK19) | AO19: =IF(OR(A19="",T19=""),"",T19-TODAY()) | AP19: =IF(OR(A19="",V19<>""),"",(TODAY()-B19)+ROW()/1000000)
A20: CC-2025-0018 | B20: 46066 | C20: People of the Philippines v. Alfonso Trinidad | D20: Barangay 4 Residents | E20: Alfonso Trinidad | F20: Violation of Local Ordinance | G20: =IF(A20="","",IFERROR(INDEX(OffCat,MATCH(F20,OffList,0)),"Unlisted")) | H20: Archived | I20: 46116 | J20: Low | K20: Closed | L20: Archived / Referred | M20: Katarungang Pambarangay | O20: Atty. C. Bautista | P20: Barangay 4 | Q20: 46016 | R20: 46066 | V20: 46116 | W20: N/A (Not in Custody) | Y20: Y | Z20: N | AA20: Y | AB20: N | AC20: N | AD20: N | AE20: N | AF20: N | AG20: =IF(A20="","",IF(V20<>"",V20-B20,TODAY()-B20)) | AH20: =IF(OR(A20="",I20=""),"",MAX(0,IF(V20<>"",V20-I20,TODAY()-I20))) | AI20: =IF(A20="","",IF(OR(K20="Closed",V20<>""),"Closed",IF(AH20>=AgeCrit,"Critical",IF(AH20>=AgeFu,"For Follow-up",IF(AH20>=AgeMonitor,"Monitor","Within Standard"))))) | AJ20: =IF(A20="","",IFERROR(INDEX(StgPct,MATCH(H20,StgList,0)),0)) | AK20: =IF(A20="","",IFERROR(COUNTIF(Y20:AF20,"Y")/(COUNTIF(Y20:AF20,"Y")+COUNTIF(Y20:AF20,"N")),0)) | AL20: =IF(OR(A20="",X20=""),"",MAX(0,IF(V20<>"",V20,TODAY())-X20)) | AM20: Settled before the Lupong Tagapamayapa; amicable settlement executed. | AN20: =IF(A20="","",LOWER(AI20)&"|"&AH20&"|"&AJ20&"|"&AK20) | AO20: =IF(OR(A20="",T20=""),"",T20-TODAY()) | AP20: =IF(OR(A20="",V20<>""),"",(TODAY()-B20)+ROW()/1000000)
A21: CC-2025-0019 | B21: 45466 | C21: People of the Philippines v. Federico Ledesma y Sy | D21: Heirs of Lorenzo Uy | E21: Federico Ledesma y Sy | F21: Homicide | G21: =IF(A21="","",IFERROR(INDEX(OffCat,MATCH(F21,OffList,0)),"Unlisted")) | H21: Appeal / Review | I21: 46016 | J21: High | K21: Active | L21: Pending | M21: Court of Appeals | N21: CA-GR-2025-1234 | O21: Atty. R. Villanueva | P21: Barangay 9 | Q21: 45416 | R21: 45466 | S21: 45516 | U21: 46016 | W21: In Custody - No Bail | X21: 45416 | Y21: Y | Z21: Y | AA21: Y | AB21: Y | AC21: Y | AD21: Y | AE21: Y | AF21: N | AG21: =IF(A21="","",IF(V21<>"",V21-B21,TODAY()-B21)) | AH21: =IF(OR(A21="",I21=""),"",MAX(0,IF(V21<>"",V21-I21,TODAY()-I21))) | AI21: =IF(A21="","",IF(OR(K21="Closed",V21<>""),"Closed",IF(AH21>=AgeCrit,"Critical",IF(AH21>=AgeFu,"For Follow-up",IF(AH21>=AgeMonitor,"Monitor","Within Standard"))))) | AJ21: =IF(A21="","",IFERROR(INDEX(StgPct,MATCH(H21,StgList,0)),0)) | AK21: =IF(A21="","",IFERROR(COUNTIF(Y21:AF21,"Y")/(COUNTIF(Y21:AF21,"Y")+COUNTIF(Y21:AF21,"N")),0)) | AL21: =IF(OR(A21="",X21=""),"",MAX(0,IF(V21<>"",V21,TODAY())-X21)) | AM21: Appeal pending. Manifestation with compliance filed; monitor CA resolution. | AN21: =IF(A21="","",LOWER(AI21)&"|"&AH21&"|"&AJ21&"|"&AK21) | AO21: =IF(OR(A21="",T21=""),"",T21-TODAY()) | AP21: =IF(OR(A21="",V21<>""),"",(TODAY()-B21)+ROW()/1000000)
A22: CC-2025-0020 | B22: 46016 | C22: People of the Philippines v. Lauro Domingo y Aquino | D22: Pedro Aquino | E22: Lauro Domingo y Aquino | F22: Frustrated Murder | G22: =IF(A22="","",IFERROR(INDEX(OffCat,MATCH(F22,OffList,0)),"Unlisted")) | H22: Trial | I22: 46231 | J22: High | K22: Active | L22: Pending | M22: Regional Trial Court | N22: RTC-2025-1355 | O22: Atty. M. Fernandez | P22: Barangay 3 | Q22: 45966 | R22: 46016 | S22: 46056 | T22: 46334 | U22: 46294 | W22: In Custody - No Bail | X22: 46016 | Y22: Y | Z22: Y | AA22: Y | AB22: Y | AC22: Y | AD22: N | AE22: Y | AF22: N | AG22: =IF(A22="","",IF(V22<>"",V22-B22,TODAY()-B22)) | AH22: =IF(OR(A22="",I22=""),"",MAX(0,IF(V22<>"",V22-I22,TODAY()-I22))) | AI22: =IF(A22="","",IF(OR(K22="Closed",V22<>""),"Closed",IF(AH22>=AgeCrit,"Critical",IF(AH22>=AgeFu,"For Follow-up",IF(AH22>=AgeMonitor,"Monitor","Within Standard"))))) | AJ22: =IF(A22="","",IFERROR(INDEX(StgPct,MATCH(H22,StgList,0)),0)) | AK22: =IF(A22="","",IFERROR(COUNTIF(Y22:AF22,"Y")/(COUNTIF(Y22:AF22,"Y")+COUNTIF(Y22:AF22,"N")),0)) | AL22: =IF(OR(A22="",X22=""),"",MAX(0,IF(V22<>"",V22,TODAY())-X22)) | AM22: Medico-legal report admitted; defense to present rebuttal witness. | AN22: =IF(A22="","",LOWER(AI22)&"|"&AH22&"|"&AJ22&"|"&AK22) | AO22: =IF(OR(A22="",T22=""),"",T22-TODAY()) | AP22: =IF(OR(A22="",V22<>""),"",(TODAY()-B22)+ROW()/1000000)
A23: CC-2026-0021 | B23: 46276 | C23: People of the Philippines v. Marilou Sanchez y Reyes | D23: Inter-Agency Council Against Trafficking | E23: Marilou Sanchez y Reyes | F23: Trafficking in Persons | G23: =IF(A23="","",IFERROR(INDEX(OffCat,MATCH(F23,OffList,0)),"Unlisted")) | H23: Preliminary Investigation | I23: 46276 | J23: High | K23: For Action | L23: Pending | M23: Office of the Prosecutor | O23: Atty. S. Navarro | P23: Barangay 8 | Q23: 46226 | R23: 46276 | W23: Released on Bail | Y23: Y | Z23: Y | AA23: N | AB23: Y | AC23: Y | AD23: N | AE23: N | AF23: N | AG23: =IF(A23="","",IF(V23<>"",V23-B23,TODAY()-B23)) | AH23: =IF(OR(A23="",I23=""),"",MAX(0,IF(V23<>"",V23-I23,TODAY()-I23))) | AI23: =IF(A23="","",IF(OR(K23="Closed",V23<>""),"Closed",IF(AH23>=AgeCrit,"Critical",IF(AH23>=AgeFu,"For Follow-up",IF(AH23>=AgeMonitor,"Monitor","Within Standard"))))) | AJ23: =IF(A23="","",IFERROR(INDEX(StgPct,MATCH(H23,StgList,0)),0)) | AK23: =IF(A23="","",IFERROR(COUNTIF(Y23:AF23,"Y")/(COUNTIF(Y23:AF23,"Y")+COUNTIF(Y23:AF23,"N")),0)) | AL23: =IF(OR(A23="",X23=""),"",MAX(0,IF(V23<>"",V23,TODAY())-X23)) | AM23: PI ongoing; victim-witness protection referral requested from DOJ. | AN23: =IF(A23="","",LOWER(AI23)&"|"&AH23&"|"&AJ23&"|"&AK23) | AO23: =IF(OR(A23="",T23=""),"",T23-TODAY()) | AP23: =IF(OR(A23="",V23<>""),"",(TODAY()-B23)+ROW()/1000000)
A24: CC-2026-0022 | B24: 46216 | C24: People of the Philippines v. Ruben Castillo y Tan | D24: Golden Grain Traders | E24: Ruben Castillo y Tan | F24: Bouncing Checks | G24: =IF(A24="","",IFERROR(INDEX(OffCat,MATCH(F24,OffList,0)),"Unlisted")) | H24: Filed in Court | I24: 46296 | J24: Low | K24: Active | L24: Pending | M24: Metropolitan Trial Court | N24: MeTC-2026-0511 | O24: Atty. J. Aquino | P24: Barangay 2 | Q24: 46166 | R24: 46216 | S24: 46296 | T24: 46321 | W24: Released on Bail | Y24: Y | Z24: Y | AA24: N | AB24: Y | AC24: Y | AD24: N | AE24: Y | AF24: N | AG24: =IF(A24="","",IF(V24<>"",V24-B24,TODAY()-B24)) | AH24: =IF(OR(A24="",I24=""),"",MAX(0,IF(V24<>"",V24-I24,TODAY()-I24))) | AI24: =IF(A24="","",IF(OR(K24="Closed",V24<>""),"Closed",IF(AH24>=AgeCrit,"Critical",IF(AH24>=AgeFu,"For Follow-up",IF(AH24>=AgeMonitor,"Monitor","Within Standard"))))) | AJ24: =IF(A24="","",IFERROR(INDEX(StgPct,MATCH(H24,StgList,0)),0)) | AK24: =IF(A24="","",IFERROR(COUNTIF(Y24:AF24,"Y")/(COUNTIF(Y24:AF24,"Y")+COUNTIF(Y24:AF24,"N")),0)) | AL24: =IF(OR(A24="",X24=""),"",MAX(0,IF(V24<>"",V24,TODAY())-X24)) | AM24: Court directed parties to explore compromise; reset for status conference. | AN24: =IF(A24="","",LOWER(AI24)&"|"&AH24&"|"&AJ24&"|"&AK24) | AO24: =IF(OR(A24="",T24=""),"",T24-TODAY()) | AP24: =IF(OR(A24="",V24<>""),"",(TODAY()-B24)+ROW()/1000000)
A25: CC-2026-0023 | B25: 46116 | C25: People of the Philippines v. Edgar Villamor y Cruz | D25: Bureau of Fire Protection | E25: Edgar Villamor y Cruz | F25: Arson | G25: =IF(A25="","",IFERROR(INDEX(OffCat,MATCH(F25,OffList,0)),"Unlisted")) | H25: Trial | I25: 46251 | J25: High | K25: Active | L25: Pending | M25: Regional Trial Court | N25: RTC-2026-1002 | O25: Atty. R. Villanueva | P25: Barangay 6 | Q25: 46076 | R25: 46116 | S25: 46146 | T25: 46356 | U25: 46304 | W25: In Custody - With Bail | X25: 46076 | Y25: Y | Z25: Y | AA25: Y | AB25: Y | AC25: Y | AD25: N | AE25: Y | AF25: N | AG25: =IF(A25="","",IF(V25<>"",V25-B25,TODAY()-B25)) | AH25: =IF(OR(A25="",I25=""),"",MAX(0,IF(V25<>"",V25-I25,TODAY()-I25))) | AI25: =IF(A25="","",IF(OR(K25="Closed",V25<>""),"Closed",IF(AH25>=AgeCrit,"Critical",IF(AH25>=AgeFu,"For Follow-up",IF(AH25>=AgeMonitor,"Monitor","Within Standard"))))) | AJ25: =IF(A25="","",IFERROR(INDEX(StgPct,MATCH(H25,StgList,0)),0)) | AK25: =IF(A25="","",IFERROR(COUNTIF(Y25:AF25,"Y")/(COUNTIF(Y25:AF25,"Y")+COUNTIF(Y25:AF25,"N")),0)) | AL25: =IF(OR(A25="",X25=""),"",MAX(0,IF(V25<>"",V25,TODAY())-X25)) | AM25: Fire investigator testimony taken; next setting for documentary exhibits. | AN25: =IF(A25="","",LOWER(AI25)&"|"&AH25&"|"&AJ25&"|"&AK25) | AO25: =IF(OR(A25="",T25=""),"",T25-TODAY()) | AP25: =IF(OR(A25="",V25<>""),"",(TODAY()-B25)+ROW()/1000000)
A26: CC-2026-0024 | B26: 46076 | C26: People of the Philippines v. Rebecca Lim y Ong | D26: Nena Fernandez | E26: Rebecca Lim y Ong | F26: Illegal Recruitment | G26: =IF(A26="","",IFERROR(INDEX(OffCat,MATCH(F26,OffList,0)),"Unlisted")) | H26: Judgment Rendered | I26: 46266 | J26: Medium | K26: Closed | L26: Amicably Settled | M26: Regional Trial Court | N26: RTC-2025-0999 | O26: Atty. C. Bautista | P26: Barangay 10 | Q26: 46036 | R26: 46076 | S26: 46106 | V26: 46271 | W26: At Large | Y26: Y | Z26: Y | AA26: Y | AB26: Y | AC26: Y | AD26: Y | AE26: Y | AF26: Y | AG26: =IF(A26="","",IF(V26<>"",V26-B26,TODAY()-B26)) | AH26: =IF(OR(A26="",I26=""),"",MAX(0,IF(V26<>"",V26-I26,TODAY()-I26))) | AI26: =IF(A26="","",IF(OR(K26="Closed",V26<>""),"Closed",IF(AH26>=AgeCrit,"Critical",IF(AH26>=AgeFu,"For Follow-up",IF(AH26>=AgeMonitor,"Monitor","Within Standard"))))) | AJ26: =IF(A26="","",IFERROR(INDEX(StgPct,MATCH(H26,StgList,0)),0)) | AK26: =IF(A26="","",IFERROR(COUNTIF(Y26:AF26,"Y")/(COUNTIF(Y26:AF26,"Y")+COUNTIF(Y26:AF26,"N")),0)) | AL26: =IF(OR(A26="",X26=""),"",MAX(0,IF(V26<>"",V26,TODAY())-X26)) | AM26: Accused jumped bail; conviction in absentia recorded, records endorsed to court. | AN26: =IF(A26="","",LOWER(AI26)&"|"&AH26&"|"&AJ26&"|"&AK26) | AO26: =IF(OR(A26="",T26=""),"",T26-TODAY()) | AP26: =IF(OR(A26="",V26<>""),"",(TODAY()-B26)+ROW()/1000000)
A27: CC-2026-0025 | B27: 46241 | C27: People of the Philippines v. Rodrigo Basco y Naval | D27: CCC (name withheld) | E27: Rodrigo Basco y Naval | F27: Acts of Lasciviousness | G27: =IF(A27="","",IFERROR(INDEX(OffCat,MATCH(F27,OffList,0)),"Unlisted")) | H27: Arraignment | I27: 46288 | J27: High | K27: Active | L27: Pending | M27: Municipal Trial Court | N27: MTC-2026-0701 | O27: Atty. M. Fernandez | P27: Barangay 5 | Q27: 46206 | R27: 46241 | S27: 46276 | T27: 46327 | U27: 46288 | W27: In Custody - No Bail | X27: 46241 | Y27: Y | Z27: Y | AA27: N | AB27: Y | AC27: Y | AD27: N | AE27: Y | AF27: N | AG27: =IF(A27="","",IF(V27<>"",V27-B27,TODAY()-B27)) | AH27: =IF(OR(A27="",I27=""),"",MAX(0,IF(V27<>"",V27-I27,TODAY()-I27))) | AI27: =IF(A27="","",IF(OR(K27="Closed",V27<>""),"Closed",IF(AH27>=AgeCrit,"Critical",IF(AH27>=AgeFu,"For Follow-up",IF(AH27>=AgeMonitor,"Monitor","Within Standard"))))) | AJ27: =IF(A27="","",IFERROR(INDEX(StgPct,MATCH(H27,StgList,0)),0)) | AK27: =IF(A27="","",IFERROR(COUNTIF(Y27:AF27,"Y")/(COUNTIF(Y27:AF27,"Y")+COUNTIF(Y27:AF27,"N")),0)) | AL27: =IF(OR(A27="",X27=""),"",MAX(0,IF(V27<>"",V27,TODAY())-X27)) | AM27: Accused entered not guilty plea; pre-trial conference scheduled. | AN27: =IF(A27="","",LOWER(AI27)&"|"&AH27&"|"&AJ27&"|"&AK27) | AO27: =IF(OR(A27="",T27=""),"",T27-TODAY()) | AP27: =IF(OR(A27="",V27<>""),"",(TODAY()-B27)+ROW()/1000000)
A28: CC-2026-0026 | B28: 45666 | C28: People of the Philippines v. San Isidro Agro-Industrial Corp. (resp. reps.) | D28: DENR - EMB Region III | E28: San Isidro Agro-Industrial Corp. | F28: Violation of Clean Water Act | G28: =IF(A28="","",IFERROR(INDEX(OffCat,MATCH(F28,OffList,0)),"Unlisted")) | H28: Trial | I28: 45796 | J28: Low | K28: Dormant | L28: Pending | M28: Regional Trial Court | N28: RTC-2024-0512 | O28: Investigator L. Gomez | P28: Outside Jurisdiction | Q28: 45616 | R28: 45666 | S28: 45716 | U28: 45796 | W28: At Large | Y28: Y | Z28: Y | AA28: N | AB28: Y | AC28: N | AD28: N | AE28: N | AF28: N | AG28: =IF(A28="","",IF(V28<>"",V28-B28,TODAY()-B28)) | AH28: =IF(OR(A28="",I28=""),"",MAX(0,IF(V28<>"",V28-I28,TODAY()-I28))) | AI28: =IF(A28="","",IF(OR(K28="Closed",V28<>""),"Closed",IF(AH28>=AgeCrit,"Critical",IF(AH28>=AgeFu,"For Follow-up",IF(AH28>=AgeMonitor,"Monitor","Within Standard"))))) | AJ28: =IF(A28="","",IFERROR(INDEX(StgPct,MATCH(H28,StgList,0)),0)) | AK28: =IF(A28="","",IFERROR(COUNTIF(Y28:AF28,"Y")/(COUNTIF(Y28:AF28,"Y")+COUNTIF(Y28:AF28,"N")),0)) | AL28: =IF(OR(A28="",X28=""),"",MAX(0,IF(V28<>"",V28,TODAY())-X28)) | AM28: Dormant - accused cannot be located. Recommend archival review. | AN28: =IF(A28="","",LOWER(AI28)&"|"&AH28&"|"&AJ28&"|"&AK28) | AO28: =IF(OR(A28="",T28=""),"",T28-TODAY()) | AP28: =IF(OR(A28="",V28<>""),"",(TODAY()-B28)+ROW()/1000000)
G29: =IF(A29="","",IFERROR(INDEX(OffCat,MATCH(F29,OffList,0)),"Unlisted")) | AG29: =IF(A29="","",IF(V29<>"",V29-B29,TODAY()-B29)) | AH29: =IF(OR(A29="",I29=""),"",MAX(0,IF(V29<>"",V29-I29,TODAY()-I29))) | AI29: =IF(A29="","",IF(OR(K29="Closed",V29<>""),"Closed",IF(AH29>=AgeCrit,"Critical",IF(AH29>=AgeFu,"For Follow-up",IF(AH29>=AgeMonitor,"Monitor","Within Standard"))))) | AJ29: =IF(A29="","",IFERROR(INDEX(StgPct,MATCH(H29,StgList,0)),0)) | AK29: =IF(A29="","",IFERROR(COUNTIF(Y29:AF29,"Y")/(COUNTIF(Y29:AF29,"Y")+COUNTIF(Y29:AF29,"N")),0)) | AL29: =IF(OR(A29="",X29=""),"",MAX(0,IF(V29<>"",V29,TODAY())-X29)) | AN29: =IF(A29="","",LOWER(AI29)&"|"&AH29&"|"&AJ29&"|"&AK29) | AO29: =IF(OR(A29="",T29=""),"",T29-TODAY()) | AP29: =IF(OR(A29="",V29<>""),"",(TODAY()-B29)+ROW()/1000000)
G30: =IF(A30="","",IFERROR(INDEX(OffCat,MATCH(F30,OffList,0)),"Unlisted")) | AG30: =IF(A30="","",IF(V30<>"",V30-B30,TODAY()-B30)) | AH30: =IF(OR(A30="",I30=""),"",MAX(0,IF(V30<>"",V30-I30,TODAY()-I30))) | AI30: =IF(A30="","",IF(OR(K30="Closed",V30<>""),"Closed",IF(AH30>=AgeCrit,"Critical",IF(AH30>=AgeFu,"For Follow-up",IF(AH30>=AgeMonitor,"Monitor","Within Standard"))))) | AJ30: =IF(A30="","",IFERROR(INDEX(StgPct,MATCH(H30,StgList,0)),0)) | AK30: =IF(A30="","",IFERROR(COUNTIF(Y30:AF30,"Y")/(COUNTIF(Y30:AF30,"Y")+COUNTIF(Y30:AF30,"N")),0)) | AL30: =IF(OR(A30="",X30=""),"",MAX(0,IF(V30<>"",V30,TODAY())-X30)) | AN30: =IF(A30="","",LOWER(AI30)&"|"&AH30&"|"&AJ30&"|"&AK30) | AO30: =IF(OR(A30="",T30=""),"",T30-TODAY()) | AP30: =IF(OR(A30="",V30<>""),"",(TODAY()-B30)+ROW()/1000000)
G31: =IF(A31="","",IFERROR(INDEX(OffCat,MATCH(F31,OffList,0)),"Unlisted")) | AG31: =IF(A31="","",IF(V31<>"",V31-B31,TODAY()-B31)) | AH31: =IF(OR(A31="",I31=""),"",MAX(0,IF(V31<>"",V31-I31,TODAY()-I31))) | AI31: =IF(A31="","",IF(OR(K31="Closed",V31<>""),"Closed",IF(AH31>=AgeCrit,"Critical",IF(AH31>=AgeFu,"For Follow-up",IF(AH31>=AgeMonitor,"Monitor","Within Standard"))))) | AJ31: =IF(A31="","",IFERROR(INDEX(StgPct,MATCH(H31,StgList,0)),0)) | AK31: =IF(A31="","",IFERROR(COUNTIF(Y31:AF31,"Y")/(COUNTIF(Y31:AF31,"Y")+COUNTIF(Y31:AF31,"N")),0)) | AL31: =IF(OR(A31="",X31=""),"",MAX(0,IF(V31<>"",V31,TODAY())-X31)) | AN31: =IF(A31="","",LOWER(AI31)&"|"&AH31&"|"&AJ31&"|"&AK31) | AO31: =IF(OR(A31="",T31=""),"",T31-TODAY()) | AP31: =IF(OR(A31="",V31<>""),"",(TODAY()-B31)+ROW()/1000000)
G32: =IF(A32="","",IFERROR(INDEX(OffCat,MATCH(F32,OffList,0)),"Unlisted")) | AG32: =IF(A32="","",IF(V32<>"",V32-B32,TODAY()-B32)) | AH32: =IF(OR(A32="",I32=""),"",MAX(0,IF(V32<>"",V32-I32,TODAY()-I32))) | AI32: =IF(A32="","",IF(OR(K32="Closed",V32<>""),"Closed",IF(AH32>=AgeCrit,"Critical",IF(AH32>=AgeFu,"For Follow-up",IF(AH32>=AgeMonitor,"Monitor","Within Standard"))))) | AJ32: =IF(A32="","",IFERROR(INDEX(StgPct,MATCH(H32,StgList,0)),0)) | AK32: =IF(A32="","",IFERROR(COUNTIF(Y32:AF32,"Y")/(COUNTIF(Y32:AF32,"Y")+COUNTIF(Y32:AF32,"N")),0)) | AL32: =IF(OR(A32="",X32=""),"",MAX(0,IF(V32<>"",V32,TODAY())-X32)) | AN32: =IF(A32="","",LOWER(AI32)&"|"&AH32&"|"&AJ32&"|"&AK32) | AO32: =IF(OR(A32="",T32=""),"",T32-TODAY()) | AP32: =IF(OR(A32="",V32<>""),"",(TODAY()-B32)+ROW()/1000000)
G33: =IF(A33="","",IFERROR(INDEX(OffCat,MATCH(F33,OffList,0)),"Unlisted")) | AG33: =IF(A33="","",IF(V33<>"",V33-B33,TODAY()-B33)) | AH33: =IF(OR(A33="",I33=""),"",MAX(0,IF(V33<>"",V33-I33,TODAY()-I33))) | AI33: =IF(A33="","",IF(OR(K33="Closed",V33<>""),"Closed",IF(AH33>=AgeCrit,"Critical",IF(AH33>=AgeFu,"For Follow-up",IF(AH33>=AgeMonitor,"Monitor","Within Standard"))))) | AJ33: =IF(A33="","",IFERROR(INDEX(StgPct,MATCH(H33,StgList,0)),0)) | AK33: =IF(A33="","",IFERROR(COUNTIF(Y33:AF33,"Y")/(COUNTIF(Y33:AF33,"Y")+COUNTIF(Y33:AF33,"N")),0)) | AL33: =IF(OR(A33="",X33=""),"",MAX(0,IF(V33<>"",V33,TODAY())-X33)) | AN33: =IF(A33="","",LOWER(AI33)&"|"&AH33&"|"&AJ33&"|"&AK33) | AO33: =IF(OR(A33="",T33=""),"",T33-TODAY()) | AP33: =IF(OR(A33="",V33<>""),"",(TODAY()-B33)+ROW()/1000000)
G34: =IF(A34="","",IFERROR(INDEX(OffCat,MATCH(F34,OffList,0)),"Unlisted")) | AG34: =IF(A34="","",IF(V34<>"",V34-B34,TODAY()-B34)) | AH34: =IF(OR(A34="",I34=""),"",MAX(0,IF(V34<>"",V34-I34,TODAY()-I34))) | AI34: =IF(A34="","",IF(OR(K34="Closed",V34<>""),"Closed",IF(AH34>=AgeCrit,"Critical",IF(AH34>=AgeFu,"For Follow-up",IF(AH34>=AgeMonitor,"Monitor","Within Standard"))))) | AJ34: =IF(A34="","",IFERROR(INDEX(StgPct,MATCH(H34,StgList,0)),0)) | AK34: =IF(A34="","",IFERROR(COUNTIF(Y34:AF34,"Y")/(COUNTIF(Y34:AF34,"Y")+COUNTIF(Y34:AF34,"N")),0)) | AL34: =IF(OR(A34="",X34=""),"",MAX(0,IF(V34<>"",V34,TODAY())-X34)) | AN34: =IF(A34="","",LOWER(AI34)&"|"&AH34&"|"&AJ34&"|"&AK34) | AO34: =IF(OR(A34="",T34=""),"",T34-TODAY()) | AP34: =IF(OR(A34="",V34<>""),"",(TODAY()-B34)+ROW()/1000000)
G35: =IF(A35="","",IFERROR(INDEX(OffCat,MATCH(F35,OffList,0)),"Unlisted")) | AG35: =IF(A35="","",IF(V35<>"",V35-B35,TODAY()-B35)) | AH35: =IF(OR(A35="",I35=""),"",MAX(0,IF(V35<>"",V35-I35,TODAY()-I35))) | AI35: =IF(A35="","",IF(OR(K35="Closed",V35<>""),"Closed",IF(AH35>=AgeCrit,"Critical",IF(AH35>=AgeFu,"For Follow-up",IF(AH35>=AgeMonitor,"Monitor","Within Standard"))))) | AJ35: =IF(A35="","",IFERROR(INDEX(StgPct,MATCH(H35,StgList,0)),0)) | AK35: =IF(A35="","",IFERROR(COUNTIF(Y35:AF35,"Y")/(COUNTIF(Y35:AF35,"Y")+COUNTIF(Y35:AF35,"N")),0)) | AL35: =IF(OR(A35="",X35=""),"",MAX(0,IF(V35<>"",V35,TODAY())-X35)) | AN35: =IF(A35="","",LOWER(AI35)&"|"&AH35&"|"&AJ35&"|"&AK35) | AO35: =IF(OR(A35="",T35=""),"",T35-TODAY()) | AP35: =IF(OR(A35="",V35<>""),"",(TODAY()-B35)+ROW()/1000000)
G36: =IF(A36="","",IFERROR(INDEX(OffCat,MATCH(F36,OffList,0)),"Unlisted")) | AG36: =IF(A36="","",IF(V36<>"",V36-B36,TODAY()-B36)) | AH36: =IF(OR(A36="",I36=""),"",MAX(0,IF(V36<>"",V36-I36,TODAY()-I36))) | AI36: =IF(A36="","",IF(OR(K36="Closed",V36<>""),"Closed",IF(AH36>=AgeCrit,"Critical",IF(AH36>=AgeFu,"For Follow-up",IF(AH36>=AgeMonitor,"Monitor","Within Standard"))))) | AJ36: =IF(A36="","",IFERROR(INDEX(StgPct,MATCH(H36,StgList,0)),0)) | AK36: =IF(A36="","",IFERROR(COUNTIF(Y36:AF36,"Y")/(COUNTIF(Y36:AF36,"Y")+COUNTIF(Y36:AF36,"N")),0)) | AL36: =IF(OR(A36="",X36=""),"",MAX(0,IF(V36<>"",V36,TODAY())-X36)) | AN36: =IF(A36="","",LOWER(AI36)&"|"&AH36&"|"&AJ36&"|"&AK36) | AO36: =IF(OR(A36="",T36=""),"",T36-TODAY()) | AP36: =IF(OR(A36="",V36<>""),"",(TODAY()-B36)+ROW()/1000000)
G37: =IF(A37="","",IFERROR(INDEX(OffCat,MATCH(F37,OffList,0)),"Unlisted")) | AG37: =IF(A37="","",IF(V37<>"",V37-B37,TODAY()-B37)) | AH37: =IF(OR(A37="",I37=""),"",MAX(0,IF(V37<>"",V37-I37,TODAY()-I37))) | AI37: =IF(A37="","",IF(OR(K37="Closed",V37<>""),"Closed",IF(AH37>=AgeCrit,"Critical",IF(AH37>=AgeFu,"For Follow-up",IF(AH37>=AgeMonitor,"Monitor","Within Standard"))))) | AJ37: =IF(A37="","",IFERROR(INDEX(StgPct,MATCH(H37,StgList,0)),0)) | AK37: =IF(A37="","",IFERROR(COUNTIF(Y37:AF37,"Y")/(COUNTIF(Y37:AF37,"Y")+COUNTIF(Y37:AF37,"N")),0)) | AL37: =IF(OR(A37="",X37=""),"",MAX(0,IF(V37<>"",V37,TODAY())-X37)) | AN37: =IF(A37="","",LOWER(AI37)&"|"&AH37&"|"&AJ37&"|"&AK37) | AO37: =IF(OR(A37="",T37=""),"",T37-TODAY()) | AP37: =IF(OR(A37="",V37<>""),"",(TODAY()-B37)+ROW()/1000000)
G38: =IF(A38="","",IFERROR(INDEX(OffCat,MATCH(F38,OffList,0)),"Unlisted")) | AG38: =IF(A38="","",IF(V38<>"",V38-B38,TODAY()-B38)) | AH38: =IF(OR(A38="",I38=""),"",MAX(0,IF(V38<>"",V38-I38,TODAY()-I38))) | AI38: =IF(A38="","",IF(OR(K38="Closed",V38<>""),"Closed",IF(AH38>=AgeCrit,"Critical",IF(AH38>=AgeFu,"For Follow-up",IF(AH38>=AgeMonitor,"Monitor","Within Standard"))))) | AJ38: =IF(A38="","",IFERROR(INDEX(StgPct,MATCH(H38,StgList,0)),0)) | AK38: =IF(A38="","",IFERROR(COUNTIF(Y38:AF38,"Y")/(COUNTIF(Y38:AF38,"Y")+COUNTIF(Y38:AF38,"N")),0)) | AL38: =IF(OR(A38="",X38=""),"",MAX(0,IF(V38<>"",V38,TODAY())-X38)) | AN38: =IF(A38="","",LOWER(AI38)&"|"&AH38&"|"&AJ38&"|"&AK38) | AO38: =IF(OR(A38="",T38=""),"",T38-TODAY()) | AP38: =IF(OR(A38="",V38<>""),"",(TODAY()-B38)+ROW()/1000000)
G39: =IF(A39="","",IFERROR(INDEX(OffCat,MATCH(F39,OffList,0)),"Unlisted")) | AG39: =IF(A39="","",IF(V39<>"",V39-B39,TODAY()-B39)) | AH39: =IF(OR(A39="",I39=""),"",MAX(0,IF(V39<>"",V39-I39,TODAY()-I39))) | AI39: =IF(A39="","",IF(OR(K39="Closed",V39<>""),"Closed",IF(AH39>=AgeCrit,"Critical",IF(AH39>=AgeFu,"For Follow-up",IF(AH39>=AgeMonitor,"Monitor","Within Standard"))))) | AJ39: =IF(A39="","",IFERROR(INDEX(StgPct,MATCH(H39,StgList,0)),0)) | AK39: =IF(A39="","",IFERROR(COUNTIF(Y39:AF39,"Y")/(COUNTIF(Y39:AF39,"Y")+COUNTIF(Y39:AF39,"N")),0)) | AL39: =IF(OR(A39="",X39=""),"",MAX(0,IF(V39<>"",V39,TODAY())-X39)) | AN39: =IF(A39="","",LOWER(AI39)&"|"&AH39&"|"&AJ39&"|"&AK39) | AO39: =IF(OR(A39="",T39=""),"",T39-TODAY()) | AP39: =IF(OR(A39="",V39<>""),"",(TODAY()-B39)+ROW()/1000000)
G40: =IF(A40="","",IFERROR(INDEX(OffCat,MATCH(F40,OffList,0)),"Unlisted")) | AG40: =IF(A40="","",IF(V40<>"",V40-B40,TODAY()-B40)) | AH40: =IF(OR(A40="",I40=""),"",MAX(0,IF(V40<>"",V40-I40,TODAY()-I40))) | AI40: =IF(A40="","",IF(OR(K40="Closed",V40<>""),"Closed",IF(AH40>=AgeCrit,"Critical",IF(AH40>=AgeFu,"For Follow-up",IF(AH40>=AgeMonitor,"Monitor","Within Standard"))))) | AJ40: =IF(A40="","",IFERROR(INDEX(StgPct,MATCH(H40,StgList,0)),0)) | AK40: =IF(A40="","",IFERROR(COUNTIF(Y40:AF40,"Y")/(COUNTIF(Y40:AF40,"Y")+COUNTIF(Y40:AF40,"N")),0)) | AL40: =IF(OR(A40="",X40=""),"",MAX(0,IF(V40<>"",V40,TODAY())-X40)) | AN40: =IF(A40="","",LOWER(AI40)&"|"&AH40&"|"&AJ40&"|"&AK40) | AO40: =IF(OR(A40="",T40=""),"",T40-TODAY()) | AP40: =IF(OR(A40="",V40<>""),"",(TODAY()-B40)+ROW()/1000000)
...

Sheet Hearing Calendar
A1: HEARING CALENDAR | encode every setting, then update the result after each hearing
A2: CASE NO. | B2: CASE TITLE | C2: HEARING DATE | D2: TIME | E2: HEARING TYPE | F2: COURT / FORUM | G2: HANDLER | H2: RESULT | I2: NEXT SETTING | J2: DAYS FROM TODAY | K2: STATUS | L2: ORDERS / NOTES
A3: CC-2026-0001 | B3: =IFERROR(IF($A3="","",INDEX(RegTitle,MATCH($A3,RegCaseNo,0))),"Case no. not found") | C3: 46290 | D3: 09:00 AM | E3: Trial | F3: =IFERROR(IF($A3="","",INDEX(RegCourt,MATCH($A3,RegCaseNo,0))),"") | G3: =IFERROR(IF($A3="","",INDEX(RegPersonnel,MATCH($A3,RegCaseNo,0))),"") | H3: Held as Scheduled | I3: 46320 | J3: =IF(C3="","",C3-TODAY()) | K3: =IF(A3="","",IF(AND(H3="",C3<TODAY()),"Overdue",IF(H3="","Upcoming",IF(H3="Held as Scheduled","Held",IF(H3="Cancelled","Cancelled",IF(H3="Submitted for Resolution","Cleared","Postponed")))))) | L3: Prosecution witness No. 3 testified; exhibits A to D admitted.
A4: CC-2026-0001 | B4: =IFERROR(IF($A4="","",INDEX(RegTitle,MATCH($A4,RegCaseNo,0))),"Case no. not found") | C4: 46320 | D4: 09:00 AM | E4: Trial | F4: =IFERROR(IF($A4="","",INDEX(RegCourt,MATCH($A4,RegCaseNo,0))),"") | G4: =IFERROR(IF($A4="","",INDEX(RegPersonnel,MATCH($A4,RegCaseNo,0))),"") | J4: =IF(C4="","",C4-TODAY()) | K4: =IF(A4="","",IF(AND(H4="",C4<TODAY()),"Overdue",IF(H4="","Upcoming",IF(H4="Held as Scheduled","Held",IF(H4="Cancelled","Cancelled",IF(H4="Submitted for Resolution","Cleared","Postponed")))))) | L4: Continue trial. Subpoena remaining witnesses.
A5: CC-2026-0002 | B5: =IFERROR(IF($A5="","",INDEX(RegTitle,MATCH($A5,RegCaseNo,0))),"Case no. not found") | C5: 46298 | D5: 10:30 AM | E5: Pre-Trial | F5: =IFERROR(IF($A5="","",INDEX(RegCourt,MATCH($A5,RegCaseNo,0))),"") | G5: =IFERROR(IF($A5="","",INDEX(RegPersonnel,MATCH($A5,RegCaseNo,0))),"") | H5: Held as Scheduled | I5: 46328 | J5: =IF(C5="","",C5-TODAY()) | K5: =IF(A5="","",IF(AND(H5="",C5<TODAY()),"Overdue",IF(H5="","Upcoming",IF(H5="Held as Scheduled","Held",IF(H5="Cancelled","Cancelled",IF(H5="Submitted for Resolution","Cleared","Postponed")))))) | L5: Stipulation on chain of custody; pre-trial order due.
A6: CC-2026-0003 | B6: =IFERROR(IF($A6="","",INDEX(RegTitle,MATCH($A6,RegCaseNo,0))),"Case no. not found") | C6: 46279 | D6: 02:00 PM | E6: Arraignment | F6: =IFERROR(IF($A6="","",INDEX(RegCourt,MATCH($A6,RegCaseNo,0))),"") | G6: =IFERROR(IF($A6="","",INDEX(RegPersonnel,MATCH($A6,RegCaseNo,0))),"") | H6: Reset | I6: 46310 | J6: =IF(C6="","",C6-TODAY()) | K6: =IF(A6="","",IF(AND(H6="",C6<TODAY()),"Overdue",IF(H6="","Upcoming",IF(H6="Held as Scheduled","Held",IF(H6="Cancelled","Cancelled",IF(H6="Submitted for Resolution","Cleared","Postponed")))))) | L6: Counsel moved for reset; court granted with warning.
A7: CC-2026-0003 | B7: =IFERROR(IF($A7="","",INDEX(RegTitle,MATCH($A7,RegCaseNo,0))),"Case no. not found") | C7: 46310 | D7: 02:00 PM | E7: Arraignment | F7: =IFERROR(IF($A7="","",INDEX(RegCourt,MATCH($A7,RegCaseNo,0))),"") | G7: =IFERROR(IF($A7="","",INDEX(RegPersonnel,MATCH($A7,RegCaseNo,0))),"") | J7: =IF(C7="","",C7-TODAY()) | K7: =IF(A7="","",IF(AND(H7="",C7<TODAY()),"Overdue",IF(H7="","Upcoming",IF(H7="Held as Scheduled","Held",IF(H7="Cancelled","Cancelled",IF(H7="Submitted for Resolution","Cleared","Postponed")))))) | L7: Overdue setting. Confirm new calendar with branch clerk.
A8: CC-2026-0004 | B8: =IFERROR(IF($A8="","",INDEX(RegTitle,MATCH($A8,RegCaseNo,0))),"Case no. not found") | C8: 46306 | D8: 08:30 AM | E8: Arraignment | F8: =IFERROR(IF($A8="","",INDEX(RegCourt,MATCH($A8,RegCaseNo,0))),"") | G8: =IFERROR(IF($A8="","",INDEX(RegPersonnel,MATCH($A8,RegCaseNo,0))),"") | H8: Held as Scheduled | I8: 46336 | J8: =IF(C8="","",C8-TODAY()) | K8: =IF(A8="","",IF(AND(H8="",C8<TODAY()),"Overdue",IF(H8="","Upcoming",IF(H8="Held as Scheduled","Held",IF(H8="Cancelled","Cancelled",IF(H8="Submitted for Resolution","Cleared","Postponed")))))) | L8: Not guilty plea entered; pre-trial set.
A9: CC-2026-0005 | B9: =IFERROR(IF($A9="","",INDEX(RegTitle,MATCH($A9,RegCaseNo,0))),"Case no. not found") | C9: 46314 | D9: 09:30 AM | E9: Trial | F9: =IFERROR(IF($A9="","",INDEX(RegCourt,MATCH($A9,RegCaseNo,0))),"") | G9: =IFERROR(IF($A9="","",INDEX(RegPersonnel,MATCH($A9,RegCaseNo,0))),"") | H9: Postponed - Defense | I9: 46318 | J9: =IF(C9="","",C9-TODAY()) | K9: =IF(A9="","",IF(AND(H9="",C9<TODAY()),"Overdue",IF(H9="","Upcoming",IF(H9="Held as Scheduled","Held",IF(H9="Cancelled","Cancelled",IF(H9="Submitted for Resolution","Cleared","Postponed")))))) | L9: Defense counsel unavailable; motion for continuance granted.
A10: CC-2026-0007 | B10: =IFERROR(IF($A10="","",INDEX(RegTitle,MATCH($A10,RegCaseNo,0))),"Case no. not found") | C10: 46276 | D10: 10:00 AM | E10: Promulgation | F10: =IFERROR(IF($A10="","",INDEX(RegCourt,MATCH($A10,RegCaseNo,0))),"") | G10: =IFERROR(IF($A10="","",INDEX(RegPersonnel,MATCH($A10,RegCaseNo,0))),"") | H10: Held as Scheduled | J10: =IF(C10="","",C10-TODAY()) | K10: =IF(A10="","",IF(AND(H10="",C10<TODAY()),"Overdue",IF(H10="","Upcoming",IF(H10="Held as Scheduled","Held",IF(H10="Cancelled","Cancelled",IF(H10="Submitted for Resolution","Cleared","Postponed")))))) | L10: Judgment of conviction promulgated; records updated.
A11: CC-2025-0012 | B11: =IFERROR(IF($A11="","",INDEX(RegTitle,MATCH($A11,RegCaseNo,0))),"Case no. not found") | C11: 46301 | D11: 01:30 PM | E11: Arraignment | F11: =IFERROR(IF($A11="","",INDEX(RegCourt,MATCH($A11,RegCaseNo,0))),"") | G11: =IFERROR(IF($A11="","",INDEX(RegPersonnel,MATCH($A11,RegCaseNo,0))),"") | H11: Held as Scheduled | I11: 46323 | J11: =IF(C11="","",C11-TODAY()) | K11: =IF(A11="","",IF(AND(H11="",C11<TODAY()),"Overdue",IF(H11="","Upcoming",IF(H11="Held as Scheduled","Held",IF(H11="Cancelled","Cancelled",IF(H11="Submitted for Resolution","Cleared","Postponed")))))) | L11: Accused arraigned with counsel; bail bond approved.
A12: CC-2025-0019 | B12: =IFERROR(IF($A12="","",INDEX(RegTitle,MATCH($A12,RegCaseNo,0))),"Case no. not found") | C12: 46286 | D12: 09:00 AM | E12: Motion Hearing | F12: =IFERROR(IF($A12="","",INDEX(RegCourt,MATCH($A12,RegCaseNo,0))),"") | G12: =IFERROR(IF($A12="","",INDEX(RegPersonnel,MATCH($A12,RegCaseNo,0))),"") | H12: Submitted for Resolution | J12: =IF(C12="","",C12-TODAY()) | K12: =IF(A12="","",IF(AND(H12="",C12<TODAY()),"Overdue",IF(H12="","Upcoming",IF(H12="Held as Scheduled","Held",IF(H12="Cancelled","Cancelled",IF(H12="Submitted for Resolution","Cleared","Postponed")))))) | L12: Appeal briefs submitted; awaiting CA resolution.
A13: CC-2026-0022 | B13: =IFERROR(IF($A13="","",INDEX(RegTitle,MATCH($A13,RegCaseNo,0))),"Case no. not found") | C13: 46321 | D13: 03:00 PM | E13: Motion Hearing | F13: =IFERROR(IF($A13="","",INDEX(RegCourt,MATCH($A13,RegCaseNo,0))),"") | G13: =IFERROR(IF($A13="","",INDEX(RegPersonnel,MATCH($A13,RegCaseNo,0))),"") | J13: =IF(C13="","",C13-TODAY()) | K13: =IF(A13="","",IF(AND(H13="",C13<TODAY()),"Overdue",IF(H13="","Upcoming",IF(H13="Held as Scheduled","Held",IF(H13="Cancelled","Cancelled",IF(H13="Submitted for Resolution","Cleared","Postponed")))))) | L13: Status conference on possible compromise agreement.
A14: CC-2026-0025 | B14: =IFERROR(IF($A14="","",INDEX(RegTitle,MATCH($A14,RegCaseNo,0))),"Case no. not found") | C14: 46288 | D14: 08:30 AM | E14: Arraignment | F14: =IFERROR(IF($A14="","",INDEX(RegCourt,MATCH($A14,RegCaseNo,0))),"") | G14: =IFERROR(IF($A14="","",INDEX(RegPersonnel,MATCH($A14,RegCaseNo,0))),"") | H14: Held as Scheduled | I14: 46327 | J14: =IF(C14="","",C14-TODAY()) | K14: =IF(A14="","",IF(AND(H14="",C14<TODAY()),"Overdue",IF(H14="","Upcoming",IF(H14="Held as Scheduled","Held",IF(H14="Cancelled","Cancelled",IF(H14="Submitted for Resolution","Cleared","Postponed")))))) | L14: Plea of not guilty; pre-trial conference scheduled.
B15: =IFERROR(IF($A15="","",INDEX(RegTitle,MATCH($A15,RegCaseNo,0))),"Case no. not found") | F15: =IFERROR(IF($A15="","",INDEX(RegCourt,MATCH($A15,RegCaseNo,0))),"") | G15: =IFERROR(IF($A15="","",INDEX(RegPersonnel,MATCH($A15,RegCaseNo,0))),"") | J15: =IF(C15="","",C15-TODAY()) | K15: =IF(A15="","",IF(AND(H15="",C15<TODAY()),"Overdue",IF(H15="","Upcoming",IF(H15="Held as Scheduled","Held",IF(H15="Cancelled","Cancelled",IF(H15="Submitted for Resolution","Cleared","Postponed"))))))
B16: =IFERROR(IF($A16="","",INDEX(RegTitle,MATCH($A16,RegCaseNo,0))),"Case no. not found") | F16: =IFERROR(IF($A16="","",INDEX(RegCourt,MATCH($A16,RegCaseNo,0))),"") | G16: =IFERROR(IF($A16="","",INDEX(RegPersonnel,MATCH($A16,RegCaseNo,0))),"") | J16: =IF(C16="","",C16-TODAY()) | K16: =IF(A16="","",IF(AND(H16="",C16<TODAY()),"Overdue",IF(H16="","Upcoming",IF(H16="Held as Scheduled","Held",IF(H16="Cancelled","Cancelled",IF(H16="Submitted for Resolution","Cleared","Postponed"))))))
B17: =IFERROR(IF($A17="","",INDEX(RegTitle,MATCH($A17,RegCaseNo,0))),"Case no. not found") | F17: =IFERROR(IF($A17="","",INDEX(RegCourt,MATCH($A17,RegCaseNo,0))),"") | G17: =IFERROR(IF($A17="","",INDEX(RegPersonnel,MATCH($A17,RegCaseNo,0))),"") | J17: =IF(C17="","",C17-TODAY()) | K17: =IF(A17="","",IF(AND(H17="",C17<TODAY()),"Overdue",IF(H17="","Upcoming",IF(H17="Held as Scheduled","Held",IF(H17="Cancelled","Cancelled",IF(H17="Submitted for Resolution","Cleared","Postponed"))))))
B18: =IFERROR(IF($A18="","",INDEX(RegTitle,MATCH($A18,RegCaseNo,0))),"Case no. not found") | F18: =IFERROR(IF($A18="","",INDEX(RegCourt,MATCH($A18,RegCaseNo,0))),"") | G18: =IFERROR(IF($A18="","",INDEX(RegPersonnel,MATCH($A18,RegCaseNo,0))),"") | J18: =IF(C18="","",C18-TODAY()) | K18: =IF(A18="","",IF(AND(H18="",C18<TODAY()),"Overdue",IF(H18="","Upcoming",IF(H18="Held as Scheduled","Held",IF(H18="Cancelled","Cancelled",IF(H18="Submitted for Resolution","Cleared","Postponed"))))))
B19: =IFERROR(IF($A19="","",INDEX(RegTitle,MATCH($A19,RegCaseNo,0))),"Case no. not found") | F19: =IFERROR(IF($A19="","",INDEX(RegCourt,MATCH($A19,RegCaseNo,0))),"") | G19: =IFERROR(IF($A19="","",INDEX(RegPersonnel,MATCH($A19,RegCaseNo,0))),"") | J19: =IF(C19="","",C19-TODAY()) | K19: =IF(A19="","",IF(AND(H19="",C19<TODAY()),"Overdue",IF(H19="","Upcoming",IF(H19="Held as Scheduled","Held",IF(H19="Cancelled","Cancelled",IF(H19="Submitted for Resolution","Cleared","Postponed"))))))
