Workbook
Name VER_DATE: Verint_Raw!$A$6:$A$10005
Name VER_TIME: Verint_Raw!$B$6:$B$10005
Name VER_END: Verint_Raw!$C$6:$C$10005
Name VER_INT: Verint_Raw!$D$6:$D$10005
Name VER_SITE: Verint_Raw!$E$6:$E$10005
Name VER_QUEUE: Verint_Raw!$F$6:$F$10005
Name VER_CHAN: Verint_Raw!$G$6:$G$10005
Name VER_OFFERED: Verint_Raw!$H$6:$H$10005
Name VER_HANDLED: Verint_Raw!$I$6:$I$10005
Name VER_ABAND: Verint_Raw!$J$6:$J$10005
Name VER_SHORT: Verint_Raw!$K$6:$K$10005
Name VER_ASA: Verint_Raw!$L$6:$L$10005
Name VER_AHT: Verint_Raw!$M$6:$M$10005
Name VER_TALK: Verint_Raw!$N$6:$N$10005
Name VER_HOLD: Verint_Raw!$O$6:$O$10005
Name VER_ACW: Verint_Raw!$P$6:$P$10005
Name VER_STAFFED: Verint_Raw!$Q$6:$Q$10005
Name VER_REQ: Verint_Raw!$R$6:$R$10005
Name VER_SL: Verint_Raw!$S$6:$S$10005
Name VER_WAIT: Verint_Raw!$T$6:$T$10005
Name VER_SRC: Verint_Raw!$U$6:$U$10005
Name VER_NOTES: Verint_Raw!$V$6:$V$10005
Name IEX_DATE: IEX_Raw!$A$6:$A$10005
Name IEX_TIME: IEX_Raw!$B$6:$B$10005
Name IEX_END: IEX_Raw!$C$6:$C$10005
Name IEX_INT: IEX_Raw!$D$6:$D$10005
Name IEX_SITE: IEX_Raw!$E$6:$E$10005
Name IEX_QUEUE: IEX_Raw!$F$6:$F$10005
Name IEX_CHAN: IEX_Raw!$G$6:$G$10005
Name IEX_OFFERED: IEX_Raw!$H$6:$H$10005
Name IEX_HANDLED: IEX_Raw!$I$6:$I$10005
Name IEX_ABAND: IEX_Raw!$J$6:$J$10005
Name IEX_SHORT: IEX_Raw!$K$6:$K$10005
Name IEX_ASA: IEX_Raw!$L$6:$L$10005
Name IEX_AHT: IEX_Raw!$M$6:$M$10005
Name IEX_TALK: IEX_Raw!$N$6:$N$10005
Name IEX_HOLD: IEX_Raw!$O$6:$O$10005
Name IEX_ACW: IEX_Raw!$P$6:$P$10005
Name IEX_STAFFED: IEX_Raw!$Q$6:$Q$10005
Name IEX_REQ: IEX_Raw!$R$6:$R$10005
Name IEX_SL: IEX_Raw!$S$6:$S$10005
Name IEX_WAIT: IEX_Raw!$T$6:$T$10005
Name IEX_SRC: IEX_Raw!$U$6:$U$10005
Name IEX_NOTES: IEX_Raw!$V$6:$V$10005
Name LIST_SITES: Lists!$A$5:$A$8
Name LIST_QUEUES: Lists!$B$5:$B$14
Name LIST_CHANNELS: Lists!$C$5:$C$9
Name LIST_SITES_FILTER: Lists!$G$5:$G$9
Name LIST_QUEUES_FILTER: Lists!$H$5:$H$15
Name LIST_CHANNELS_FILTER: Lists!$I$5:$I$10

Sheet README
A1: VERINT + IEX RAW DATA TEMPLATE
A2: One schema, two sources, one reconciled view of interval performance.
A4: WHAT THIS WORKBOOK DOES
B5: Captures raw Verint Workforce Management and IEX TotalView interval exports, keeps them untouched, then calculates the same KPIs for both sources and reconciles them day by day.
B6: Use it to answer three questions every WFM cycle: what happened (volume, handle time, service level), does the data agree across systems, and where is staffing short of requirement.
A8: SHEET MAP
B9: README | C9: This guide | F9: Read first.
B10: Setup | C10: Period, filters, tolerance | F10: Only place you change inputs.
B11: Verint_Raw | C11: Paste the Verint export | F11: Data only - no formulas.
B12: IEX_Raw | C12: Paste the IEX export | F12: Data only - no formulas.
B13: Calc_Data | C13: Calculation engine | F13: Totals, daily trend, interval profile, queue mix.
B14: Dashboard | C14: KPIs and charts | F14: Reads Calc_Data using the Setup source.
B15: Reconciliation | C15: Verint vs IEX by day | F15: Variance flags against the tolerance.
B16: DQ_Checks | C16: Data quality rules | F16: Fix FAIL rows before reporting.
B17: Lists | C17: Sites, queues, channels | F17: Feeds every dropdown and the queue mix.
A19: WORKFLOW
B20: 1. Set the month | C20: Setup!B5 = first day of the reporting month. Period End calculates itself.
B21: 2. Paste Verint | C21: Verint_Raw rows 6+ - align to the header row, paste as values.
B22: 3. Paste IEX | C22: IEX_Raw rows 6+ - same schema, same order.
B23: 4. Clear the sample | C23: Delete rows 6:101 on both raw sheets when you go live.
B24: 5. Run DQ_Checks | C24: Every FAIL row is a real data problem - fix it at source.
B25: 6. Read the Dashboard | C25: Pick VERINT, IEX or COMBINED in Setup!B13.
B26: 7. Reconcile | C26: Reconciliation compares both pulls per day; investigate REVIEW rows.
A28: COLUMN DICTIONARY (identical schema on both raw sheets)
B29: Column | C29: Verint export name | D29: IEX TotalView name | E29: Type / format | F29: Notes
B30: Date | C30: Date / Interval Date | D30: Date / Start Date | E30: Date (yyyy-mm-dd) | F30: Interval start date, not the file date.
B31: Interval Start | C31: Interval Start / Start Time | D31: Interval / Start Time | E31: Time (hh:mm) | F31: Time only - never a date-time value.
B32: Interval End | C32: Interval End / End Time | D32: End Time | E32: Time (hh:mm) | F32: Optional but recommended.
B33: Interval | C33: Interval / Interval Name | D33: Interval Label | E33: Text | F33: Optional display label.
B34: Site | C34: Site / Location | D34: Location / Site | E34: Text | F34: Must match Lists column A.
B35: Queue / Skill | C35: Queue / Queue Name | D35: Skill / Skill Name | E35: Text | F35: Must match Lists column B.
B36: Channel | C36: Channel / Media Type | D36: Channel / Media | E36: Text | F36: Voice, Chat, Email, Social, Backoffice.
B37: Offered | C37: Offered / Contacts Offered | D37: Offered / Total Offered | E37: Integer | F37: Contacts that arrived in the interval.
B38: Handled | C38: Handled / Answered | D38: Handled / Answered | E38: Integer | F38: Contacts answered by an agent.
B39: Abandoned | C39: Abandoned / Abandons | D39: Abandoned | E39: Integer | F39: Offered minus handled is the sanity check.
B40: Short Abandoned | C40: Short Abandoned / Abn < 5s | D40: Short Abandoned | E40: Integer | F40: Optional short-abandon split.
... B51: Notes | C51: Notes | D51: Notes | E51: Text | F51: Anything the next analyst should know.
A53: RULES, LIMITS AND DEFINITIONS
B54: Capacity | C54: 10,000 rows per raw sheet (rows 6-10,005). Extend the ranges and update the defined names for larger months.
B55: Don't | C55: Never insert rows above row 6, merge cells in the raw sheets, or type into Calc_Data - it breaks every reference.
...

Sheet Setup
A1: SETUP - PERIOD, FILTERS & SETTINGS
A2: Every report in this workbook reads from these cells. Change a filter here and all outputs refresh.
A4: REPORTING PERIOD
A5: Period Start | B5: 46296 | C5: First day of the reporting month.
A6: Period End | B6: =EOMONTH(B5,0) | C6: Auto-calculated - do not overwrite.
A7: Interval Minutes | B7: 30 | C7: Length of one interval: 15, 30 or 60.
A9: FILTERS (applies to Calc_Data, Dashboard & Reconciliation)
A10: Site | B10: ALL | C10: Use ALL for the whole account.
A11: Queue / Skill | B11: ALL | C11: Use ALL or pick one queue from Lists.
A12: Channel | B12: ALL | C12: Use ALL or pick one channel from Lists.
A13: Report Source | B13: COMBINED | C13: VERINT, IEX or COMBINED on the dashboard.
A15: WORKBOOK INFO
A16: Account / Site Name | B16: Contact Center Operations | C16: Shown on the dashboard.
A17: Time Zone | B17: GMT+8 | C17: Label only - keep both sources in one time zone.
A18: Prepared By | B18: WFM Team | C18: Owner of this workbook.
A19: Last Updated | B19: =TODAY() | C19: Auto-stamped on open.
A20: Reconciliation Tolerance | B20: 0.02 | C20: Variance above this is flagged REVIEW.
A22: HOW TO USE
A23: 1. Set Period Start above, then paste the Verint export into Verint_Raw and the IEX export into IEX_Raw.
A24: 2. Both raw sheets share one schema - if your export order differs, rearrange the columns before pasting.
A25: 3. Clear the yellow sample rows (6:101) in both raw sheets once you are ready for live data.
A26: 4. Check DQ_Checks for blanks, duplicates and impossible values before reading the dashboard.
A27: 5. Use Reconciliation to prove Verint and IEX agree interval by interval.
A28: 6. Capacity is 10,000 rows per source. For a larger month, extend the raw ranges and update the defined names.

Sheet Lists
A1: REFERENCE LISTS
A2: Dropdown sources and queue master. Edit freely - filter lists always keep ALL in row 1.
A4: Sites | B4: Queues / Skills | C4: Channels | D4: Interval Minutes | E4: Sources | G4: Site filter | H4: Queue filter | I4: Channel filter
A5: Manila | B5: CS_Voice_General | C5: Voice | D5: 15 | E5: VERINT | G5: ALL | H5: ALL | I5: ALL
A6: Cebu | B6: CS_Voice_Billing | C6: Chat | D6: 30 | E6: IEX | G6: Manila | H6: CS_Voice_General | I6: Voice
A7: Davao | B7: Tech_Support | C7: Email | D7: 60 | E7: COMBINED | G7: Cebu | H7: CS_Voice_Billing | I7: Chat
A8: Bacolod | B8: Retention | C8: Social | G8: Davao | H8: Tech_Support | I8: Email
B9: Sales_Inbound | C9: Backoffice | G9: Bacolod | H9: Retention | I9: Social
B10: Chat_Support | H10: Sales_Inbound | I10: Backoffice
B11: Backoffice_Email | H11: Chat_Support
B12: Escalations | H12: Backoffice_Email
B13: VIP_Line | H13: Escalations
B14: Overflow | H14: VIP_Line
H15: Overflow

Sheet Verint_Raw
A1: VERINT RAW DATA
A2: Paste the raw interval export below the header row. Do not edit column order, insert formulas or merge cells - all calculations happen on Calc_Data.
A3: Source | B3: VERINT | C3: Rows 6-10,005 available | Paste as values | Date = date, Interval = hh:mm | J3: Sample rows are included - clear rows 6:101 before live use
A5: Date | B5: Interval Start | C5: Interval End | D5: Interval | E5: Site | F5: Queue / Skill | G5: Channel | H5: Offered | I5: Handled | J5: Abandoned | K5: Short Abandoned | L5: ASA (sec) | M5: AHT (sec) | N5: Talk (sec) | O5: Hold (sec) | P5: ACW (sec) | Q5: Staffed (agents) | R5: Required (agents) | S5: Service Level % | T5: Max Wait (sec) | U5: Source File | V5: Notes
A6: 46296 | B6: 0.33333333 | C6: 0.35416667 | D6: 8:00 AM - 8:30 AM | E6: Manila | F6: CS_Voice_General | G6: Voice | H6: 22 | I6: 19 | J6: 3 | K6: 1 | L6: 31 | M6: 410.7 | N6: 5150 | O6: 390 | P6: 2263 | Q6: 5.4 | R6: 5.2 | S6: 0.782 | T6: 120 | U6: SAMPLE_VERINT_2026-10.xlsx | V6: Sample row - delete before live use
A7: 46296 | B7: 0.35416667 | C7: 0.375 | D7: 8:30 AM - 9:00 AM | E7: Manila | F7: CS_Voice_General | G7: Voice | H7: 31 | I7: 27 | J7: 4 | K7: 1 | L7: 24 | M7: 386.3 | N7: 6883 | O7: 521 | P7: 3024 | Q7: 7.2 | R7: 6.9 | S7: 0.794 | T7: 310 | U7: SAMPLE_VERINT_2026-10.xlsx | V7: Sample row - delete before live use
A8: 46296 | B8: 0.375 | C8: 0.39583333 | D8: 9:00 AM - 9:30 AM | E8: Manila | F8: CS_Voice_General | G8: Voice | H8: 36 | I8: 31 | J8: 5 | K8: 2 | L8: 8 | M8: 372.2 | N8: 7615 | O8: 577 | P8: 3346 | Q8: 8 | R8: 8.9 | S8: 0.778 | T8: 180 | U8: SAMPLE_VERINT_2026-10.xlsx | V8: Sample row - delete before live use
A9: 46296 | B9: 0.39583333 | C9: 0.41666667 | D9: 9:30 AM - 10:00 AM | E9: Manila | F9: CS_Voice_General | G9: Voice | H9: 43 | I9: 39 | J9: 4 | K9: 1 | L9: 8 | M9: 310.5 | N9: 7993 | O9: 606 | P9: 3512 | Q9: 8 | R9: 8.5 | S9: 0.851 | T9: 180 | U9: SAMPLE_VERINT_2026-10.xlsx | V9: Sample row - delete before live use
A10: 46296 | B10: 0.41666667 | C10: 0.4375 | D10: 10:00 AM - 10:30 AM | E10: Manila | F10: CS_Voice_General | G10: Voice | H10: 38 | I10: 35 | J10: 3 | K10: 1 | L10: 8 | M10: 349.2 | N10: 8067 | O10: 611 | P10: 3545 | Q10: 8 | R10: 7.8 | S10: 0.874 | T10: 420 | U10: SAMPLE_VERINT_2026-10.xlsx | V10: Sample row - delete before live use
A11: 46296 | B11: 0.4375 | C11: 0.45833333 | D11: 10:30 AM - 11:00 AM | E11: Manila | F11: CS_Voice_General | G11: Voice | H11: 38 | I11: 35 | J11: 3 | K11: 1 | L11: 44 | M11: 330.7 | N11: 7640 | O11: 579 | P11: 3357 | Q11: 7.5 | R11: 8 | S11: 0.874 | T11: 180 | U11: SAMPLE_VERINT_2026-10.xlsx | V11: Sample row - delete before live use
A12: 46296 | B12: 0.45833333 | C12: 0.47916667 | D12: 11:00 AM - 11:30 AM | E12: Manila | F12: CS_Voice_General | G12: Voice | H12: 37 | I12: 33 | J12: 4 | K12: 1 | L12: 12 | M12: 310.7 | N12: 6766 | O12: 513 | P12: 2973 | Q12: 6.9 | R12: 6.6 | S12: 0.827 | T12: 310 | U12: SAMPLE_VERINT_2026-10.xlsx | V12: Sample row - delete before live use
A13: 46296 | B13: 0.47916667 | C13: 0.5 | D13: 11:30 AM - 12:00 PM | E13: Manila | F13: CS_Voice_General | G13: Voice | H13: 37 | I13: 33 | J13: 4 | K13: 1 | L13: 24 | M13: 353.4 | N13: 7697 | O13: 583 | P13: 3382 | Q13: 7.8 | R13: 8.3 | S13: 0.827 | T13: 240 | U13: SAMPLE_VERINT_2026-10.xlsx | V13: Sample row - delete before live use
A14: 46296 | B14: 0.5 | C14: 0.52083333 | D14: 12:00 PM - 12:30 PM | E14: Manila | F14: CS_Voice_General | G14: Voice | H14: 32 | I14: 29 | J14: 3 | K14: 1 | L14: 31 | M14: 418.8 | N14: 8016 | O14: 607 | P14: 3522 | Q14: 8 | R14: 8 | S14: 0.85 | T14: 240 | U14: SAMPLE_VERINT_2026-10.xlsx | V14: Sample row - delete before live use
A15: 46296 | B15: 0.52083333 | C15: 0.54166667 | D15: 12:30 PM - 1:00 PM | E15: Manila | F15: CS_Voice_General | G15: Voice | H15: 36 | I15: 33 | J15: 3 | K15: 1 | L15: 8 | M15: 424 | N15: 9235 | O15: 700 | P15: 4058 | Q15: 9.2 | R15: 9.3 | S15: 0.867 | T15: 120 | U15: SAMPLE_VERINT_2026-10.xlsx | V15: Sample row - delete before live use
A16: 46296 | B16: 0.54166667 | C16: 0.5625 | D16: 1:00 PM - 1:30 PM | E16: Manila | F16: CS_Voice_General | G16: Voice | H16: 38 | I16: 33 | J16: 5 | K16: 2 | L16: 24 | M16: 358.1 | N16: 7800 | O16: 591 | P16: 3427 | Q16: 8.2 | R16: 9.3 | S16: 0.789 | T16: 120 | U16: SAMPLE_VERINT_2026-10.xlsx | V16: Sample row - delete before live use
A17: 46296 | B17: 0.5625 | C17: 0.58333333 | D17: 1:30 PM - 2:00 PM | E17: Manila | F17: CS_Voice_General | G17: Voice | H17: 32 | I17: 27 | J17: 5 | K17: 2 | L17: 58 | M17: 394.9 | N17: 7037 | O17: 533 | P17: 3092 | Q17: 7.6 | R17: 8.4 | S17: 0.75 | T17: 240 | U17: SAMPLE_VERINT_2026-10.xlsx | V17: Sample row - delete before live use
... A101: 46297 | B101: 0.5625 | C101: 0.58333333 | D101: 1:30 PM - 2:00 PM | E101: Manila | F101: Retention | G101: Voice | H101: 8 | I101: 7 | J101: 1 | K101: 0 | L101: 58 | M101: 381.4 | N101: 1762 | O101: 134 | P101: 774 | Q101: 1.8 | R101: 2 | S101: 0.8 | T101: 120 | U101: SAMPLE_VERINT_2026-10.xlsx | V101: Sample row - delete before live use

Sheet IEX_Raw
A1: IEX RAW DATA
A2: Paste the raw interval export below the header row. Do not edit column order, insert formulas or merge cells - all calculations happen on Calc_Data.
A3: Source | B3: IEX | C3: Rows 6-10,005 available | Paste as values | Date = date, Interval = hh:mm | J3: Sample rows are included - clear rows 6:101 before live use
A5: Date | B5: Interval Start | C5: Interval End | D5: Interval | E5: Site | F5: Queue / Skill | G5: Channel | H5: Offered | I5: Handled | J5: Abandoned | K5: Short Abandoned | L5: ASA (sec) | M5: AHT (sec) | N5: Talk (sec) | O5: Hold (sec) | P5: ACW (sec) | Q5: Staffed (agents) | R5: Required (agents) | S5: Service Level % | T5: Max Wait (sec) | U5: Source File | V5: Notes
A6: 46296 | B6: 0.33333333 | C6: 0.35416667 | D6: 8:00 AM - 8:30 AM | E6: Manila | F6: CS_Voice_General | G6: Voice | H6: 22 | I6: 19 | J6: 3 | K6: 1 | L6: 31 | M6: 410.7 | N6: 5150 | O6: 390 | P6: 2263 | Q6: 5.4 | R6: 5.2 | S6: 0.782 | T6: 120 | U6: SAMPLE_IEX_2026-10.xlsx | V6: Sample row - delete before live use
A7: 46296 | B7: 0.35416667 | C7: 0.375 | D7: 8:30 AM - 9:00 AM | E7: Manila | F7: CS_Voice_General | G7: Voice | H7: 31 | I7: 27 | J7: 4 | K7: 1 | L7: 24 | M7: 386.3 | N7: 6883 | O7: 521 | P7: 3024 | Q7: 7.2 | R7: 6.9 | S7: 0.794 | T7: 310 | U7: SAMPLE_IEX_2026-10.xlsx | V7: Sample row - delete before live use
A8: 46296 | B8: 0.375 | C8: 0.39583333 | D8: 9:00 AM - 9:30 AM | E8: Manila | F8: CS_Voice_General | G8: Voice | H8: 36 | I8: 31 | J8: 5 | K8: 2 | L8: 8 | M8: 372.2 | N8: 7615 | O8: 577 | P8: 3346 | Q8: 8 | R8: 8.9 | S8: 0.778 | T8: 180 | U8: SAMPLE_IEX_2026-10.xlsx | V8: Sample row - delete before live use
A9: 46296 | B9: 0.39583333 | C9: 0.41666667 | D9: 9:30 AM - 10:00 AM | E9: Manila | F9: CS_Voice_General | G9: Voice | H9: 43 | I9: 39 | J9: 4 | K9: 1 | L9: 8 | M9: 310.5 | N9: 7993 | O9: 606 | P9: 3512 | Q9: 8 | R9: 8.5 | S9: 0.851 | T9: 180 | U9: SAMPLE_IEX_2026-10.xlsx | V9: Sample row - delete before live use
A10: 46296 | B10: 0.41666667 | C10: 0.4375 | D10: 10:00 AM - 10:30 AM | E10: Manila | F10: CS_Voice_General | G10: Voice | H10: 38 | I10: 35 | J10: 3 | K10: 1 | L10: 8 | M10: 349.2 | N10: 8067 | O10: 611 | P10: 3545 | Q10: 8 | R10: 7.8 | S10: 0.874 | T10: 420 | U10: SAMPLE_IEX_2026-10.xlsx | V10: Sample row - delete before live use
A11: 46296 | B11: 0.4375 | C11: 0.45833333 | D11: 10:30 AM - 11:00 AM | E11: Manila | F11: CS_Voice_General | G11: Voice | H11: 38 | I11: 35 | J11: 3 | K11: 1 | L11: 44 | M11: 330.7 | N11: 7640 | O11: 579 | P11: 3357 | Q11: 7.5 | R11: 8 | S11: 0.874 | T11: 180 | U11: SAMPLE_IEX_2026-10.xlsx | V11: Sample row - delete before live use
A12: 46296 | B12: 0.45833333 | C12: 0.47916667 | D12: 11:00 AM - 11:30 AM | E12: Manila | F12: CS_Voice_General | G12: Voice | H12: 37 | I12: 33 | J12: 4 | K12: 1 | L12: 12 | M12: 310.7 | N12: 6766 | O12: 513 | P12: 2973 | Q12: 6.9 | R12: 6.6 | S12: 0.827 | T12: 310 | U12: SAMPLE_IEX_2026-10.xlsx | V12: Sample row - delete before live use
A13: 46296 | B13: 0.47916667 | C13: 0.5 | D13: 11:30 AM - 12:00 PM | E13: Manila | F13: CS_Voice_General | G13: Voice | H13: 37 | I13: 33 | J13: 4 | K13: 1 | L13: 24 | M13: 353.4 | N13: 7697 | O13: 583 | P13: 3382 | Q13: 7.8 | R13: 8.3 | S13: 0.827 | T13: 240 | U13: SAMPLE_IEX_2026-10.xlsx | V13: Sample row - delete before live use
A14: 46296 | B14: 0.5 | C14: 0.52083333 | D14: 12:00 PM - 12:30 PM | E14: Manila | F14: CS_Voice_General | G14: Voice | H14: 32 | I14: 29 | J14: 3 | K14: 1 | L14: 31 | M14: 418.8 | N14: 8016 | O14: 607 | P14: 3522 | Q14: 8 | R14: 8 | S14: 0.85 | T14: 240 | U14: SAMPLE_IEX_2026-10.xlsx | V14: Sample row - delete before live use
A15: 46296 | B15: 0.52083333 | C15: 0.54166667 | D15: 12:30 PM - 1:00 PM | E15: Manila | F15: CS_Voice_General | G15: Voice | H15: 36 | I15: 33 | J15: 3 | K15: 1 | L15: 8 | M15: 424 | N15: 9235 | O15: 700 | P15: 4058 | Q15: 9.2 | R15: 9.3 | S15: 0.867 | T15: 120 | U15: SAMPLE_IEX_2026-10.xlsx | V15: Sample row - delete before live use
A16: 46296 | B16: 0.54166667 | C16: 0.5625 | D16: 1:00 PM - 1:30 PM | E16: Manila | F16: CS_Voice_General | G16: Voice | H16: 38 | I16: 33 | J16: 5 | K16: 2 | L16: 24 | M16: 358.1 | N16: 7800 | O16: 591 | P16: 3427 | Q16: 8.2 | R16: 9.3 | S16: 0.789 | T16: 120 | U16: SAMPLE_IEX_2026-10.xlsx | V16: Sample row - delete before live use
A17: 46296 | B17: 0.5625 | C17: 0.58333333 | D17: 1:30 PM - 2:00 PM | E17: Manila | F17: CS_Voice_General | G17: Voice | H17: 32 | I17: 27 | J17: 5 | K17: 2 | L17: 58 | M17: 394.9 | N17: 7037 | O17: 533 | P17: 3092 | Q17: 7.6 | R17: 8.4 | S17: 0.75 | T17: 240 | U17: SAMPLE_IEX_2026-10.xlsx | V17: Sample row - delete before live use
... A101: 46297 | B101: 0.5625 | C101: 0.58333333 | D101: 1:30 PM - 2:00 PM | E101: Manila | F101: Retention | G101: Voice | H101: 8 | I101: 7 | J101: 1 | K101: 0 | L101: 58 | M101: 381.4 | N101: 1762 | O101: 134 | P101: 774 | Q101: 1.8 | R101: 2 | S101: 0.8 | T101: 120 | U101: SAMPLE_IEX_2026-10.xlsx | V101: Sample row - delete before live use

Sheet Calc_Data
A1: CALCULATION ENGINE
A2: Do not edit. Every figure is derived from the raw sheets through filtered SUMIFS / SUMPRODUCT formulas.
A3: Period Start | B3: =Setup!$B$5 | D3: =IF($B$6="ALL","*",$B$6) | E3: <- SUMIFS criteria
A4: Period End | B4: =Setup!$B$6 | D4: =IF($B$7="ALL","*",$B$7)
A5: Interval Minutes | B5: =Setup!$B$7 | D5: =IF($B$8="ALL","*",$B$8)
A6: Site Filter | B6: =Setup!$B$10
A7: Queue Filter | B7: =Setup!$B$11
A8: Channel Filter | B8: =Setup!$B$12
A9: Reconciliation Tolerance | B9: =Setup!$B$20
A10: Report Source | B10: =Setup!$B$13
A12: 1. PERIOD TOTALS BY SOURCE
A13: Metric | C13: VERINT | D13: IEX | E13: COMBINED
A14: Contacts Offered | C14: =SUMIFS(VER_OFFERED,VER_DATE,">="&$B$3,VER_DATE,"<="&$B$4,VER_SITE,$D$3,VER_QUEUE,$D$4,VER_CHAN,$D$5) | D14: =SUMIFS(IEX_OFFERED,IEX_DATE,">="&$B$3,IEX_DATE,"<="&$B$4,IEX_SITE,$D$3,IEX_QUEUE,$D$4,IEX_CHAN,$D$5) | E14: =C14+D14
A15: Contacts Handled | C15: =SUMIFS(VER_HANDLED,VER_DATE,">="&$B$3,VER_DATE,"<="&$B$4,VER_SITE,$D$3,VER_QUEUE,$D$4,VER_CHAN,$D$5) | D15: =SUMIFS(IEX_HANDLED,IEX_DATE,">="&$B$3,IEX_DATE,"<="&$B$4,IEX_SITE,$D$3,IEX_QUEUE,$D$4,IEX_CHAN,$D$5) | E15: =C15+D15
A16: Contacts Abandoned | C16: =SUMIFS(VER_ABAND,VER_DATE,">="&$B$3,VER_DATE,"<="&$B$4,VER_SITE,$D$3,VER_QUEUE,$D$4,VER_CHAN,$D$5) | D16: =SUMIFS(IEX_ABAND,IEX_DATE,">="&$B$3,IEX_DATE,"<="&$B$4,IEX_SITE,$D$3,IEX_QUEUE,$D$4,IEX_CHAN,$D$5) | E16: =C16+D16
A17: Abandon Rate | C17: =IFERROR(C16/C14,0) | D17: =IFERROR(D16/D14,0) | E17: =IFERROR(E16/E14,0)
A18: Service Level | C18: =IFERROR(SUMPRODUCT((((VER_DATE>=$B$3)*(VER_DATE<=$B$4)))*(((($B$6="ALL")+(VER_SITE=$B$6))>0))*(((($B$7="ALL")+(VER_QUEUE=$B$7))>0))*(((($B$8="ALL")+(VER_CHAN=$B$8))>0))*VER_SL*VER_OFFERED)/C14,0) | D18: =IFERROR(SUMPRODUCT((((IEX_DATE>=$B$3)*(IEX_DATE<=$B$4)))*(((($B$6="ALL")+(IEX_SITE=$B$6))>0))*(((($B$7="ALL")+(IEX_QUEUE=$B$7))>0))*(((($B$8="ALL")+(IEX_CHAN=$B$8))>0))*IEX_SL*IEX_OFFERED)/D14,0) | E18: =IFERROR((C18*C14+D18*D14)/E14,0)
A19: Avg Speed of Answer (sec) | C19: =IFERROR(SUMPRODUCT((((VER_DATE>=$B$3)*(VER_DATE<=$B$4)))*(((($B$6="ALL")+(VER_SITE=$B$6))>0))*(((($B$7="ALL")+(VER_QUEUE=$B$7))>0))*(((($B$8="ALL")+(VER_CHAN=$B$8))>0))*VER_ASA*VER_HANDLED)/C15,0) | D19: =IFERROR(SUMPRODUCT((((IEX_DATE>=$B$3)*(IEX_DATE<=$B$4)))*(((($B$6="ALL")+(IEX_SITE=$B$6))>0))*(((($B$7="ALL")+(IEX_QUEUE=$B$7))>0))*(((($B$8="ALL")+(IEX_CHAN=$B$8))>0))*IEX_ASA*IEX_HANDLED)/D15,0) | E19: =IFERROR((C19*C15+D19*D15)/E15,0)
A20: Avg Handle Time (sec) | C20: =IFERROR((SUMIFS(VER_TALK,VER_DATE,">="&$B$3,VER_DATE,"<="&$B$4,VER_SITE,$D$3,VER_QUEUE,$D$4,VER_CHAN,$D$5)+SUMIFS(VER_HOLD,VER_DATE,">="&$B$3,VER_DATE,"<="&$B$4,VER_SITE,$D$3,VER_QUEUE,$D$4,VER_CHAN,$D$5)+SUMIFS(VER_ACW,VER_DATE,">="&$B$3,VER_DATE,"<="&$B$4,VER_SITE,$D$3,VER_QUEUE,$D$4,VER_CHAN,$D$5))/C15,0) | D20: =IFERROR((SUMIFS(IEX_TALK,IEX_DATE,">="&$B$3,IEX_DATE,"<="&$B$4,IEX_SITE,$D$3,IEX_QUEUE,$D$4,IEX_CHAN,$D$5)+SUMIFS(IEX_HOLD,IEX_DATE,">="&$B$3,IEX_DATE,"<="&$B$4,IEX_SITE,$D$3,IEX_QUEUE,$D$4,IEX_CHAN,$D$5)+SUMIFS(IEX_ACW,IEX_DATE,">="&$B$3,IEX_DATE,"<="&$B$4,IEX_SITE,$D$3,IEX_QUEUE,$D$4,IEX_CHAN,$D$5))/D15,0) | E20: =IFERROR((C20*C15+D20*D15)/E15,0)
A21: Staffed Agent-Hours | C21: =SUMIFS(VER_STAFFED,VER_DATE,">="&$B$3,VER_DATE,"<="&$B$4,VER_SITE,$D$3,VER_QUEUE,$D$4,VER_CHAN,$D$5)*$B$5/60 | D21: =SUMIFS(IEX_STAFFED,IEX_DATE,">="&$B$3,IEX_DATE,"<="&$B$4,IEX_SITE,$D$3,IEX_QUEUE,$D$4,IEX_CHAN,$D$5)*$B$5/60 | E21: =C21+D21
A22: Required Agent-Hours | C22: =SUMIFS(VER_REQ,VER_DATE,">="&$B$3,VER_DATE,"<="&$B$4,VER_SITE,$D$3,VER_QUEUE,$D$4,VER_CHAN,$D$5)*$B$5/60 | D22: =SUMIFS(IEX_REQ,IEX_DATE,">="&$B$3,IEX_DATE,"<="&$B$4,IEX_SITE,$D$3,IEX_QUEUE,$D$4,IEX_CHAN,$D$5)*$B$5/60 | E22: =C22+D22
A23: Staffing Gap (Agent-Hours) | C23: =C22-C21 | D23: =D22-D21 | E23: =E22-E21
A24: Staffing Gap % | C24: =IFERROR(C23/C22,0) | D24: =IFERROR(D23/D22,0) | E24: =IFERROR(E23/E22,0)
A25: Occupancy | C25: =IFERROR(((SUMIFS(VER_TALK,VER_DATE,">="&$B$3,VER_DATE,"<="&$B$4,VER_SITE,$D$3,VER_QUEUE,$D$4,VER_CHAN,$D$5)+SUMIFS(VER_HOLD,VER_DATE,">="&$B$3,VER_DATE,"<="&$B$4,VER_SITE,$D$3,VER_QUEUE,$D$4,VER_CHAN,$D$5)+SUMIFS(VER_ACW,VER_DATE,">="&$B$3,VER_DATE,"<="&$B$4,VER_SITE,$D$3,VER_QUEUE,$D$4,VER_CHAN,$D$5))/3600)/C21,0) | D25: =IFERROR(((SUMIFS(IEX_TALK,IEX_DATE,">="&$B$3,IEX_DATE,"<="&$B$4,IEX_SITE,$D$3,IEX_QUEUE,$D$4,IEX_CHAN,$D$5)+SUMIFS(IEX_HOLD,IEX_DATE,">="&$B$3,IEX_DATE,"<="&$B$4,IEX_SITE,$D$3,IEX_QUEUE,$D$4,IEX_CHAN,$D$5)+SUMIFS(IEX_ACW,IEX_DATE,">="&$B$3,IEX_DATE,"<="&$B$4,IEX_SITE,$D$3,IEX_QUEUE,$D$4,IEX_CHAN,$D$5))/3600)/D21,0) | E25: =IFERROR((C25*C21+D25*D21)/E21,0)
A26: Intervals Captured | C26: =SUMPRODUCT((VER_DATE>=$B$3)*(VER_DATE<=$B$4)*(($B$6="ALL")+(VER_SITE=$B$6)-($B$6="ALL")*(VER_SITE=$B$6))*(($B$7="ALL")+(VER_QUEUE=$B$7)-($B$7="ALL")*(VER_QUEUE=$B$7))*(($B$8="ALL")+(VER_CHAN=$B$8)-($B$8="ALL")*(VER_CHAN=$B$8))) | D26: =SUMPRODUCT((IEX_DATE>=$B$3)*(IEX_DATE<=$B$4)*(($B$6="ALL")+(IEX_SITE=$B$6)-($B$6="ALL")*(IEX_SITE=$B$6))*(($B$7="ALL")+(IEX_QUEUE=$B$7)-($B$7="ALL")*(IEX_QUEUE=$B$7))*(($B$8="ALL")+(IEX_CHAN=$B$8)-($B$8="ALL")*(IEX_CHAN=$B$8))) | E26: =C26+D26
A27: Avg Staffed Agents / Interval | C27: =IFERROR(SUMIFS(VER_STAFFED,VER_DATE,">="&$B$3,VER_DATE,"<="&$B$4,VER_SITE,$D$3,VER_QUEUE,$D$4,VER_CHAN,$D$5)/C26,0) | D27: =IFERROR(SUMIFS(IEX_STAFFED,IEX_DATE,">="&$B$3,IEX_DATE,"<="&$B$4,IEX_SITE,$D$3,IEX_QUEUE,$D$4,IEX_CHAN,$D$5)/D26,0) | E27: =IFERROR((C27*C26+D27*D26)/E26,0)
A28: Max Interval Wait (sec) | C28: =IFERROR(SUMPRODUCT(MAX((VER_DATE>=$B$3)*(VER_DATE<=$B$4)*(($B$6="ALL")+(VER_SITE=$B$6)-($B$6="ALL")*(VER_SITE=$B$6))*(($B$7="ALL")+(VER_QUEUE=$B$7)-($B$7="ALL")*(VER_QUEUE=$B$7))*(($B$8="ALL")+(VER_CHAN=$B$8)-($B$8="ALL")*(VER_CHAN=$B$8))*VER_WAIT)),0) | D28: =IFERROR(SUMPRODUCT(MAX((IEX_DATE>=$B$3)*(IEX_DATE<=$B$4)*(($B$6="ALL")+(IEX_SITE=$B$6)-($B$6="ALL")*(IEX_SITE=$B$6))*(($B$7="ALL")+(IEX_QUEUE=$B$7)-($B$7="ALL")*(IEX_QUEUE=$B$7))*(($B$8="ALL")+(IEX_CHAN=$B$8)-($B$8="ALL")*(IEX_CHAN=$B$8))*IEX_WAIT)),0) | E28: =MAX(C28,D28)
A29: 2. DAILY TREND (period dates)
A31: Date | B31: Day | C31: VERINT Offered | D31: IEX Offered | E31: VERINT Handled | F31: IEX Handled | G31: VERINT Abandoned | H31: IEX Abandoned | I31: VERINT Aband % | J31: IEX Aband % | K31: VERINT SL % | L31: IEX SL % | M31: VERINT AHT | N31: IEX AHT
A32: =IF($B$3>$B$4,"",$B$3) | B32: =IF(A32="","",TEXT(A32,"ddd")) | C32: =IF($A32="","",SUMIFS(VER_OFFERED,VER_DATE,">="&$A32,VER_DATE,"<="&$A32,VER_SITE,$D$3,VER_QUEUE,$D$4,VER_CHAN,$D$5)) | D32: =IF($A32="","",SUMIFS(IEX_OFFERED,IEX_DATE,">="&$A32,IEX_DATE,"<="&$A32,IEX_SITE,$D$3,IEX_QUEUE,$D$4,IEX_CHAN,$D$5)) | E32: =IF($A32="","",SUMIFS(VER_HANDLED,VER_DATE,">="&$A32,VER_DATE,"<="&$A32,VER_SITE,$D$3,VER_QUEUE,$D$4,VER_CHAN,$D$5)) | F32: =IF($A32="","",SUMIFS(IEX_HANDLED,IEX_DATE,">="&$A32,IEX_DATE,"<="&$A32,IEX_SITE,$D$3,IEX_QUEUE,$D$4,IEX_CHAN,$D$5)) | G32: =IF($A32="","",SUMIFS(VER_ABAND,VER_DATE,">="&$A32,VER_DATE,"<="&$A32,VER_SITE,$D$3,VER_QUEUE,$D$4,VER_CHAN,$D$5)) | H32: =IF($A32="","",SUMIFS(IEX_ABAND,IEX_DATE,">="&$A32,IEX_DATE,"<="&$A32,IEX_SITE,$D$3,IEX_QUEUE,$D$4,IEX_CHAN,$D$5)) | I32: =IF(C32="","",IFERROR(G32/C32,0)) | J32: =IF(D32="","",IFERROR(H32/D32,0)) | K32: =IF(C32="","",IFERROR(SUMPRODUCT((((VER_DATE>=$A32)*(VER_DATE<=$A32)))*(((($B$6="ALL")+(VER_SITE=$B$6))>0))*(((($B$7="ALL")+(VER_QUEUE=$B$7))>0))*(((($B$8="ALL")+(VER_CHAN=$B$8))>0))*VER_SL*VER_OFFERED)/C32,0)) | L32: =IF(D32="","",IFERROR(SUMPRODUCT((((IEX_DATE>=$A32)*(IEX_DATE<=$A32)))*(((($B$6="ALL")+(IEX_SITE=$B$6))>0))*(((($B$7="ALL")+(IEX_QUEUE=$B$7))>0))*(((($B$8="ALL")+(IEX_CHAN=$B$8))>0))*IEX_SL*IEX_OFFERED)/D32,0)) | M32: =IF(C32="","",IFERROR((SUMIFS(VER_TALK,VER_DATE,">="&$A32,VER_DATE,"<="&$A32,VER_SITE,$D$3,VER_QUEUE,$D$4,VER_CHAN,$D$5)+SUMIFS(VER_HOLD,VER_DATE,">="&$A32,VER_DATE,"<="&$A32,VER_SITE,$D$3,VER_QUEUE,$D$4,VER_CHAN,$D$5)+SUMIFS(VER_ACW,VER_DATE,">="&$A32,VER_DATE,"<="&$A32,VER_SITE,$D$3,VER_QUEUE,$D$4,VER_CHAN,$D$5))/E32,0)) | N32: =IF(D32="","",IFERROR((SUMIFS(IEX_TALK,IEX_DATE,">="&$A32,IEX_DATE,"<="&$A32,IEX_SITE,$D$3,IEX_QUEUE,$D$4,IEX_CHAN,$D$5)+SUMIFS(IEX_HOLD,IEX_DATE,">="&$A32,IEX_DATE,"<="&$A32,IEX_SITE,$D$3,IEX_QUEUE,$D$4,IEX_CHAN,$D$5)+SUMIFS(IEX_ACW,IEX_DATE,">="&$A32,IEX_DATE,"<="&$A32,IEX_SITE,$D$3,IEX_QUEUE,$D$4,IEX_CHAN,$D$5))/F32,0))
A33: =IF(OR(A32="",A32+1>$B$4),"",A32+1) | B33: =IF(A33="","",TEXT(A33,"ddd")) | C33: =IF($A33="","",SUMIFS(VER_OFFERED,VER_DATE,">="&$A33,VER_DATE,"<="&$A33,VER_SITE,$D$3,VER_QUEUE,$D$4,VER_CHAN,$D$5)) | D33: =IF($A33="","",SUMIFS(IEX_OFFERED,IEX_DATE,">="&$A33,IEX_DATE,"<="&$A33,IEX_SITE,$D$3,IEX_QUEUE,$D$4,IEX_CHAN,$D$5)) | E33: =IF($A33="","",SUMIFS(VER_HANDLED,VER_DATE,">="&$A33,VER_DATE,"<="&$A33,VER_SITE,$D$3,VER_QUEUE,$D$4,VER_CHAN,$D$5)) | F33: =IF($A33="","",SUMIFS(IEX_HANDLED,IEX_DATE,">="&$A33,IEX_DATE,"<="&$A33,IEX_SITE,$D$3,IEX_QUEUE,$D$4,IEX_CHAN,$D$5)) | G33: =IF($A33="","",SUMIFS(VER_ABAND,VER_DATE,">="&$A33,VER_DATE,"<="&$A33,VER_SITE,$D$3,VER_QUEUE,$D$4,VER_CHAN,$D$5)) | H33: =IF($A33="","",SUMIFS(IEX_ABAND,IEX_DATE,">="&$A33,IEX_DATE,"<="&$A33,IEX_SITE,$D$3,IEX_QUEUE,$D$4,IEX_CHAN,$D$5)) | I33: =IF(C33="","",IFERROR(G33/C33,0)) | J33: =IF(D33="","",IFERROR(H33/D33,0)) | K33: =IF(C33="","",IFERROR(SUMPRODUCT((((VER_DATE>=$A33)*(VER_DATE<=$A33)))*(((($B$6="ALL")+(VER_SITE=$B$6))>0))*(((($B$7="ALL")+(VER_QUEUE=$B$7))>0))*(((($B$8="ALL")+(VER_CHAN=$B$8))>0))*VER_SL*VER_OFFERED)/C33,0)) | L33: =IF(D33="","",IFERROR(SUMPRODUCT((((IEX_DATE>=$A33)*(IEX_DATE<=$A33)))*(((($B$6="ALL")+(IEX_SITE=$B$6))>0))*(((($B$7="ALL")+(IEX_QUEUE=$B$7))>0))*(((($B$8="ALL")+(IEX_CHAN=$B$8))>0))*IEX_SL*IEX_OFFERED)/D33,0)) | M33: =IF(C33="","",IFERROR((SUMIFS(VER_TALK,VER_DATE,">="&$A33,VER_DATE,"<="&$A33,VER_SITE,$D$3,VER_QUEUE,$D$4,VER_CHAN,$D$5)+SUMIFS(VER_HOLD,VER_DATE,">="&$A33,VER_DATE,"<="&$A33,VER_SITE,$D$3,VER_QUEUE,$D$4,VER_CHAN,$D$5)+SUMIFS(VER_ACW,VER_DATE,">="&$A33,VER_DATE,"<="&$A33,VER_SITE,$D$3,VER_QUEUE,$D$4,VER_CHAN,$D$5))/E33,0)) | N33: =IF(D33="","",IFERROR((SUMIFS(IEX_TALK,IEX_DATE,">="&$A33,IEX_DATE,"<="&$A33,IEX_SITE,$D$3,IEX_QUEUE,$D$4,IEX_CHAN,$D$5)+SUMIFS(IEX_HOLD,IEX_DATE,">="&$A33,IEX_DATE,"<="&$A33,IEX_SITE,$D$3,IEX_QUEUE,$D$4,IEX_CHAN,$D$5)+SUMIFS(IEX_ACW,IEX_DATE,">="&$A33,IEX_DATE,"<="&$A33,IEX_SITE,$D$3,IEX_QUEUE,$D$4,IEX_CHAN,$D$5))/F33,0))
A34: =IF(OR(A33="",A33+1>$B$4),"",A33+1) | B34: =IF(A34="","",TEXT(A34,"ddd")) | C34: =IF($A34="","",SUMIFS(VER_OFFERED,VER_DATE,">="&$A34,VER_DATE,"<="&$A34,VER_SITE,$D$3,VER_QUEUE,$D$4,VER_CHAN,$D$5)) | D34: =IF($A34="","",SUMIFS(IEX_OFFERED,IEX_DATE,">="&$A34,IEX_DATE,"<="&$A34,IEX_SITE,$D$3,IEX_QUEUE,$D$4,IEX_CHAN,$D$5)) | E34: =IF($A34="","",SUMIFS(VER_HANDLED,VER_DATE,">="&$A34,VER_DATE,"<="&$A34,VER_SITE,$D$3,VER_QUEUE,$D$4,VER_CHAN,$D$5)) | F34: =IF($A34="","",SUMIFS(IEX_HANDLED,IEX_DATE,">="&$A34,IEX_DATE,"<="&$A34,IEX_SITE,$D$3,IEX_QUEUE,$D$4,IEX_CHAN,$D$5)) | G34: =IF($A34="","",SUMIFS(VER_ABAND,VER_DATE,">="&$A34,VER_DATE,"<="&$A34,VER_SITE,$D$3,VER_QUEUE,$D$4,VER_CHAN,$D$5)) | H34: =IF($A34="","",SUMIFS(IEX_ABAND,IEX_DATE,">="&$A34,IEX_DATE,"<="&$A34,IEX_SITE,$D$3,IEX_QUEUE,$D$4,IEX_CHAN,$D$5)) | I34: =IF(C34="","",IFERROR(G34/C34,0)) | J34: =IF(D34="","",IFERROR(H34/D34,0)) | K34: =IF(C34="","",IFERROR(SUMPRODUCT((((VER_DATE>=$A34)*(VER_DATE<=$A34)))*(((($B$6="ALL")+(VER_SITE=$B$6))>0))*(((($B$7="ALL")+(VER_QUEUE=$B$7))>0))*(((($B$8="ALL")+(VER_CHAN=$B$8))>0))*VER_SL*VER_OFFERED)/C34,0)) | L34: =IF(D34="","",IFERROR(SUMPRODUCT((((IEX_DATE>=$A34)*(IEX_DATE<=$A34)))*(((($B$6="ALL")+(IEX_SITE=$B$6))>0))*(((($B$7="ALL")+(IEX_QUEUE=$B$7))>0))*(((($B$8="ALL")+(IEX_CHAN=$B$8))>0))*IEX_SL*IEX_OFFERED)/D34,0)) | M34: =IF(C34="","",IFERROR((SUMIFS(VER_TALK,VER_DATE,">="&$A34,VER_DATE,"<="&$A34,VER_SITE,$D$3,VER_QUEUE,$D$4,VER_CHAN,$D$5)+SUMIFS(VER_HOLD,VER_DATE,">="&$A34,VER_DATE,"<="&$A34,VER_SITE,$D$3,VER_QUEUE,$D$4,VER_CHAN,$D$5)+SUMIFS(VER_ACW,VER_DATE,">="&$A34,VER_DATE,"<="&$A34,VER_SITE,$D$3,VER_QUEUE,$D$4,VER_CHAN,$D$5))/E34,0)) | N34: =IF(D34="","",IFERROR((SUMIFS(IEX_TALK,IEX_DATE,">="&$A34,IEX_DATE,"<="&$A34,IEX_SITE,$D$3,IEX_QUEUE,$D$4,IEX_CHAN,$D$5)+SUMIFS(IEX_HOLD,IEX_DATE,">="&$A34,IEX_DATE,"<="&$A34,IEX_SITE,$D$3,IEX_QUEUE,$D$4,IEX_CHAN,$D$5)+SUMIFS(IEX_ACW,IEX_DATE,">="&$A34,IEX_DATE,"<="&$A34,IEX_SITE,$D$3,IEX_QUEUE,$D$4,IEX_CHAN,$D$5))/F34,0))
A35: =IF(OR(A34="",A34+1>$B$4),"",A34+1) | B35: =IF(A35="","",TEXT(A35,"ddd")) | C35: =IF($A35="","",SUMIFS(VER_OFFERED,VER_DATE,">="&$A35,VER_DATE,"<="&$A35,VER_SITE,$D$3,VER_QUEUE,$D$4,VER_CHAN,$D$5)) | D35: =IF($A35="","",SUMIFS(IEX_OFFERED,IEX_DATE,">="&$A35,IEX_DATE,"<="&$A35,IEX_SITE,$D$3,IEX_QUEUE,$D$4,IEX_CHAN,$D$5)) | E35: =IF($A35="","",SUMIFS(VER_HANDLED,VER_DATE,">="&$A35,VER_DATE,"<="&$A35,VER_SITE,$D$3,VER_QUEUE,$D$4,VER_CHAN,$D$5)) | F35: =IF($A35="","",SUMIFS(IEX_HANDLED,IEX_DATE,">="&$A35,IEX_DATE,"<="&$A35,IEX_SITE,$D$3,IEX_QUEUE,$D$4,IEX_CHAN,$D$5)) | G35: =IF($A35="","",SUMIFS(VER_ABAND,VER_DATE,">="&$A35,VER_DATE,"<="&$A35,VER_SITE,$D$3,VER_QUEUE,$D$4,VER_CHAN,$D$5)) | H35: =IF($A35="","",SUMIFS(IEX_ABAND,IEX_DATE,">="&$A35,IEX_DATE,"<="&$A35,IEX_SITE,$D$3,IEX_QUEUE,$D$4,IEX_CHAN,$D$5)) | I35: =IF(C35="","",IFERROR(G35/C35,0)) | J35: =IF(D35="","",IFERROR(H35/D35,0)) | K35: =IF(C35="","",IFERROR(SUMPRODUCT((((VER_DATE>=$A35)*(VER_DATE<=$A35)))*(((($B$6="ALL")+(VER_SITE=$B$6))>0))*(((($B$7="ALL")+(VER_QUEUE=$B$7))>0))*(((($B$8="ALL")+(VER_CHAN=$B$8))>0))*VER_SL*VER_OFFERED)/C35,0)) | L35: =IF(D35="","",IFERROR(SUMPRODUCT((((IEX_DATE>=$A35)*(IEX_DATE<=$A35)))*(((($B$6="ALL")+(IEX_SITE=$B$6))>0))*(((($B$7="ALL")+(IEX_QUEUE=$B$7))>0))*(((($B$8="ALL")+(IEX_CHAN=$B$8))>0))*IEX_SL*IEX_OFFERED)/D35,0)) | M35: =IF(C35="","",IFERROR((SUMIFS(VER_TALK,VER_DATE,">="&$A35,VER_DATE,"<="&$A35,VER_SITE,$D$3,VER_QUEUE,$D$4,VER_CHAN,$D$5)+SUMIFS(VER_HOLD,VER_DATE,">="&$A35,VER_DATE,"<="&$A35,VER_SITE,$D$3,VER_QUEUE,$D$4,VER_CHAN,$D$5)+SUMIFS(VER_ACW,VER_DATE,">="&$A35,VER_DATE,"<="&$A35,VER_SITE,$D$3,VER_QUEUE,$D$4,VER_CHAN,$D$5))/E35,0)) | N35: =IF(D35="","",IFERROR((SUMIFS(IEX_TALK,IEX_DATE,">="&$A35,IEX_DATE,"<="&$A35,IEX_SITE,$D$3,IEX_QUEUE,$D$4,IEX_CHAN,$D$5)+SUMIFS(IEX_HOLD,IEX_DATE,">="&$A35,IEX_DATE,"<="&$A35,IEX_SITE,$D$3,IEX_QUEUE,$D$4,IEX_CHAN,$D$5)+SUMIFS(IEX_ACW,IEX_DATE,">="&$A35,IEX_DATE,"<="&$A35,IEX_SITE,$D$3,IEX_QUEUE,$D$4,IEX_CHAN,$D$5))/F35,0))
A36: =IF(OR(A35="",A35+1>$B$4),"",A35+1) | B36: =IF(A36="","",TEXT(A36,"ddd")) | C36: =IF($A36="","",SUMIFS(VER_OFFERED,VER_DATE,">="&$A36,VER_DATE,"<="&$A36,VER_SITE,$D$3,VER_QUEUE,$D$4,VER_CHAN,$D$5)) | D36: =IF($A36="","",SUMIFS(IEX_OFFERED,IEX_DATE,">="&$A36,IEX_DATE,"<="&$A36,IEX_SITE,$D$3,IEX_QUEUE,$D$4,IEX_CHAN,$D$5)) | E36: =IF($A36="","",SUMIFS(VER_HANDLED,VER_DATE,">="&$A36,VER_DATE,"<="&$A36,VER_SITE,$D$3,VER_QUEUE,$D$4,VER_CHAN,$D$5)) | F36: =IF($A36="","",SUMIFS(IEX_HANDLED,IEX_DATE,">="&$A36,IEX_DATE,"<="&$A36,IEX_SITE,$D$3,IEX_QUEUE,$D$4,IEX_CHAN,$D$5)) | G36: =IF($A36="","",SUMIFS(VER_ABAND,VER_DATE,">="&$A36,VER_DATE,"<="&$A36,VER_SITE,$D$3,VER_QUEUE,$D$4,VER_CHAN,$D$5)) | H36: =IF($A36="","",SUMIFS(IEX_ABAND,IEX_DATE,">="&$A36,IEX_DATE,"<="&$A36,IEX_SITE,$D$3,IEX_QUEUE,$D$4,IEX_CHAN,$D$5)) | I36: =IF(C36="","",IFERROR(G36/C36,0)) | J36: =IF(D36="","",IFERROR(H36/D36,0)) | K36: =IF(C36="","",IFERROR(SUMPRODUCT((((VER_DATE>=$A36)*(VER_DATE<=$A36)))*(((($B$6="ALL")+(VER_SITE=$B$6))>0))*(((($B$7="ALL")+(VER_QUEUE=$B$7))>0))*(((($B$8="ALL")+(VER_CHAN=$B$8))>0))*VER_SL*VER_OFFERED)/C36,0)) | L36: =IF(D36="","",IFERROR(SUMPRODUCT((((IEX_DATE>=$A36)*(IEX_DATE<=$A36)))*(((($B$6="ALL")+(IEX_SITE=$B$6))>0))*(((($B$7="ALL")+(IEX_QUEUE=$B$7))>0))*(((($B$8="ALL")+(IEX_CHAN=$B$8))>0))*IEX_SL*IEX_OFFERED)/D36,0)) | M36: =IF(C36="","",IFERROR((SUMIFS(VER_TALK,VER_DATE,">="&$A36,VER_DATE,"<="&$A36,VER_SITE,$D$3,VER_QUEUE,$D$4,VER_CHAN,$D$5)+SUMIFS(VER_HOLD,VER_DATE,">="&$A36,VER_DATE,"<="&$A36,VER_SITE,$D$3,VER_QUEUE,$D$4,VER_CHAN,$D$5)+SUMIFS(VER_ACW,VER_DATE,">="&$A36,VER_DATE,"<="&$A36,VER_SITE,$D$3,VER_QUEUE,$D$4,VER_CHAN,$D$5))/E36,0)) | N36: =IF(D36="","",IFERROR((SUMIFS(IEX_TALK,IEX_DATE,">="&$A36,IEX_DATE,"<="&$A36,IEX_SITE,$D$3,IEX_QUEUE,$D$4,IEX_CHAN,$D$5)+SUMIFS(IEX_HOLD,IEX_DATE,">="&$A36,IEX_DATE,"<="&$A36,IEX_SITE,$D$3,IEX_QUEUE,$D$4,IEX_CHAN,$D$5)+SUMIFS(IEX_ACW,IEX_DATE,">="&$A36,IEX_DATE,"<="&$A36,IEX_SITE,$D$3,IEX_QUEUE,$D$4,IEX_CHAN,$D$5))/F36,0))
A37: =IF(OR(A36="",A36+1>$B$4),"",A36+1) | B37: =IF(A37="","",TEXT(A37,"ddd")) | C37: =IF($A37="","",SUMIFS(VER_OFFERED,VER_DATE,">="&$A37,VER_DATE,"<="&$A37,VER_SITE,$D$3,VER_QUEUE,$D$4,VER_CHAN,$D$5)) | D37: =IF($A37="","",SUMIFS(IEX_OFFERED,IEX_DATE,">="&$A37,IEX_DATE,"<="&$A37,IEX_SITE,$D$3,IEX_QUEUE,$D$4,IEX_CHAN,$D$5)) | E37: =IF($A37="","",SUMIFS(VER_HANDLED,VER_DATE,">="&$A37,VER_DATE,"<="&$A37,VER_SITE,$D$3,VER_QUEUE,$D$4,VER_CHAN,$D$5)) | F37: =IF($A37="","",SUMIFS(IEX_HANDLED,IEX_DATE,">="&$A37,IEX_DATE,"<="&$A37,IEX_SITE,$D$3,IEX_QUEUE,$D$4,IEX_CHAN,$D$5)) | G37: =IF($A37="","",SUMIFS(VER_ABAND,VER_DATE,">="&$A37,VER_DATE,"<="&$A37,VER_SITE,$D$3,VER_QUEUE,$D$4,VER_CHAN,$D$5)) | H37: =IF($A37="","",SUMIFS(IEX_ABAND,IEX_DATE,">="&$A37,IEX_DATE,"<="&$A37,IEX_SITE,$D$3,IEX_QUEUE,$D$4,IEX_CHAN,$D$5)) | I37: =IF(C37="","",IFERROR(G37/C37,0)) | J37: =IF(D37="","",IFERROR(H37/D37,0)) | K37: =IF(C37="","",IFERROR(SUMPRODUCT((((VER_DATE>=$A37)*(VER_DATE<=$A37)))*(((($B$6="ALL")+(VER_SITE=$B$6))>0))*(((($B$7="ALL")+(VER_QUEUE=$B$7))>0))*(((($B$8="ALL")+(VER_CHAN=$B$8))>0))*VER_SL*VER_OFFERED)/C37,0)) | L37: =IF(D37="","",IFERROR(SUMPRODUCT((((IEX_DATE>=$A37)*(IEX_DATE<=$A37)))*(((($B$6="ALL")+(IEX_SITE=$B$6))>0))*(((($B$7="ALL")+(IEX_QUEUE=$B$7))>0))*(((($B$8="ALL")+(IEX_CHAN=$B$8))>0))*IEX_SL*IEX_OFFERED)/D37,0)) | M37: =IF(C37="","",IFERROR((SUMIFS(VER_TALK,VER_DATE,">="&$A37,VER_DATE,"<="&$A37,VER_SITE,$D$3,VER_QUEUE,$D$4,VER_CHAN,$D$5)+SUMIFS(VER_HOLD,VER_DATE,">="&$A37,VER_DATE,"<="&$A37,VER_SITE,$D$3,VER_QUEUE,$D$4,VER_CHAN,$D$5)+SUMIFS(VER_ACW,VER_DATE,">="&$A37,VER_DATE,"<="&$A37,VER_SITE,$D$3,VER_QUEUE,$D$4,VER_CHAN,$D$5))/E37,0)) | N37: =IF(D37="","",IFERROR((SUMIFS(IEX_TALK,IEX_DATE,">="&$A37,IEX_DATE,"<="&$A37,IEX_SITE,$D$3,IEX_QUEUE,$D$4,IEX_CHAN,$D$5)+SUMIFS(IEX_HOLD,IEX_DATE,">="&$A37,IEX_DATE,"<="&$A37,IEX_SITE,$D$3,IEX_QUEUE,$D$4,IEX_CHAN,$D$5)+SUMIFS(IEX_ACW,IEX_DATE,">="&$A37,IEX_DATE,"<="&$A37,IEX_SITE,$D$3,IEX_QUEUE,$D$4,IEX_CHAN,$D$5))/F37,0))
A38: =IF(OR(A37="",A37+1>$B$4),"",A37+1) | B38: =IF(A38="","",TEXT(A38,"ddd")) | C38: =IF($A38="","",SUMIFS(VER_OFFERED,VER_DATE,">="&$A38,VER_DATE,"<="&$A38,VER_SITE,$D$3,VER_QUEUE,$D$4,VER_CHAN,$D$5)) | D38: =IF($A38="","",SUMIFS(IEX_OFFERED,IEX_DATE,">="&$A38,IEX_DATE,"<="&$A38,IEX_SITE,$D$3,IEX_QUEUE,$D$4,IEX_CHAN,$D$5)) | E38: =IF($A38="","",SUMIFS(VER_HANDLED,VER_DATE,">="&$A38,VER_DATE,"<="&$A38,VER_SITE,$D$3,VER_QUEUE,$D$4,VER_CHAN,$D$5)) | F38: =IF($A38="","",SUMIFS(IEX_HANDLED,IEX_DATE,">="&$A38,IEX_DATE,"<="&$A38,IEX_SITE,$D$3,IEX_QUEUE,$D$4,IEX_CHAN,$D$5)) | G38: =IF($A38="","",SUMIFS(VER_ABAND,VER_DATE,">="&$A38,VER_DATE,"<="&$A38,VER_SITE,$D$3,VER_QUEUE,$D$4,VER_CHAN,$D$5)) | H38: =IF($A38="","",SUMIFS(IEX_ABAND,IEX_DATE,">="&$A38,IEX_DATE,"<="&$A38,IEX_SITE,$D$3,IEX_QUEUE,$D$4,IEX_CHAN,$D$5)) | I38: =IF(C38="","",IFERROR(G38/C38,0)) | J38: =IF(D38="","",IFERROR(H38/D38,0)) | K38: =IF(C38="","",IFERROR(SUMPRODUCT((((VER_DATE>=$A38)*(VER_DATE<=$A38)))*(((($B$6="ALL")+(VER_SITE=$B$6))>0))*(((($B$7="ALL")+(VER_QUEUE=$B$7))>0))*(((($B$8="ALL")+(VER_CHAN=$B$8))>0))*VER_SL*VER_OFFERED)/C38,0)) | L38: =IF(D38="","",IFERROR(SUMPRODUCT((((IEX_DATE>=$A38)*(IEX_DATE<=$A38)))*(((($B$6="ALL")+(IEX_SITE=$B$6))>0))*(((($B$7="ALL")+(IEX_QUEUE=$B$7))>0))*(((($B$8="ALL")+(IEX_CHAN=$B$8))>0))*IEX_SL*IEX_OFFERED)/D38,0)) | M38: =IF(C38="","",IFERROR((SUMIFS(VER_TALK,VER_DATE,">="&$A38,VER_DATE,"<="&$A38,VER_SITE,$D$3,VER_QUEUE,$D$4,VER_CHAN,$D$5)+SUMIFS(VER_HOLD,VER_DATE,">="&$A38,VER_DATE,"<="&$A38,VER_SITE,$D$3,VER_QUEUE,$D$4,VER_CHAN,$D$5)+SUMIFS(VER_ACW,VER_DATE,">="&$A38,VER_DATE,"<="&$A38,VER_SITE,$D$3,VER_QUEUE,$D$4,VER_CHAN,$D$5))/E38,0)) | N38: =IF(D38="","",IFERROR((SUMIFS(IEX_TALK,IEX_DATE,">="&$A38,IEX_DATE,"<="&$A38,IEX_SITE,$D$3,IEX_QUEUE,$D$4,IEX_CHAN,$D$5)+SUMIFS(IEX_HOLD,IEX_DATE,">="&$A38,IEX_DATE,"<="&$A38,IEX_SITE,$D$3,IEX_QUEUE,$D$4,IEX_CHAN,$D$5)+SUMIFS(IEX_ACW,IEX_DATE,">="&$A38,IEX_DATE,"<="&$A38,IEX_SITE,$D$3,IEX_QUEUE,$D$4,IEX_CHAN,$D$5))/F38,0))
A39: =IF(OR(A38="",A38+1>$B$4),"",A38+1) | B39: =IF(A39="","",TEXT(A39,"ddd")) | C39: =IF($A39="","",SUMIFS(VER_OFFERED,VER_DATE,">="&$A39,VER_DATE,"<="&$A39,VER_SITE,$D$3,VER_QUEUE,$D$4,VER_CHAN,$D$5)) | D39: =IF($A39="","",SUMIFS(IEX_OFFERED,IEX_DATE,">="&$A39,IEX_DATE,"<="&$A39,IEX_SITE,$D$3,IEX_QUEUE,$D$4,IEX_CHAN,$D$5)) | E39: =IF($A39="","",SUMIFS(VER_HANDLED,VER_DATE,">="&$A39,VER_DATE,"<="&$A39,VER_SITE,$D$3,VER_QUEUE,$D$4,VER_CHAN,$D$5)) | F39: =IF($A39="","",SUMIFS(IEX_HANDLED,IEX_DATE,">="&$A39,IEX_DATE,"<="&$A39,IEX_SITE,$D$3,IEX_QUEUE,$D$4,IEX_CHAN,$D$5)) | G39: =IF($A39="","",SUMIFS(VER_ABAND,VER_DATE,">="&$A39,VER_DATE,"<="&$A39,VER_SITE,$D$3,VER_QUEUE,$D$4,VER_CHAN,$D$5)) | H39: =IF($A39="","",SUMIFS(IEX_ABAND,IEX_DATE,">="&$A39,IEX_DATE,"<="&$A39,IEX_SITE,$D$3,IEX_QUEUE,$D$4,IEX_CHAN,$D$5)) | I39: =IF(C39="","",IFERROR(G39/C39,0)) | J39: =IF(D39="","",IFERROR(H39/D39,0)) | K39: =IF(C39="","",IFERROR(SUMPRODUCT((((VER_DATE>=$A39)*(VER_DATE<=$A39)))*(((($B$6="ALL")+(VER_SITE=$B$6))>0))*(((($B$7="ALL")+(VER_QUEUE=$B$7))>0))*(((($B$8="ALL")+(VER_CHAN=$B$8))>0))*VER_SL*VER_OFFERED)/C39,0)) | L39: =IF(D39="","",IFERROR(SUMPRODUCT((((IEX_DATE>=$A39)*(IEX_DATE<=$A39)))*(((($B$6="ALL")+(IEX_SITE=$B$6))>0))*(((($B$7="ALL")+(IEX_QUEUE=$B$7))>0))*(((($B$8="ALL")+(IEX_CHAN=$B$8))>0))*IEX_SL*IEX_OFFERED)/D39,0)) | M39: =IF(C39="","",IFERROR((SUMIFS(VER_TALK,VER_DATE,">="&$A39,VER_DATE,"<="&$A39,VER_SITE,$D$3,VER_QUEUE,$D$4,VER_CHAN,$D$5)+SUMIFS(VER_HOLD,VER_DATE,">="&$A39,VER_DATE,"<="&$A39,VER_SITE,$D$3,VER_QUEUE,$D$4,VER_CHAN,$D$5)+SUMIFS(VER_ACW,VER_DATE,">="&$A39,VER_DATE,"<="&$A39,VER_SITE,$D$3,VER_QUEUE,$D$4,VER_CHAN,$D$5))/E39,0)) | N39: =IF(D39="","",IFERROR((SUMIFS(IEX_TALK,IEX_DATE,">="&$A39,IEX_DATE,"<="&$A39,IEX_SITE,$D$3,IEX_QUEUE,$D$4,IEX_CHAN,$D$5)+SUMIFS(IEX_HOLD,IEX_DATE,">="&$A39,IEX_DATE,"<="&$A39,IEX_SITE,$D$3,IEX_QUEUE,$D$4,IEX_CHAN,$D$5)+SUMIFS(IEX_ACW,IEX_DATE,">="&$A39,IEX_DATE,"<="&$A39,IEX_SITE,$D$3,IEX_QUEUE,$D$4,IEX_CHAN,$D$5))/F39,0))
A40: =IF(OR(A39="",A39+1>$B$4),"",A39+1) | B40: =IF(A40="","",TEXT(A40,"ddd")) | C40: =IF($A40="","",SUMIFS(VER_OFFERED,VER_DATE,">="&$A40,VER_DATE,"<="&$A40,VER_SITE,$D$3,VER_QUEUE,$D$4,VER_CHAN,$D$5)) | D40: =IF($A40="","",SUMIFS(IEX_OFFERED,IEX_DATE,">="&$A40,IEX_DATE,"<="&$A40,IEX_SITE,$D$3,IEX_QUEUE,$D$4,IEX_CHAN,$D$5)) | E40: =IF($A40="","",SUMIFS(VER_HANDLED,VER_DATE,">="&$A40,VER_DATE,"<="&$A40,VER_SITE,$D$3,VER_QUEUE,$D$4,VER_CHAN,$D$5)) | F40: =IF($A40="","",SUMIFS(IEX_HANDLED,IEX_DATE,">="&$A40,IEX_DATE,"<="&$A40,IEX_SITE,$D$3,IEX_QUEUE,$D$4,IEX_CHAN,$D$5)) | G40: =IF($A40="","",SUMIFS(VER_ABAND,VER_DATE,">="&$A40,VER_DATE,"<="&$A40,VER_SITE,$D$3,VER_QUEUE,$D$4,VER_CHAN,$D$5)) | H40: =IF($A40="","",SUMIFS(IEX_ABAND,IEX_DATE,">="&$A40,IEX_DATE,"<="&$A40,IEX_SITE,$D$3,IEX_QUEUE,$D$4,IEX_CHAN,$D$5)) | I40: =IF(C40="","",IFERROR(G40/C40,0)) | J40: =IF(D40="","",IFERROR(H40/D40,0)) | K40: =IF(C40="","",IFERROR(SUMPRODUCT((((VER_DATE>=$A40)*(VER_DATE<=$A40)))*(((($B$6="ALL")+(VER_SITE=$B$6))>0))*(((($B$7="ALL")+(VER_QUEUE=$B$7))>0))*(((($B$8="ALL")+(VER_CHAN=$B$8))>0))*VER_SL*VER_OFFERED)/C40,0)) | L40: =IF(D40="","",IFERROR(SUMPRODUCT((((IEX_DATE>=$A40)*(IEX_DATE<=$A40)))*(((($B$6="ALL")+(IEX_SITE=$B$6))>0))*(((($B$7="ALL")+(IEX_QUEUE=$B$7))>0))*(((($B$8="ALL")+(IEX_CHAN=$B$8))>0))*IEX_SL*IEX_OFFERED)/D40,0)) | M40: =IF(C40="","",IFERROR((SUMIFS(VER_TALK,VER_DATE,">="&$A40,VER_DATE,"<="&$A40,VER_SITE,$D$3,VER_QUEUE,$D$4,VER_CHAN,$D$5)+SUMIFS(VER_HOLD,VER_DATE,">="&$A40,VER_DATE,"<="&$A40,VER_SITE,$D$3,VER_QUEUE,$D$4,VER_CHAN,$D$5)+SUMIFS(VER_ACW,VER_DATE,">="&$A40,VER_DATE,"<="&$A40,VER_SITE,$D$3,VER_QUEUE,$D$4,VER_CHAN,$D$5))/E40,0)) | N40: =IF(D40="","",IFERROR((SUMIFS(IEX_TALK,IEX_DATE,">="&$A40,IEX_DATE,"<="&$A40,IEX_SITE,$D$3,IEX_QUEUE,$D$4,IEX_CHAN,$D$5)+SUMIFS(IEX_HOLD,IEX_DATE,">="&$A40,IEX_DATE,"<="&$A40,IEX_SITE,$D$3,IEX_QUEUE,$D$4,IEX_CHAN,$D$5)+SUMIFS(IEX_ACW,IEX_DATE,">="&$A40,IEX_DATE,"<="&$A40,IEX_SITE,$D$3,IEX_QUEUE,$D$4,IEX_CHAN,$D$5))/F40,0))
A41: =IF(OR(A40="",A40+1>$B$4),"",A40+1) | B41: =IF(A41="","",TEXT(A41,"ddd")) | C41: =IF($A41="","",SUMIFS(VER_OFFERED,VER_DATE,">="&$A41,VER_DATE,"<="&$A41,VER_SITE,$D$3,VER_QUEUE,$D$4,VER_CHAN,$D$5)) | D41: =IF($A41="","",SUMIFS(IEX_OFFERED,IEX_DATE,">="&$A41,IEX_DATE,"<="&$A41,IEX_SITE,$D$3,IEX_QUEUE,$D$4,IEX_CHAN,$D$5)) | E41: =IF($A41="","",SUMIFS(VER_HANDLED,VER_DATE,">="&$A41,VER_DATE,"<="&$A41,VER_SITE,$D$3,VER_QUEUE,$D$4,VER_CHAN,$D$5)) | F41: =IF($A41="","",SUMIFS(IEX_HANDLED,IEX_DATE,">="&$A41,IEX_DATE,"<="&$A41,IEX_SITE,$D$3,IEX_QUEUE,$D$4,IEX_CHAN,$D$5)) | G41: =IF($A41="","",SUMIFS(VER_ABAND,VER_DATE,">="&$A41,VER_DATE,"<="&$A41,VER_SITE,$D$3,VER_QUEUE,$D$4,VER_CHAN,$D$5)) | H41: =IF($A41="","",SUMIFS(IEX_ABAND,IEX_DATE,">="&$A41,IEX_DATE,"<="&$A41,IEX_SITE,$D$3,IEX_QUEUE,$D$4,IEX_CHAN,$D$5)) | I41: =IF(C41="","",IFERROR(G41/C41,0)) | J41: =IF(D41="","",IFERROR(H41/D41,0)) | K41: =IF(C41="","",IFERROR(SUMPRODUCT((((VER_DATE>=$A41)*(VER_DATE<=$A41)))*(((($B$6="ALL")+(VER_SITE=$B$6))>0))*(((($B$7="ALL")+(VER_QUEUE=$B$7))>0))*(((($B$8="ALL")+(VER_CHAN=$B$8))>0))*VER_SL*VER_OFFERED)/C41,0)) | L41: =IF(D41="","",IFERROR(SUMPRODUCT((((IEX_DATE>=$A41)*(IEX_DATE<=$A41)))*(((($B$6="ALL")+(IEX_SITE=$B$6))>0))*(((($B$7="ALL")+(IEX_QUEUE=$B$7))>0))*(((($B$8="ALL")+(IEX_CHAN=$B$8))>0))*IEX_SL*IEX_OFFERED)/D41,0)) | M41: =IF(C41="","",IFERROR((SUMIFS(VER_TALK,VER_DATE,">="&$A41,VER_DATE,"<="&$A41,VER_SITE,$D$3,VER_QUEUE,$D$4,VER_CHAN,$D$5)+SUMIFS(VER_HOLD,VER_DATE,">="&$A41,VER_DATE,"<="&$A41,VER_SITE,$D$3,VER_QUEUE,$D$4,VER_CHAN,$D$5)+SUMIFS(VER_ACW,VER_DATE,">="&$A41,VER_DATE,"<="&$A41,VER_SITE,$D$3,VER_QUEUE,$D$4,VER_CHAN,$D$5))/E41,0)) | N41: =IF(D41="","",IFERROR((SUMIFS(IEX_TALK,IEX_DATE,">="&$A41,IEX_DATE,"<="&$A41,IEX_SITE,$D$3,IEX_QUEUE,$D$4,IEX_CHAN,$D$5)+SUMIFS(IEX_HOLD,IEX_DATE,">="&$A41,IEX_DATE,"<="&$A41,IEX_SITE,$D$3,IEX_QUEUE,$D$4,IEX_CHAN,$D$5)+SUMIFS(IEX_ACW,IEX_DATE,">="&$A41,IEX_DATE,"<="&$A41,IEX_SITE,$D$3,IEX_QUEUE,$D$4,IEX_CHAN,$D$5))/F41,0))
A42: =IF(OR(A41="",A41+1>$B$4),"",A41+1) | B42: =IF(A42="","",TEXT(A42,"ddd")) | C42: =IF($A42="","",SUMIFS(VER_OFFERED,VER_DATE,">="&$A42,VER_DATE,"<="&$A42,VER_SITE,$D$3,VER_QUEUE,$D$4,VER_CHAN,$D$5)) | D42: =IF($A42="","",SUMIFS(IEX_OFFERED,IEX_DATE,">="&$A42,IEX_DATE,"<="&$A42,IEX_SITE,$D$3,IEX_QUEUE,$D$4,IEX_CHAN,$D$5)) | E42: =IF($A42="","",SUMIFS(VER_HANDLED,VER_DATE,">="&$A42,VER_DATE,"<="&$A42,VER_SITE,$D$3,VER_QUEUE,$D$4,VER_CHAN,$D$5)) | F42: =IF($A42="","",SUMIFS(IEX_HANDLED,IEX_DATE,">="&$A42,IEX_DATE,"<="&$A42,IEX_SITE,$D$3,IEX_QUEUE,$D$4,IEX_CHAN,$D$5)) | G42: =IF($A42="","",SUMIFS(VER_ABAND,VER_DATE,">="&$A42,VER_DATE,"<="&$A42,VER_SITE,$D$3,VER_QUEUE,$D$4,VER_CHAN,$D$5)) | H42: =IF($A42="","",SUMIFS(IEX_ABAND,IEX_DATE,">="&$A42,IEX_DATE,"<="&$A42,IEX_SITE,$D$3,IEX_QUEUE,$D$4,IEX_CHAN,$D$5)) | I42: =IF(C42="","",IFERROR(G42/C42,0)) | J42: =IF(D42="","",IFERROR(H42/D42,0)) | K42: =IF(C42="","",IFERROR(SUMPRODUCT((((VER_DATE>=$A42)*(VER_DATE<=$A42)))*(((($B$6="ALL")+(VER_SITE=$B$6))>0))*(((($B$7="ALL")+(VER_QUEUE=$B$7))>0))*(((($B$8="ALL")+(VER_CHAN=$B$8))>0))*VER_SL*VER_OFFERED)/C42,0)) | L42: =IF(D42="","",IFERROR(SUMPRODUCT((((IEX_DATE>=$A42)*(IEX_DATE<=$A42)))*(((($B$6="ALL")+(IEX_SITE=$B$6))>0))*(((($B$7="ALL")+(IEX_QUEUE=$B$7))>0))*(((($B$8="ALL")+(IEX_CHAN=$B$8))>0))*IEX_SL*IEX_OFFERED)/D42,0)) | M42: =IF(C42="","",IFERROR((SUMIFS(VER_TALK,VER_DATE,">="&$A42,VER_DATE,"<="&$A42,VER_SITE,$D$3,VER_QUEUE,$D$4,VER_CHAN,$D$5)+SUMIFS(VER_HOLD,VER_DATE,">="&$A42,VER_DATE,"<="&$A42,VER_SITE,$D$3,VER_QUEUE,$D$4,VER_CHAN,$D$5)+SUMIFS(VER_ACW,VER_DATE,">="&$A42,VER_DATE,"<="&$A42,VER_SITE,$D$3,VER_QUEUE,$D$4,VER_CHAN,$D$5))/E42,0)) | N42: =IF(D42="","",IFERROR((SUMIFS(IEX_TALK,IEX_DATE,">="&$A42,IEX_DATE,"<="&$A42,IEX_SITE,$D$3,IEX_QUEUE,$D$4,IEX_CHAN,$D$5)+SUMIFS(IEX_HOLD,IEX_DATE,">="&$A42,IEX_DATE,"<="&$A42,IEX_SITE,$D$3,IEX_QUEUE,$D$4,IEX_CHAN,$D$5)+SUMIFS(IEX_ACW,IEX_DATE,">="&$A42,IEX_DATE,"<="&$A42,IEX_SITE,$D$3,IEX_QUEUE,$D$4,IEX_CHAN,$D$5))/F42,0))
...

Sheet Dashboard
A1: VERINT + IEX | WFM PERFORMANCE DASHBOARD
A2: ="Period "&TEXT(Calc_Data!$B$3,"dd mmm yyyy")&" to "&TEXT(Calc_Data!$B$4,"dd mmm yyyy")&" | Source: "&Setup!$B$13&" | Site: "&Setup!$B$10&" | Queue: "&Setup!$B$11&" | Channel: "&Setup!$B$12
A3: =Setup!$B$16
A5: HEADLINE KPIs
A7: CONTACTS OFFERED | C7: CONTACTS HANDLED | E7: ABANDON RATE | G7: SERVICE LEVEL | I7: AVG HANDLE TIME
A8: =INDEX(Calc_Data!$C$14:$E$14,MATCH(Setup!$B$13,Calc_Data!$C$13:$E$13,0)) | C8: =INDEX(Calc_Data!$C$15:$E$15,MATCH(Setup!$B$13,Calc_Data!$C$13:$E$13,0)) | E8: =INDEX(Calc_Data!$C$17:$E$17,MATCH(Setup!$B$13,Calc_Data!$C$13:$E$13,0)) | G8: =INDEX(Calc_Data!$C$18:$E$18,MATCH(Setup!$B$13,Calc_Data!$C$13:$E$13,0)) | I8: =INDEX(Calc_Data!$C$20:$E$20,MATCH(Setup!$B$13,Calc_Data!$C$13:$E$13,0))
A12: STAFFED AGENT-HOURS | C12: REQUIRED AGENT-HOURS | E12: STAFFING GAP (HOURS) | G12: OCCUPANCY | I12: INTERVALS CAPTURED
A13: =INDEX(Calc_Data!$C$21:$E$21,MATCH(Setup!$B$13,Calc_Data!$C$13:$E$13,0)) | C13: =INDEX(Calc_Data!$C$22:$E$22,MATCH(Setup!$B$13,Calc_Data!$C$13:$E$13,0)) | E13: =INDEX(Calc_Data!$C$23:$E$23,MATCH(Setup!$B$13,Calc_Data!$C$13:$E$13,0)) | G13: =INDEX(Calc_Data!$C$25:$E$25,MATCH(Setup!$B$13,Calc_Data!$C$13:$E$13,0)) | I13: =INDEX(Calc_Data!$C$26:$E$26,MATCH(Setup!$B$13,Calc_Data!$C$13:$E$13,0))
A16: SOURCE RECONCILIATION
A17: Days with variance | B17: =COUNTIF(Reconciliation!$S$6:$S$36,"REVIEW") | D17: Variance tolerance | E17: =Setup!$B$20 | G17: Data quality alerts | H17: =COUNTIF(DQ_Checks!$E$6:$E$30,"FAIL") | I17: Open Reconciliation >
A55: Reads from Verint_Raw and IEX_Raw through Calc_Data. Change the source, site, queue or channel on Setup.

Sheet Reconciliation
A1: VERINT / IEX RECONCILIATION
A2: Side-by-side daily totals with variance flags. Tolerance is set on Setup.
A3: Period | B3: =Calc_Data!$B$3 | D3: Through | E3: =Calc_Data!$B$4 | G3: Tolerance | H3: =Setup!$B$20 | J3: Days flagged REVIEW | K3: =COUNTIF(S6:S36,"REVIEW")
A5: Date | B5: Day | C5: V Offered | D5: IEX Offered | E5: Var | F5: Var % | G5: V Handled | H5: IEX Handled | I5: Var | J5: V Aband | K5: IEX Aband | L5: Var | M5: V SL | N5: IEX SL | O5: SL Diff | P5: V AHT | Q5: IEX AHT | R5: AHT Diff | S5: Status
A6: =IF(Calc_Data!A32="","",Calc_Data!A32) | B6: =IF(Calc_Data!A32="","",Calc_Data!B32) | C6: =IF(Calc_Data!A32="","",Calc_Data!C32) | D6: =IF(Calc_Data!A32="","",Calc_Data!D32) | E6: =IF($A6="","",N(C6)-N(D6)) | F6: =IF(OR($A6="",N(D6)=0),"",E6/D6) | G6: =IF(Calc_Data!A32="","",Calc_Data!E32) | H6: =IF(Calc_Data!A32="","",Calc_Data!F32) | I6: =IF($A6="","",N(G6)-N(H6)) | J6: =IF(Calc_Data!A32="","",Calc_Data!G32) | K6: =IF(Calc_Data!A32="","",Calc_Data!H32) | L6: =IF($A6="","",N(J6)-N(K6)) | M6: =IF(Calc_Data!A32="","",Calc_Data!K32) | N6: =IF(Calc_Data!A32="","",Calc_Data!L32) | O6: =IF($A6="","",(N(M6)-N(N6))*100) | P6: =IF(Calc_Data!A32="","",Calc_Data!M32) | Q6: =IF(Calc_Data!A32="","",Calc_Data!N32) | R6: =IF($A6="","",N(P6)-N(Q6)) | S6: =IF($A6="","",IF(AND(ABS(N(F6))<=$H$3,ABS(N(I6))<=MAX(2,0.02*N(G6))),"MATCH","REVIEW"))
A7: =IF(Calc_Data!A33="","",Calc_Data!A33) | B7: =IF(Calc_Data!A33="","",Calc_Data!B33) | C7: =IF(Calc_Data!A33="","",Calc_Data!C33) | D7: =IF(Calc_Data!A33="","",Calc_Data!D33) | E7: =IF($A7="","",N(C7)-N(D7)) | F7: =IF(OR($A7="",N(D7)=0),"",E7/D7) | G7: =IF(Calc_Data!A33="","",Calc_Data!E33) | H7: =IF(Calc_Data!A33="","",Calc_Data!F33) | I7: =IF($A7="","",N(G7)-N(H7)) | J7: =IF(Calc_Data!A33="","",Calc_Data!G33) | K7: =IF(Calc_Data!A33="","",Calc_Data!H33) | L7: =IF($A7="","",N(J7)-N(K7)) | M7: =IF(Calc_Data!A33="","",Calc_Data!K33) | N7: =IF(Calc_Data!A33="","",Calc_Data!L33) | O7: =IF($A7="","",(N(M7)-N(N7))*100) | P7: =IF(Calc_Data!A33="","",Calc_Data!M33) | Q7: =IF(Calc_Data!A33="","",Calc_Data!N33) | R7: =IF($A7="","",N(P7)-N(Q7)) | S7: =IF($A7="","",IF(AND(ABS(N(F7))<=$H$3,ABS(N(I7))<=MAX(2,0.02*N(G7))),"MATCH","REVIEW"))
A8: =IF(Calc_Data!A34="","",Calc_Data!A34) | B8: =IF(Calc_Data!A34="","",Calc_Data!B34) | C8: =IF(Calc_Data!A34="","",Calc_Data!C34) | D8: =IF(Calc_Data!A34="","",Calc_Data!D34) | E8: =IF($A8="","",N(C8)-N(D8)) | F8: =IF(OR($A8="",N(D8)=0),"",E8/D8) | G8: =IF(Calc_Data!A34="","",Calc_Data!E34) | H8: =IF(Calc_Data!A34="","",Calc_Data!F34) | I8: =IF($A8="","",N(G8)-N(H8)) | J8: =IF(Calc_Data!A34="","",Calc_Data!G34) | K8: =IF(Calc_Data!A34="","",Calc_Data!H34) | L8: =IF($A8="","",N(J8)-N(K8)) | M8: =IF(Calc_Data!A34="","",Calc_Data!K34) | N8: =IF(Calc_Data!A34="","",Calc_Data!L34) | O8: =IF($A8="","",(N(M8)-N(N8))*100) | P8: =IF(Calc_Data!A34="","",Calc_Data!M34) | Q8: =IF(Calc_Data!A34="","",Calc_Data!N34) | R8: =IF($A8="","",N(P8)-N(Q8)) | S8: =IF($A8="","",IF(AND(ABS(N(F8))<=$H$3,ABS(N(I8))<=MAX(2,0.02*N(G8))),"MATCH","REVIEW"))
A9: =IF(Calc_Data!A35="","",Calc_Data!A35) | B9: =IF(Calc_Data!A35="","",Calc_Data!B35) | C9: =IF(Calc_Data!A35="","",Calc_Data!C35) | D9: =IF(Calc_Data!A35="","",Calc_Data!D35) | E9: =IF($A9="","",N(C9)-N(D9)) | F9: =IF(OR($A9="",N(D9)=0),"",E9/D9) | G9: =IF(Calc_Data!A35="","",Calc_Data!E35) | H9: =IF(Calc_Data!A35="","",Calc_Data!F35) | I9: =IF($A9="","",N(G9)-N(H9)) | J9: =IF(Calc_Data!A35="","",Calc_Data!G35) | K9: =IF(Calc_Data!A35="","",Calc_Data!H35) | L9: =IF($A9="","",N(J9)-N(K9)) | M9: =IF(Calc_Data!A35="","",Calc_Data!K35) | N9: =IF(Calc_Data!A35="","",Calc_Data!L35) | O9: =IF($A9="","",(N(M9)-N(N9))*100) | P9: =IF(Calc_Data!A35="","",Calc_Data!M35) | Q9: =IF(Calc_Data!A35="","",Calc_Data!N35) | R9: =IF($A9="","",N(P9)-N(Q9)) | S9: =IF($A9="","",IF(AND(ABS(N(F9))<=$H$3,ABS(N(I9))<=MAX(2,0.02*N(G9))),"MATCH","REVIEW"))
A10: =IF(Calc_Data!A36="","",Calc_Data!A36) | B10: =IF(Calc_Data!A36="","",Calc_Data!B36) | C10: =IF(Calc_Data!A36="","",Calc_Data!C36) | D10: =IF(Calc_Data!A36="","",Calc_Data!D36) | E10: =IF($A10="","",N(C10)-N(D10)) | F10: =IF(OR($A10="",N(D10)=0),"",E10/D10) | G10: =IF(Calc_Data!A36="","",Calc_Data!E36) | H10: =IF(Calc_Data!A36="","",Calc_Data!F36) | I10: =IF($A10="","",N(G10)-N(H10)) | J10: =IF(Calc_Data!A36="","",Calc_Data!G36) | K10: =IF(Calc_Data!A36="","",Calc_Data!H36) | L10: =IF($A10="","",N(J10)-N(K10)) | M10: =IF(Calc_Data!A36="","",Calc_Data!K36) | N10: =IF(Calc_Data!A36="","",Calc_Data!L36) | O10: =IF($A10="","",(N(M10)-N(N10))*100) | P10: =IF(Calc_Data!A36="","",Calc_Data!M36) | Q10: =IF(Calc_Data!A36="","",Calc_Data!N36) | R10: =IF($A10="","",N(P10)-N(Q10)) | S10: =IF($A10="","",IF(AND(ABS(N(F10))<=$H$3,ABS(N(I10))<=MAX(2,0.02*N(G10))),"MATCH","REVIEW"))
A11: =IF(Calc_Data!A37="","",Calc_Data!A37) | B11: =IF(Calc_Data!A37="","",Calc_Data!B37) | C11: =IF(Calc_Data!A37="","",Calc_Data!C37) | D11: =IF(Calc_Data!A37="","",Calc_Data!D37) | E11: =IF($A11="","",N(C11)-N(D11)) | F11: =IF(OR($A11="",N(D11)=0),"",E11/D11) | G11: =IF(Calc_Data!A37="","",Calc_Data!E37) | H11: =IF(Calc_Data!A37="","",Calc_Data!F37) | I11: =IF($A11="","",N(G11)-N(H11)) | J11: =IF(Calc_Data!A37="","",Calc_Data!G37) | K11: =IF(Calc_Data!A37="","",Calc_Data!H37) | L11: =IF($A11="","",N(J11)-N(K11)) | M11: =IF(Calc_Data!A37="","",Calc_Data!K37) | N11: =IF(Calc_Data!A37="","",Calc_Data!L37) | O11: =IF($A11="","",(N(M11)-N(N11))*100) | P11: =IF(Calc_Data!A37="","",Calc_Data!M37) | Q11: =IF(Calc_Data!A37="","",Calc_Data!N37) | R11: =IF($A11="","",N(P11)-N(Q11)) | S11: =IF($A11="","",IF(AND(ABS(N(F11))<=$H$3,ABS(N(I11))<=MAX(2,0.02*N(G11))),"MATCH","REVIEW"))
A12: =IF(Calc_Data!A38="","",Calc_Data!A38) | B12: =IF(Calc_Data!A38="","",Calc_Data!B38) | C12: =IF(Calc_Data!A38="","",Calc_Data!C38) | D12: =IF(Calc_Data!A38="","",Calc_Data!D38) | E12: =IF($A12="","",N(C12)-N(D12)) | F12: =IF(OR($A12="",N(D12)=0),"",E12/D12) | G12: =IF(Calc_Data!A38="","",Calc_Data!E38) | H12: =IF(Calc_Data!A38="","",Calc_Data!F38) | I12: =IF($A12="","",N(G12)-N(H12)) | J12: =IF(Calc_Data!A38="","",Calc_Data!G38) | K12: =IF(Calc_Data!A38="","",Calc_Data!H38) | L12: =IF($A12="","",N(J12)-N(K12)) | M12: =IF(Calc_Data!A38="","",Calc_Data!K38) | N12: =IF(Calc_Data!A38="","",Calc_Data!L38) | O12: =IF($A12="","",(N(M12)-N(N12))*100) | P12: =IF(Calc_Data!A38="","",Calc_Data!M38) | Q12: =IF(Calc_Data!A38="","",Calc_Data!N38) | R12: =IF($A12="","",N(P12)-N(Q12)) | S12: =IF($A12="","",IF(AND(ABS(N(F12))<=$H$3,ABS(N(I12))<=MAX(2,0.02*N(G12))),"MATCH","REVIEW"))
A13: =IF(Calc_Data!A39="","",Calc_Data!A39) | B13: =IF(Calc_Data!A39="","",Calc_Data!B39) | C13: =IF(Calc_Data!A39="","",Calc_Data!C39) | D13: =IF(Calc_Data!A39="","",Calc_Data!D39) | E13: =IF($A13="","",N(C13)-N(D13)) | F13: =IF(OR($A13="",N(D13)=0),"",E13/D13) | G13: =IF(Calc_Data!A39="","",Calc_Data!E39) | H13: =IF(Calc_Data!A39="","",Calc_Data!F39) | I13: =IF($A13="","",N(G13)-N(H13)) | J13: =IF(Calc_Data!A39="","",Calc_Data!G39) | K13: =IF(Calc_Data!A39="","",Calc_Data!H39) | L13: =IF($A13="","",N(J13)-N(K13)) | M13: =IF(Calc_Data!A39="","",Calc_Data!K39) | N13: =IF(Calc_Data!A39="","",Calc_Data!L39) | O13: =IF($A13="","",(N(M13)-N(N13))*100) | P13: =IF(Calc_Data!A39="","",Calc_Data!M39) | Q13: =IF(Calc_Data!A39="","",Calc_Data!N39) | R13: =IF($A13="","",N(P13)-N(Q13)) | S13: =IF($A13="","",IF(AND(ABS(N(F13))<=$H$3,ABS(N(I13))<=MAX(2,0.02*N(G13))),"MATCH","REVIEW"))
A14: =IF(Calc_Data!A40="","",Calc_Data!A40) | B14: =IF(Calc_Data!A40="","",Calc_Data!B40) | C14: =IF(Calc_Data!A40="","",Calc_Data!C40) | D14: =IF(Calc_Data!A40="","",Calc_Data!D40) | E14: =IF($A14="","",N(C14)-N(D14)) | F14: =IF(OR($A14="",N(D14)=0),"",E14/D14) | G14: =IF(Calc_Data!A40="","",Calc_Data!E40) | H14: =IF(Calc_Data!A40="","",Calc_Data!F40) | I14: =IF($A14="","",N(G14)-N(H14)) | J14: =IF(Calc_Data!A40="","",Calc_Data!G40) | K14: =IF(Calc_Data!A40="","",Calc_Data!H40) | L14: =IF($A14="","",N(J14)-N(K14)) | M14: =IF(Calc_Data!A40="","",Calc_Data!K40) | N14: =IF(Calc_Data!A40="","",Calc_Data!L40) | O14: =IF($A14="","",(N(M14)-N(N14))*100) | P14: =IF(Calc_Data!A40="","",Calc_Data!M40) | Q14: =IF(Calc_Data!A40="","",Calc_Data!N40) | R14: =IF($A14="","",N(P14)-N(Q14)) | S14: =IF($A14="","",IF(AND(ABS(N(F14))<=$H$3,ABS(N(I14))<=MAX(2,0.02*N(G14))),"MATCH","REVIEW"))
A15: =IF(Calc_Data!A41="","",Calc_Data!A41) | B15: =IF(Calc_Data!A41="","",Calc_Data!B41) | C15: =IF(Calc_Data!A41="","",Calc_Data!C41) | D15: =IF(Calc_Data!A41="","",Calc_Data!D41) | E15: =IF($A15="","",N(C15)-N(D15)) | F15: =IF(OR($A15="",N(D15)=0),"",E15/D15) | G15: =IF(Calc_Data!A41="","",Calc_Data!E41) | H15: =IF(Calc_Data!A41="","",Calc_Data!F41) | I15: =IF($A15="","",N(G15)-N(H15)) | J15: =IF(Calc_Data!A41="","",Calc_Data!G41) | K15: =IF(Calc_Data!A41="","",Calc_Data!H41) | L15: =IF($A15="","",N(J15)-N(K15)) | M15: =IF(Calc_Data!A41="","",Calc_Data!K41) | N15: =IF(Calc_Data!A41="","",Calc_Data!L41) | O15: =IF($A15="","",(N(M15)-N(N15))*100) | P15: =IF(Calc_Data!A41="","",Calc_Data!M41) | Q15: =IF(Calc_Data!A41="","",Calc_Data!N41) | R15: =IF($A15="","",N(P15)-N(Q15)) | S15: =IF($A15="","",IF(AND(ABS(N(F15))<=$H$3,ABS(N(I15))<=MAX(2,0.02*N(G15))),"MATCH","REVIEW"))
A16: =IF(Calc_Data!A42="","",Calc_Data!A42) | B16: =IF(Calc_Data!A42="","",Calc_Data!B42) | C16: =IF(Calc_Data!A42="","",Calc_Data!C42) | D16: =IF(Calc_Data!A42="","",Calc_Data!D42) | E16: =IF($A16="","",N(C16)-N(D16)) | F16: =IF(OR($A16="",N(D16)=0),"",E16/D16) | G16: =IF(Calc_Data!A42="","",Calc_Data!E42) | H16: =IF(Calc_Data!A42="","",Calc_Data!F42) | I16: =IF($A16="","",N(G16)-N(H16)) | J16: =IF(Calc_Data!A42="","",Calc_Data!G42) | K16: =IF(Calc_Data!A42="","",Calc_Data!H42) | L16: =IF($A16="","",N(J16)-N(K16)) | M16: =IF(Calc_Data!A42="","",Calc_Data!K42) | N16: =IF(Calc_Data!A42="","",Calc_Data!L42) | O16: =IF($A16="","",(N(M16)-N(N16))*100) | P16: =IF(Calc_Data!A42="","",Calc_Data!M42) | Q16: =IF(Calc_Data!A42="","",Calc_Data!N42) | R16: =IF($A16="","",N(P16)-N(Q16)) | S16: =IF($A16="","",IF(AND(ABS(N(F16))<=$H$3,ABS(N(I16))<=MAX(2,0.02*N(G16))),"MATCH","REVIEW"))
A17: =IF(Calc_Data!A43="","",Calc_Data!A43) | B17: =IF(Calc_Data!A43="","",Calc_Data!B43) | C17: =IF(Calc_Data!A43="","",Calc_Data!C43) | D17: =IF(Calc_Data!A43="","",Calc_Data!D43) | E17: =IF($A17="","",N(C17)-N(D17)) | F17: =IF(OR($A17="",N(D17)=0),"",E17/D17) | G17: =IF(Calc_Data!A43="","",Calc_Data!E43) | H17: =IF(Calc_Data!A43="","",Calc_Data!F43) | I17: =IF($A17="","",N(G17)-N(H17)) | J17: =IF(Calc_Data!A43="","",Calc_Data!G43) | K17: =IF(Calc_Data!A43="","",Calc_Data!H43) | L17: =IF($A17="","",N(J17)-N(K17)) | M17: =IF(Calc_Data!A43="","",Calc_Data!K43) | N17: =IF(Calc_Data!A43="","",Calc_Data!L43) | O17: =IF($A17="","",(N(M17)-N(N17))*100) | P17: =IF(Calc_Data!A43="","",Calc_Data!M43) | Q17: =IF(Calc_Data!A43="","",Calc_Data!N43) | R17: =IF($A17="","",N(P17)-N(Q17)) | S17: =IF($A17="","",IF(AND(ABS(N(F17))<=$H$3,ABS(N(I17))<=MAX(2,0.02*N(G17))),"MATCH","REVIEW"))
